2017-10-10 15:52:22,116 [Thread-2:17316] [django.request:135] [ERROR]- Internal Server Error: /Users/
Traceback (most recent call last):
  File "C:\Python36-32\lib\site-packages\rest_framework\relations.py", line 378, in to_representation
    url = self.get_url(value, self.view_name, request, format)
  File "C:\Python36-32\lib\site-packages\rest_framework\relations.py", line 316, in get_url
    return self.reverse(view_name, kwargs=kwargs, request=request, format=format)
  File "C:\Python36-32\lib\site-packages\rest_framework\reverse.py", line 50, in reverse
    url = _reverse(viewname, args, kwargs, request, format, **extra)
  File "C:\Python36-32\lib\site-packages\rest_framework\reverse.py", line 63, in _reverse
    url = django_reverse(viewname, args=args, kwargs=kwargs, **extra)
  File "C:\Python36-32\lib\site-packages\django\urls\base.py", line 91, in reverse
    return force_text(iri_to_uri(resolver._reverse_with_prefix(view, prefix, *args, **kwargs)))
  File "C:\Python36-32\lib\site-packages\django\urls\resolvers.py", line 497, in _reverse_with_prefix
    raise NoReverseMatch(msg)
django.urls.exceptions.NoReverseMatch: Reverse for 'Note-detail' not found. 'Note-detail' is not a valid view function or pattern name.

During handling of the above exception, another exception occurred:

Traceback (most recent call last):
  File "C:\Python36-32\lib\site-packages\django\core\handlers\exception.py", line 41, in inner
    response = get_response(request)
  File "C:\Python36-32\lib\site-packages\django\core\handlers\base.py", line 249, in _legacy_get_response
    response = self._get_response(request)
  File "C:\Python36-32\lib\site-packages\django\core\handlers\base.py", line 187, in _get_response
    response = self.process_exception_by_middleware(e, request)
  File "C:\Python36-32\lib\site-packages\django\core\handlers\base.py", line 185, in _get_response
    response = wrapped_callback(request, *callback_args, **callback_kwargs)
  File "C:\Python36-32\lib\site-packages\django\views\decorators\csrf.py", line 58, in wrapped_view
    return view_func(*args, **kwargs)
  File "C:\Python36-32\lib\site-packages\rest_framework\viewsets.py", line 90, in view
    return self.dispatch(request, *args, **kwargs)
  File "C:\Python36-32\lib\site-packages\rest_framework\views.py", line 489, in dispatch
    response = self.handle_exception(exc)
  File "C:\Python36-32\lib\site-packages\rest_framework\views.py", line 449, in handle_exception
    self.raise_uncaught_exception(exc)
  File "C:\Python36-32\lib\site-packages\rest_framework\views.py", line 486, in dispatch
    response = handler(request, *args, **kwargs)
  File "C:\Python36-32\lib\site-packages\rest_framework\mixins.py", line 45, in list
    return self.get_paginated_response(serializer.data)
  File "C:\Python36-32\lib\site-packages\rest_framework\serializers.py", line 739, in data
    ret = super(ListSerializer, self).data
  File "C:\Python36-32\lib\site-packages\rest_framework\serializers.py", line 263, in data
    self._data = self.to_representation(self.instance)
  File "C:\Python36-32\lib\site-packages\rest_framework\serializers.py", line 657, in to_representation
    self.child.to_representation(item) for item in iterable
  File "C:\Python36-32\lib\site-packages\rest_framework\serializers.py", line 657, in <listcomp>
    self.child.to_representation(item) for item in iterable
  File "C:\Python36-32\lib\site-packages\rest_framework\serializers.py", line 501, in to_representation
    ret[field.field_name] = field.to_representation(attribute)
  File "C:\Python36-32\lib\site-packages\rest_framework\relations.py", line 520, in to_representation
    for value in iterable
  File "C:\Python36-32\lib\site-packages\rest_framework\relations.py", line 520, in <listcomp>
    for value in iterable
  File "C:\Python36-32\lib\site-packages\rest_framework\relations.py", line 393, in to_representation
    raise ImproperlyConfigured(msg % self.view_name)
django.core.exceptions.ImproperlyConfigured: Could not resolve URL for hyperlinked relationship using view name "Note-detail". You may have failed to include the related model in your API, or incorrectly configured the `lookup_field` attribute on this field.
2017-10-10 15:53:09,800 [Thread-3:23112] [django.request:135] [ERROR]- Internal Server Error: /index-hot
Traceback (most recent call last):
  File "C:\Python36-32\lib\site-packages\django\core\handlers\exception.py", line 41, in inner
    response = get_response(request)
  File "C:\Python36-32\lib\site-packages\django\core\handlers\base.py", line 249, in _legacy_get_response
    response = self._get_response(request)
  File "C:\Python36-32\lib\site-packages\django\core\handlers\base.py", line 187, in _get_response
    response = self.process_exception_by_middleware(e, request)
  File "C:\Python36-32\lib\site-packages\django\core\handlers\base.py", line 185, in _get_response
    response = wrapped_callback(request, *callback_args, **callback_kwargs)
  File "C:\Python36-32\lib\site-packages\django\views\decorators\csrf.py", line 58, in wrapped_view
    return view_func(*args, **kwargs)
  File "C:\Python36-32\lib\site-packages\django\views\generic\base.py", line 68, in view
    return self.dispatch(request, *args, **kwargs)
  File "C:\Python36-32\lib\site-packages\rest_framework\views.py", line 489, in dispatch
    response = self.handle_exception(exc)
  File "C:\Python36-32\lib\site-packages\rest_framework\views.py", line 449, in handle_exception
    self.raise_uncaught_exception(exc)
  File "C:\Python36-32\lib\site-packages\rest_framework\views.py", line 486, in dispatch
    response = handler(request, *args, **kwargs)
  File "C:\Python36-32\lib\site-packages\rest_framework\decorators.py", line 52, in handler
    return func(*args, **kwargs)
  File "D:\code\PycharmProjects\cms\focus\views.py", line 159, in index_hot
    logger.info(se.data)
  File "C:\Python36-32\lib\site-packages\rest_framework\serializers.py", line 739, in data
    ret = super(ListSerializer, self).data
  File "C:\Python36-32\lib\site-packages\rest_framework\serializers.py", line 263, in data
    self._data = self.to_representation(self.instance)
  File "C:\Python36-32\lib\site-packages\rest_framework\serializers.py", line 657, in to_representation
    self.child.to_representation(item) for item in iterable
  File "C:\Python36-32\lib\site-packages\rest_framework\serializers.py", line 657, in <listcomp>
    self.child.to_representation(item) for item in iterable
  File "C:\Python36-32\lib\site-packages\rest_framework\serializers.py", line 501, in to_representation
    ret[field.field_name] = field.to_representation(attribute)
  File "C:\Python36-32\lib\site-packages\rest_framework\relations.py", line 358, in to_representation
    "the serializer." % self.__class__.__name__
AssertionError: `HyperlinkedIdentityField` requires the request in the serializer context. Add `context={'request': request}` when instantiating the serializer.
2017-10-10 15:54:04,669 [Thread-2:19720] [django.request:135] [ERROR]- Internal Server Error: /index-hot
Traceback (most recent call last):
  File "C:\Python36-32\lib\site-packages\django\core\handlers\exception.py", line 41, in inner
    response = get_response(request)
  File "C:\Python36-32\lib\site-packages\django\core\handlers\base.py", line 249, in _legacy_get_response
    response = self._get_response(request)
  File "C:\Python36-32\lib\site-packages\django\core\handlers\base.py", line 187, in _get_response
    response = self.process_exception_by_middleware(e, request)
  File "C:\Python36-32\lib\site-packages\django\core\handlers\base.py", line 185, in _get_response
    response = wrapped_callback(request, *callback_args, **callback_kwargs)
  File "C:\Python36-32\lib\site-packages\django\views\decorators\csrf.py", line 58, in wrapped_view
    return view_func(*args, **kwargs)
  File "C:\Python36-32\lib\site-packages\django\views\generic\base.py", line 68, in view
    return self.dispatch(request, *args, **kwargs)
  File "C:\Python36-32\lib\site-packages\rest_framework\views.py", line 489, in dispatch
    response = self.handle_exception(exc)
  File "C:\Python36-32\lib\site-packages\rest_framework\views.py", line 449, in handle_exception
    self.raise_uncaught_exception(exc)
  File "C:\Python36-32\lib\site-packages\rest_framework\views.py", line 486, in dispatch
    response = handler(request, *args, **kwargs)
  File "C:\Python36-32\lib\site-packages\rest_framework\decorators.py", line 52, in handler
    return func(*args, **kwargs)
  File "D:\code\PycharmProjects\cms\focus\views.py", line 159, in index_hot
    logger.info(se.data)
  File "C:\Python36-32\lib\site-packages\rest_framework\serializers.py", line 739, in data
    ret = super(ListSerializer, self).data
  File "C:\Python36-32\lib\site-packages\rest_framework\serializers.py", line 263, in data
    self._data = self.to_representation(self.instance)
  File "C:\Python36-32\lib\site-packages\rest_framework\serializers.py", line 657, in to_representation
    self.child.to_representation(item) for item in iterable
  File "C:\Python36-32\lib\site-packages\rest_framework\serializers.py", line 657, in <listcomp>
    self.child.to_representation(item) for item in iterable
  File "C:\Python36-32\lib\site-packages\rest_framework\serializers.py", line 501, in to_representation
    ret[field.field_name] = field.to_representation(attribute)
  File "C:\Python36-32\lib\site-packages\rest_framework\serializers.py", line 501, in to_representation
    ret[field.field_name] = field.to_representation(attribute)
  File "C:\Python36-32\lib\site-packages\rest_framework\relations.py", line 520, in to_representation
    for value in iterable
  File "C:\Python36-32\lib\site-packages\rest_framework\relations.py", line 520, in <listcomp>
    for value in iterable
  File "C:\Python36-32\lib\site-packages\rest_framework\relations.py", line 358, in to_representation
    "the serializer." % self.__class__.__name__
AssertionError: `HyperlinkedRelatedField` requires the request in the serializer context. Add `context={'request': request}` when instantiating the serializer.
2017-10-10 15:55:18,972 [Thread-2:8472] [django.request:135] [ERROR]- Internal Server Error: /index-hot
Traceback (most recent call last):
  File "C:\Python36-32\lib\site-packages\django\core\handlers\exception.py", line 41, in inner
    response = get_response(request)
  File "C:\Python36-32\lib\site-packages\django\core\handlers\base.py", line 249, in _legacy_get_response
    response = self._get_response(request)
  File "C:\Python36-32\lib\site-packages\django\core\handlers\base.py", line 187, in _get_response
    response = self.process_exception_by_middleware(e, request)
  File "C:\Python36-32\lib\site-packages\django\core\handlers\base.py", line 185, in _get_response
    response = wrapped_callback(request, *callback_args, **callback_kwargs)
  File "C:\Python36-32\lib\site-packages\django\views\decorators\csrf.py", line 58, in wrapped_view
    return view_func(*args, **kwargs)
  File "C:\Python36-32\lib\site-packages\django\views\generic\base.py", line 68, in view
    return self.dispatch(request, *args, **kwargs)
  File "C:\Python36-32\lib\site-packages\rest_framework\views.py", line 489, in dispatch
    response = self.handle_exception(exc)
  File "C:\Python36-32\lib\site-packages\rest_framework\views.py", line 449, in handle_exception
    self.raise_uncaught_exception(exc)
  File "C:\Python36-32\lib\site-packages\rest_framework\views.py", line 486, in dispatch
    response = handler(request, *args, **kwargs)
  File "C:\Python36-32\lib\site-packages\rest_framework\decorators.py", line 52, in handler
    return func(*args, **kwargs)
  File "D:\code\PycharmProjects\cms\focus\views.py", line 159, in index_hot
    logger.info(se.data)
  File "C:\Python36-32\lib\site-packages\rest_framework\serializers.py", line 739, in data
    ret = super(ListSerializer, self).data
  File "C:\Python36-32\lib\site-packages\rest_framework\serializers.py", line 263, in data
    self._data = self.to_representation(self.instance)
  File "C:\Python36-32\lib\site-packages\rest_framework\serializers.py", line 657, in to_representation
    self.child.to_representation(item) for item in iterable
  File "C:\Python36-32\lib\site-packages\rest_framework\serializers.py", line 657, in <listcomp>
    self.child.to_representation(item) for item in iterable
  File "C:\Python36-32\lib\site-packages\rest_framework\serializers.py", line 501, in to_representation
    ret[field.field_name] = field.to_representation(attribute)
  File "C:\Python36-32\lib\site-packages\rest_framework\serializers.py", line 501, in to_representation
    ret[field.field_name] = field.to_representation(attribute)
  File "C:\Python36-32\lib\site-packages\rest_framework\relations.py", line 520, in to_representation
    for value in iterable
  File "C:\Python36-32\lib\site-packages\rest_framework\relations.py", line 520, in <listcomp>
    for value in iterable
  File "C:\Python36-32\lib\site-packages\rest_framework\relations.py", line 358, in to_representation
    "the serializer." % self.__class__.__name__
AssertionError: `HyperlinkedRelatedField` requires the request in the serializer context. Add `context={'request': request}` when instantiating the serializer.
2017-10-10 15:55:52,340 [Thread-2:17868] [django.request:135] [ERROR]- Internal Server Error: /index-hot
Traceback (most recent call last):
  File "C:\Python36-32\lib\site-packages\django\core\handlers\exception.py", line 41, in inner
    response = get_response(request)
  File "C:\Python36-32\lib\site-packages\django\core\handlers\base.py", line 249, in _legacy_get_response
    response = self._get_response(request)
  File "C:\Python36-32\lib\site-packages\django\core\handlers\base.py", line 187, in _get_response
    response = self.process_exception_by_middleware(e, request)
  File "C:\Python36-32\lib\site-packages\django\core\handlers\base.py", line 185, in _get_response
    response = wrapped_callback(request, *callback_args, **callback_kwargs)
  File "C:\Python36-32\lib\site-packages\django\views\decorators\csrf.py", line 58, in wrapped_view
    return view_func(*args, **kwargs)
  File "C:\Python36-32\lib\site-packages\django\views\generic\base.py", line 68, in view
    return self.dispatch(request, *args, **kwargs)
  File "C:\Python36-32\lib\site-packages\rest_framework\views.py", line 489, in dispatch
    response = self.handle_exception(exc)
  File "C:\Python36-32\lib\site-packages\rest_framework\views.py", line 449, in handle_exception
    self.raise_uncaught_exception(exc)
  File "C:\Python36-32\lib\site-packages\rest_framework\views.py", line 486, in dispatch
    response = handler(request, *args, **kwargs)
  File "C:\Python36-32\lib\site-packages\rest_framework\decorators.py", line 52, in handler
    return func(*args, **kwargs)
  File "D:\code\PycharmProjects\cms\focus\views.py", line 159, in index_hot
    logger.info(se.data)
  File "C:\Python36-32\lib\site-packages\rest_framework\serializers.py", line 739, in data
    ret = super(ListSerializer, self).data
  File "C:\Python36-32\lib\site-packages\rest_framework\serializers.py", line 263, in data
    self._data = self.to_representation(self.instance)
  File "C:\Python36-32\lib\site-packages\rest_framework\serializers.py", line 657, in to_representation
    self.child.to_representation(item) for item in iterable
  File "C:\Python36-32\lib\site-packages\rest_framework\serializers.py", line 657, in <listcomp>
    self.child.to_representation(item) for item in iterable
  File "C:\Python36-32\lib\site-packages\rest_framework\serializers.py", line 484, in to_representation
    fields = self._readable_fields
  File "C:\Python36-32\lib\site-packages\django\utils\functional.py", line 35, in __get__
    res = instance.__dict__[self.name] = self.func(instance)
  File "C:\Python36-32\lib\site-packages\rest_framework\serializers.py", line 378, in _readable_fields
    field for field in self.fields.values()
  File "C:\Python36-32\lib\site-packages\rest_framework\serializers.py", line 364, in fields
    for key, value in self.get_fields().items():
  File "C:\Python36-32\lib\site-packages\rest_framework\serializers.py", line 994, in get_fields
    field_names = self.get_field_names(declared_fields, info)
  File "C:\Python36-32\lib\site-packages\rest_framework\serializers.py", line 1093, in get_field_names
    serializer_class=self.__class__.__name__
AssertionError: The field 'comments' was declared on serializer NoteSerializer, but has not been included in the 'fields' option.
2017-10-10 15:56:08,276 [Thread-2:2496] [django.request:135] [ERROR]- Internal Server Error: /index-hot
Traceback (most recent call last):
  File "C:\Python36-32\lib\site-packages\django\core\handlers\exception.py", line 41, in inner
    response = get_response(request)
  File "C:\Python36-32\lib\site-packages\django\core\handlers\base.py", line 249, in _legacy_get_response
    response = self._get_response(request)
  File "C:\Python36-32\lib\site-packages\django\core\handlers\base.py", line 187, in _get_response
    response = self.process_exception_by_middleware(e, request)
  File "C:\Python36-32\lib\site-packages\django\core\handlers\base.py", line 185, in _get_response
    response = wrapped_callback(request, *callback_args, **callback_kwargs)
  File "C:\Python36-32\lib\site-packages\django\views\decorators\csrf.py", line 58, in wrapped_view
    return view_func(*args, **kwargs)
  File "C:\Python36-32\lib\site-packages\django\views\generic\base.py", line 68, in view
    return self.dispatch(request, *args, **kwargs)
  File "C:\Python36-32\lib\site-packages\rest_framework\views.py", line 489, in dispatch
    response = self.handle_exception(exc)
  File "C:\Python36-32\lib\site-packages\rest_framework\views.py", line 449, in handle_exception
    self.raise_uncaught_exception(exc)
  File "C:\Python36-32\lib\site-packages\rest_framework\views.py", line 486, in dispatch
    response = handler(request, *args, **kwargs)
  File "C:\Python36-32\lib\site-packages\rest_framework\decorators.py", line 52, in handler
    return func(*args, **kwargs)
  File "D:\code\PycharmProjects\cms\focus\views.py", line 159, in index_hot
    logger.info(se.data)
  File "C:\Python36-32\lib\site-packages\rest_framework\serializers.py", line 739, in data
    ret = super(ListSerializer, self).data
  File "C:\Python36-32\lib\site-packages\rest_framework\serializers.py", line 263, in data
    self._data = self.to_representation(self.instance)
  File "C:\Python36-32\lib\site-packages\rest_framework\serializers.py", line 657, in to_representation
    self.child.to_representation(item) for item in iterable
  File "C:\Python36-32\lib\site-packages\rest_framework\serializers.py", line 657, in <listcomp>
    self.child.to_representation(item) for item in iterable
  File "C:\Python36-32\lib\site-packages\rest_framework\serializers.py", line 501, in to_representation
    ret[field.field_name] = field.to_representation(attribute)
  File "C:\Python36-32\lib\site-packages\rest_framework\serializers.py", line 501, in to_representation
    ret[field.field_name] = field.to_representation(attribute)
  File "C:\Python36-32\lib\site-packages\rest_framework\relations.py", line 520, in to_representation
    for value in iterable
  File "C:\Python36-32\lib\site-packages\rest_framework\relations.py", line 520, in <listcomp>
    for value in iterable
  File "C:\Python36-32\lib\site-packages\rest_framework\relations.py", line 358, in to_representation
    "the serializer." % self.__class__.__name__
AssertionError: `HyperlinkedRelatedField` requires the request in the serializer context. Add `context={'request': request}` when instantiating the serializer.
2017-10-10 15:57:09,672 [Thread-2:7800] [django.request:135] [ERROR]- Internal Server Error: /index-hot
Traceback (most recent call last):
  File "C:\Python36-32\lib\site-packages\django\core\handlers\exception.py", line 41, in inner
    response = get_response(request)
  File "C:\Python36-32\lib\site-packages\django\core\handlers\base.py", line 249, in _legacy_get_response
    response = self._get_response(request)
  File "C:\Python36-32\lib\site-packages\django\core\handlers\base.py", line 187, in _get_response
    response = self.process_exception_by_middleware(e, request)
  File "C:\Python36-32\lib\site-packages\django\core\handlers\base.py", line 185, in _get_response
    response = wrapped_callback(request, *callback_args, **callback_kwargs)
  File "C:\Python36-32\lib\site-packages\django\views\decorators\csrf.py", line 58, in wrapped_view
    return view_func(*args, **kwargs)
  File "C:\Python36-32\lib\site-packages\django\views\generic\base.py", line 68, in view
    return self.dispatch(request, *args, **kwargs)
  File "C:\Python36-32\lib\site-packages\rest_framework\views.py", line 489, in dispatch
    response = self.handle_exception(exc)
  File "C:\Python36-32\lib\site-packages\rest_framework\views.py", line 449, in handle_exception
    self.raise_uncaught_exception(exc)
  File "C:\Python36-32\lib\site-packages\rest_framework\views.py", line 486, in dispatch
    response = handler(request, *args, **kwargs)
  File "C:\Python36-32\lib\site-packages\rest_framework\decorators.py", line 52, in handler
    return func(*args, **kwargs)
  File "D:\code\PycharmProjects\cms\focus\views.py", line 159, in index_hot
    logger.info(se.data)
  File "C:\Python36-32\lib\site-packages\rest_framework\serializers.py", line 739, in data
    ret = super(ListSerializer, self).data
  File "C:\Python36-32\lib\site-packages\rest_framework\serializers.py", line 263, in data
    self._data = self.to_representation(self.instance)
  File "C:\Python36-32\lib\site-packages\rest_framework\serializers.py", line 657, in to_representation
    self.child.to_representation(item) for item in iterable
  File "C:\Python36-32\lib\site-packages\rest_framework\serializers.py", line 657, in <listcomp>
    self.child.to_representation(item) for item in iterable
  File "C:\Python36-32\lib\site-packages\rest_framework\serializers.py", line 501, in to_representation
    ret[field.field_name] = field.to_representation(attribute)
  File "C:\Python36-32\lib\site-packages\rest_framework\serializers.py", line 657, in to_representation
    self.child.to_representation(item) for item in iterable
TypeError: 'MyUser' object is not iterable
2017-10-10 15:59:12,112 [Thread-2:6580] [django.request:135] [ERROR]- Internal Server Error: /index-hot
Traceback (most recent call last):
  File "C:\Python36-32\lib\site-packages\django\core\handlers\exception.py", line 41, in inner
    response = get_response(request)
  File "C:\Python36-32\lib\site-packages\django\core\handlers\base.py", line 249, in _legacy_get_response
    response = self._get_response(request)
  File "C:\Python36-32\lib\site-packages\django\core\handlers\base.py", line 187, in _get_response
    response = self.process_exception_by_middleware(e, request)
  File "C:\Python36-32\lib\site-packages\django\core\handlers\base.py", line 185, in _get_response
    response = wrapped_callback(request, *callback_args, **callback_kwargs)
  File "C:\Python36-32\lib\site-packages\django\views\decorators\csrf.py", line 58, in wrapped_view
    return view_func(*args, **kwargs)
  File "C:\Python36-32\lib\site-packages\django\views\generic\base.py", line 68, in view
    return self.dispatch(request, *args, **kwargs)
  File "C:\Python36-32\lib\site-packages\rest_framework\views.py", line 489, in dispatch
    response = self.handle_exception(exc)
  File "C:\Python36-32\lib\site-packages\rest_framework\views.py", line 449, in handle_exception
    self.raise_uncaught_exception(exc)
  File "C:\Python36-32\lib\site-packages\rest_framework\views.py", line 486, in dispatch
    response = handler(request, *args, **kwargs)
  File "C:\Python36-32\lib\site-packages\rest_framework\decorators.py", line 52, in handler
    return func(*args, **kwargs)
  File "D:\code\PycharmProjects\cms\focus\views.py", line 159, in index_hot
    logger.info(se.data)
  File "C:\Python36-32\lib\site-packages\rest_framework\serializers.py", line 739, in data
    ret = super(ListSerializer, self).data
  File "C:\Python36-32\lib\site-packages\rest_framework\serializers.py", line 263, in data
    self._data = self.to_representation(self.instance)
  File "C:\Python36-32\lib\site-packages\rest_framework\serializers.py", line 657, in to_representation
    self.child.to_representation(item) for item in iterable
  File "C:\Python36-32\lib\site-packages\rest_framework\serializers.py", line 657, in <listcomp>
    self.child.to_representation(item) for item in iterable
  File "C:\Python36-32\lib\site-packages\rest_framework\serializers.py", line 501, in to_representation
    ret[field.field_name] = field.to_representation(attribute)
  File "C:\Python36-32\lib\site-packages\rest_framework\serializers.py", line 484, in to_representation
    fields = self._readable_fields
  File "C:\Python36-32\lib\site-packages\django\utils\functional.py", line 35, in __get__
    res = instance.__dict__[self.name] = self.func(instance)
  File "C:\Python36-32\lib\site-packages\rest_framework\serializers.py", line 378, in _readable_fields
    field for field in self.fields.values()
  File "C:\Python36-32\lib\site-packages\rest_framework\serializers.py", line 364, in fields
    for key, value in self.get_fields().items():
  File "C:\Python36-32\lib\site-packages\rest_framework\serializers.py", line 994, in get_fields
    field_names = self.get_field_names(declared_fields, info)
  File "C:\Python36-32\lib\site-packages\rest_framework\serializers.py", line 1093, in get_field_names
    serializer_class=self.__class__.__name__
AssertionError: The field 'notes' was declared on serializer MyUserSerializer, but has not been included in the 'fields' option.
2017-10-10 16:01:23,436 [Thread-2:8672] [django.request:135] [ERROR]- Internal Server Error: /index-hot
Traceback (most recent call last):
  File "C:\Python36-32\lib\site-packages\django\core\handlers\exception.py", line 41, in inner
    response = get_response(request)
  File "C:\Python36-32\lib\site-packages\django\core\handlers\base.py", line 249, in _legacy_get_response
    response = self._get_response(request)
  File "C:\Python36-32\lib\site-packages\django\core\handlers\base.py", line 187, in _get_response
    response = self.process_exception_by_middleware(e, request)
  File "C:\Python36-32\lib\site-packages\django\core\handlers\base.py", line 185, in _get_response
    response = wrapped_callback(request, *callback_args, **callback_kwargs)
  File "C:\Python36-32\lib\site-packages\django\views\decorators\csrf.py", line 58, in wrapped_view
    return view_func(*args, **kwargs)
  File "C:\Python36-32\lib\site-packages\django\views\generic\base.py", line 68, in view
    return self.dispatch(request, *args, **kwargs)
  File "C:\Python36-32\lib\site-packages\rest_framework\views.py", line 489, in dispatch
    response = self.handle_exception(exc)
  File "C:\Python36-32\lib\site-packages\rest_framework\views.py", line 449, in handle_exception
    self.raise_uncaught_exception(exc)
  File "C:\Python36-32\lib\site-packages\rest_framework\views.py", line 486, in dispatch
    response = handler(request, *args, **kwargs)
  File "C:\Python36-32\lib\site-packages\rest_framework\decorators.py", line 52, in handler
    return func(*args, **kwargs)
  File "D:\code\PycharmProjects\cms\focus\views.py", line 159, in index_hot
    logger.info(se.data)
  File "C:\Python36-32\lib\site-packages\rest_framework\serializers.py", line 739, in data
    ret = super(ListSerializer, self).data
  File "C:\Python36-32\lib\site-packages\rest_framework\serializers.py", line 263, in data
    self._data = self.to_representation(self.instance)
  File "C:\Python36-32\lib\site-packages\rest_framework\serializers.py", line 657, in to_representation
    self.child.to_representation(item) for item in iterable
  File "C:\Python36-32\lib\site-packages\rest_framework\serializers.py", line 657, in <listcomp>
    self.child.to_representation(item) for item in iterable
  File "C:\Python36-32\lib\site-packages\rest_framework\serializers.py", line 501, in to_representation
    ret[field.field_name] = field.to_representation(attribute)
  File "C:\Python36-32\lib\site-packages\rest_framework\serializers.py", line 501, in to_representation
    ret[field.field_name] = field.to_representation(attribute)
  File "C:\Python36-32\lib\site-packages\rest_framework\relations.py", line 520, in to_representation
    for value in iterable
  File "C:\Python36-32\lib\site-packages\rest_framework\relations.py", line 520, in <listcomp>
    for value in iterable
  File "C:\Python36-32\lib\site-packages\rest_framework\relations.py", line 358, in to_representation
    "the serializer." % self.__class__.__name__
AssertionError: `HyperlinkedRelatedField` requires the request in the serializer context. Add `context={'request': request}` when instantiating the serializer.
2017-10-10 16:10:15,059 [Thread-23:2132] [django.request:152] [WARNING]- Not Found: /index-hot.json
