2017-10-26 14:32:20,337 [Thread-1:1536] [django.request:135] [ERROR]- Internal Server Error: /contents
Traceback (most recent call last):
  File "C:\Python36-32\lib\site-packages\django\core\handlers\exception.py", line 41, in inner
    response = get_response(request)
  File "C:\Python36-32\lib\site-packages\django\core\handlers\base.py", line 249, in _legacy_get_response
    response = self._get_response(request)
  File "C:\Python36-32\lib\site-packages\django\core\handlers\base.py", line 187, in _get_response
    response = self.process_exception_by_middleware(e, request)
  File "C:\Python36-32\lib\site-packages\django\core\handlers\base.py", line 185, in _get_response
    response = wrapped_callback(request, *callback_args, **callback_kwargs)
  File "C:\Python36-32\lib\site-packages\django\views\decorators\csrf.py", line 58, in wrapped_view
    return view_func(*args, **kwargs)
  File "C:\Python36-32\lib\site-packages\django\views\generic\base.py", line 68, in view
    return self.dispatch(request, *args, **kwargs)
  File "C:\Python36-32\lib\site-packages\rest_framework\views.py", line 489, in dispatch
    response = self.handle_exception(exc)
  File "C:\Python36-32\lib\site-packages\rest_framework\views.py", line 449, in handle_exception
    self.raise_uncaught_exception(exc)
  File "C:\Python36-32\lib\site-packages\rest_framework\views.py", line 486, in dispatch
    response = handler(request, *args, **kwargs)
  File "D:\code\PycharmProjects\cms\focus\views.py", line 191, in get
    if total / 0 > 1:
ZeroDivisionError: division by zero
2017-10-26 15:13:53,534 [Thread-4:1768] [django.request:152] [WARNING]- Not Found: /manager/login
2017-10-26 15:14:05,436 [Thread-21:2184] [django.request:152] [WARNING]- Not Found: /manager/login
2017-10-26 15:14:09,379 [Thread-22:15416] [django.request:152] [WARNING]- Not Found: /manager/login
2017-10-26 15:16:11,155 [Thread-18:12184] [django.request:152] [WARNING]- Not Found: /manager/login
2017-10-26 15:17:40,341 [Thread-1:9696] [django.request:152] [WARNING]- Not Found: /manager/login
2017-10-26 15:38:37,920 [Thread-1:14268] [django.request:135] [ERROR]- Internal Server Error: /v1/login/
Traceback (most recent call last):
  File "C:\Python36-32\lib\site-packages\django\utils\datastructures.py", line 83, in __getitem__
    list_ = super(MultiValueDict, self).__getitem__(key)
KeyError: 'username'

During handling of the above exception, another exception occurred:

Traceback (most recent call last):
  File "C:\Python36-32\lib\site-packages\django\core\handlers\exception.py", line 41, in inner
    response = get_response(request)
  File "C:\Python36-32\lib\site-packages\django\core\handlers\base.py", line 249, in _legacy_get_response
    response = self._get_response(request)
  File "C:\Python36-32\lib\site-packages\django\core\handlers\base.py", line 187, in _get_response
    response = self.process_exception_by_middleware(e, request)
  File "C:\Python36-32\lib\site-packages\django\core\handlers\base.py", line 185, in _get_response
    response = wrapped_callback(request, *callback_args, **callback_kwargs)
  File "D:\code\PycharmProjects\cms\manager\views.py", line 49, in log_in
    logger.debug(request.POST['username'])
  File "C:\Python36-32\lib\site-packages\django\utils\datastructures.py", line 85, in __getitem__
    raise MultiValueDictKeyError(repr(key))
django.utils.datastructures.MultiValueDictKeyError: "'username'"
2017-10-26 15:46:29,331 [Thread-6:17896] [django.request:135] [ERROR]- Internal Server Error: /v1/login/
Traceback (most recent call last):
  File "C:\Python36-32\lib\site-packages\django\utils\datastructures.py", line 83, in __getitem__
    list_ = super(MultiValueDict, self).__getitem__(key)
KeyError: '{"username":"123","password":"123"}'

During handling of the above exception, another exception occurred:

Traceback (most recent call last):
  File "C:\Python36-32\lib\site-packages\django\core\handlers\exception.py", line 41, in inner
    response = get_response(request)
  File "C:\Python36-32\lib\site-packages\django\core\handlers\base.py", line 249, in _legacy_get_response
    response = self._get_response(request)
  File "C:\Python36-32\lib\site-packages\django\core\handlers\base.py", line 187, in _get_response
    response = self.process_exception_by_middleware(e, request)
  File "C:\Python36-32\lib\site-packages\django\core\handlers\base.py", line 185, in _get_response
    response = wrapped_callback(request, *callback_args, **callback_kwargs)
  File "D:\code\PycharmProjects\cms\manager\views.py", line 50, in log_in
    logger.debug(request.POST['{"username":"123","password":"123"}'])
  File "C:\Python36-32\lib\site-packages\django\utils\datastructures.py", line 85, in __getitem__
    raise MultiValueDictKeyError(repr(key))
django.utils.datastructures.MultiValueDictKeyError: '\'{"username":"123","password":"123"}\''
2017-10-26 16:48:37,605 [Thread-1:15880] [django.request:135] [ERROR]- Internal Server Error: /v1/login/
Traceback (most recent call last):
  File "C:\Python36-32\lib\site-packages\django\core\handlers\exception.py", line 41, in inner
    response = get_response(request)
  File "C:\Python36-32\lib\site-packages\django\core\handlers\base.py", line 249, in _legacy_get_response
    response = self._get_response(request)
  File "C:\Python36-32\lib\site-packages\django\core\handlers\base.py", line 187, in _get_response
    response = self.process_exception_by_middleware(e, request)
  File "C:\Python36-32\lib\site-packages\django\core\handlers\base.py", line 185, in _get_response
    response = wrapped_callback(request, *callback_args, **callback_kwargs)
  File "D:\code\PycharmProjects\cms\manager\views.py", line 48, in log_in
    d = json.loads(request.body)
  File "C:\Python36-32\lib\json\__init__.py", line 354, in loads
    return _default_decoder.decode(s)
  File "C:\Python36-32\lib\json\decoder.py", line 339, in decode
    obj, end = self.raw_decode(s, idx=_w(s, 0).end())
  File "C:\Python36-32\lib\json\decoder.py", line 357, in raw_decode
    raise JSONDecodeError("Expecting value", s, err.value) from None
json.decoder.JSONDecodeError: Expecting value: line 1 column 1 (char 0)
2017-10-26 16:51:18,430 [Thread-1:8744] [django.request:135] [ERROR]- Internal Server Error: /v1/login/
Traceback (most recent call last):
  File "C:\Python36-32\lib\site-packages\django\core\handlers\exception.py", line 41, in inner
    response = get_response(request)
  File "C:\Python36-32\lib\site-packages\django\core\handlers\base.py", line 249, in _legacy_get_response
    response = self._get_response(request)
  File "C:\Python36-32\lib\site-packages\django\core\handlers\base.py", line 187, in _get_response
    response = self.process_exception_by_middleware(e, request)
  File "C:\Python36-32\lib\site-packages\django\core\handlers\base.py", line 185, in _get_response
    response = wrapped_callback(request, *callback_args, **callback_kwargs)
  File "D:\code\PycharmProjects\cms\manager\views.py", line 50, in log_in
    logger.debug(d.items()[0])
TypeError: 'dict_items' object does not support indexing
2017-10-26 16:51:50,262 [Thread-1:14104] [django.request:135] [ERROR]- Internal Server Error: /v1/login/
Traceback (most recent call last):
  File "C:\Python36-32\lib\site-packages\django\core\handlers\exception.py", line 41, in inner
    response = get_response(request)
  File "C:\Python36-32\lib\site-packages\django\core\handlers\base.py", line 249, in _legacy_get_response
    response = self._get_response(request)
  File "C:\Python36-32\lib\site-packages\django\core\handlers\base.py", line 187, in _get_response
    response = self.process_exception_by_middleware(e, request)
  File "C:\Python36-32\lib\site-packages\django\core\handlers\base.py", line 185, in _get_response
    response = wrapped_callback(request, *callback_args, **callback_kwargs)
  File "D:\code\PycharmProjects\cms\manager\views.py", line 50, in log_in
    logger.debug(d.items().keys())
AttributeError: 'dict_items' object has no attribute 'keys'
2017-10-26 16:52:43,598 [Thread-1:15496] [django.request:135] [ERROR]- Internal Server Error: /v1/login/
Traceback (most recent call last):
  File "C:\Python36-32\lib\site-packages\django\core\handlers\exception.py", line 41, in inner
    response = get_response(request)
  File "C:\Python36-32\lib\site-packages\django\core\handlers\base.py", line 249, in _legacy_get_response
    response = self._get_response(request)
  File "C:\Python36-32\lib\site-packages\django\core\handlers\base.py", line 187, in _get_response
    response = self.process_exception_by_middleware(e, request)
  File "C:\Python36-32\lib\site-packages\django\core\handlers\base.py", line 185, in _get_response
    response = wrapped_callback(request, *callback_args, **callback_kwargs)
  File "D:\code\PycharmProjects\cms\manager\views.py", line 50, in log_in
    logger.debug(d.items()[0])
TypeError: 'dict_items' object does not support indexing
2017-10-26 16:57:28,655 [Thread-1:11484] [django.request:135] [ERROR]- Internal Server Error: /v1/login/
Traceback (most recent call last):
  File "C:\Python36-32\lib\site-packages\django\core\handlers\exception.py", line 41, in inner
    response = get_response(request)
  File "C:\Python36-32\lib\site-packages\django\core\handlers\base.py", line 249, in _legacy_get_response
    response = self._get_response(request)
  File "C:\Python36-32\lib\site-packages\django\core\handlers\base.py", line 187, in _get_response
    response = self.process_exception_by_middleware(e, request)
  File "C:\Python36-32\lib\site-packages\django\core\handlers\base.py", line 185, in _get_response
    response = wrapped_callback(request, *callback_args, **callback_kwargs)
  File "D:\code\PycharmProjects\cms\manager\views.py", line 49, in log_in
    # d = dict(json.loads(request.body))
  File "C:\Python36-32\lib\json\__init__.py", line 354, in loads
    return _default_decoder.decode(s)
  File "C:\Python36-32\lib\json\decoder.py", line 339, in decode
    obj, end = self.raw_decode(s, idx=_w(s, 0).end())
  File "C:\Python36-32\lib\json\decoder.py", line 357, in raw_decode
    raise JSONDecodeError("Expecting value", s, err.value) from None
json.decoder.JSONDecodeError: Expecting value: line 1 column 1 (char 0)
2017-10-26 16:58:16,853 [Thread-9:2724] [django.request:135] [ERROR]- Internal Server Error: /v1/login/
Traceback (most recent call last):
  File "C:\Python36-32\lib\site-packages\django\core\handlers\exception.py", line 41, in inner
    response = get_response(request)
  File "C:\Python36-32\lib\site-packages\django\core\handlers\base.py", line 249, in _legacy_get_response
    response = self._get_response(request)
  File "C:\Python36-32\lib\site-packages\django\core\handlers\base.py", line 187, in _get_response
    response = self.process_exception_by_middleware(e, request)
  File "C:\Python36-32\lib\site-packages\django\core\handlers\base.py", line 185, in _get_response
    response = wrapped_callback(request, *callback_args, **callback_kwargs)
  File "D:\code\PycharmProjects\cms\manager\views.py", line 49, in log_in
    # d = dict(json.loads(request.body))
  File "C:\Python36-32\lib\json\__init__.py", line 354, in loads
    return _default_decoder.decode(s)
  File "C:\Python36-32\lib\json\decoder.py", line 339, in decode
    obj, end = self.raw_decode(s, idx=_w(s, 0).end())
  File "C:\Python36-32\lib\json\decoder.py", line 357, in raw_decode
    raise JSONDecodeError("Expecting value", s, err.value) from None
json.decoder.JSONDecodeError: Expecting value: line 1 column 1 (char 0)
2017-10-26 16:59:10,162 [Thread-1:9828] [django.request:135] [ERROR]- Internal Server Error: /v1/login/
Traceback (most recent call last):
  File "C:\Python36-32\lib\site-packages\django\core\handlers\exception.py", line 41, in inner
    response = get_response(request)
  File "C:\Python36-32\lib\site-packages\django\core\handlers\base.py", line 249, in _legacy_get_response
    response = self._get_response(request)
  File "C:\Python36-32\lib\site-packages\django\core\handlers\base.py", line 187, in _get_response
    response = self.process_exception_by_middleware(e, request)
  File "C:\Python36-32\lib\site-packages\django\core\handlers\base.py", line 185, in _get_response
    response = wrapped_callback(request, *callback_args, **callback_kwargs)
  File "D:\code\PycharmProjects\cms\manager\views.py", line 64, in log_in
    username, password = form.cleaned_data['username'], form.cleaned_data['password']
KeyError: 'username'
2017-10-26 16:59:21,834 [Thread-4:8752] [django.request:135] [ERROR]- Internal Server Error: /v1/login/
Traceback (most recent call last):
  File "C:\Python36-32\lib\site-packages\django\core\handlers\exception.py", line 41, in inner
    response = get_response(request)
  File "C:\Python36-32\lib\site-packages\django\core\handlers\base.py", line 249, in _legacy_get_response
    response = self._get_response(request)
  File "C:\Python36-32\lib\site-packages\django\core\handlers\base.py", line 187, in _get_response
    response = self.process_exception_by_middleware(e, request)
  File "C:\Python36-32\lib\site-packages\django\core\handlers\base.py", line 185, in _get_response
    response = wrapped_callback(request, *callback_args, **callback_kwargs)
  File "D:\code\PycharmProjects\cms\manager\views.py", line 64, in log_in
    username, password = form.cleaned_data['username'], form.cleaned_data['password']
KeyError: 'username'
2017-10-26 17:00:10,349 [Thread-1:10116] [django.request:135] [ERROR]- Internal Server Error: /v1/login/
Traceback (most recent call last):
  File "C:\Python36-32\lib\site-packages\django\core\handlers\exception.py", line 41, in inner
    response = get_response(request)
  File "C:\Python36-32\lib\site-packages\django\core\handlers\base.py", line 249, in _legacy_get_response
    response = self._get_response(request)
  File "C:\Python36-32\lib\site-packages\django\core\handlers\base.py", line 187, in _get_response
    response = self.process_exception_by_middleware(e, request)
  File "C:\Python36-32\lib\site-packages\django\core\handlers\base.py", line 185, in _get_response
    response = wrapped_callback(request, *callback_args, **callback_kwargs)
  File "D:\code\PycharmProjects\cms\manager\views.py", line 60, in log_in
    if form.is_valid():
  File "C:\Python36-32\lib\site-packages\django\forms\forms.py", line 183, in is_valid
    return self.is_bound and not self.errors
  File "C:\Python36-32\lib\site-packages\django\forms\forms.py", line 175, in errors
    self.full_clean()
  File "C:\Python36-32\lib\site-packages\django\forms\forms.py", line 384, in full_clean
    self._clean_fields()
  File "C:\Python36-32\lib\site-packages\django\forms\forms.py", line 396, in _clean_fields
    value = field.widget.value_from_datadict(self.data, self.files, self.add_prefix(name))
  File "C:\Python36-32\lib\site-packages\django\forms\widgets.py", line 240, in value_from_datadict
    return data.get(name)
AttributeError: 'str' object has no attribute 'get'
2017-10-26 17:07:26,824 [Thread-1:8580] [django.request:135] [ERROR]- Internal Server Error: /v1/login/
Traceback (most recent call last):
  File "C:\Python36-32\lib\site-packages\django\core\handlers\exception.py", line 41, in inner
    response = get_response(request)
  File "C:\Python36-32\lib\site-packages\django\core\handlers\base.py", line 249, in _legacy_get_response
    response = self._get_response(request)
  File "C:\Python36-32\lib\site-packages\django\core\handlers\base.py", line 187, in _get_response
    response = self.process_exception_by_middleware(e, request)
  File "C:\Python36-32\lib\site-packages\django\core\handlers\base.py", line 185, in _get_response
    response = wrapped_callback(request, *callback_args, **callback_kwargs)
  File "D:\code\PycharmProjects\cms\manager\views.py", line 53, in log_in
    d = QueryDict(d)
  File "C:\Python36-32\lib\site-packages\django\http\request.py", line 394, in __init__
    for key, value in limited_parse_qsl(query_string, **parse_qsl_kwargs):
  File "C:\Python36-32\lib\site-packages\django\utils\http.py", line 439, in limited_parse_qsl
    pairs = FIELDS_MATCH.split(qs, fields_limit)
TypeError: expected string or bytes-like object
2017-10-26 17:10:51,962 [Thread-4:15088] [django.request:135] [ERROR]- Internal Server Error: /v1/login/
Traceback (most recent call last):
  File "C:\Python36-32\lib\site-packages\django\core\handlers\exception.py", line 41, in inner
    response = get_response(request)
  File "C:\Python36-32\lib\site-packages\django\core\handlers\base.py", line 249, in _legacy_get_response
    response = self._get_response(request)
  File "C:\Python36-32\lib\site-packages\django\core\handlers\base.py", line 187, in _get_response
    response = self.process_exception_by_middleware(e, request)
  File "C:\Python36-32\lib\site-packages\django\core\handlers\base.py", line 185, in _get_response
    response = wrapped_callback(request, *callback_args, **callback_kwargs)
  File "D:\code\PycharmProjects\cms\manager\views.py", line 50, in log_in
    d = dict(json.loads(request.body))
  File "C:\Python36-32\lib\json\__init__.py", line 354, in loads
    return _default_decoder.decode(s)
  File "C:\Python36-32\lib\json\decoder.py", line 339, in decode
    obj, end = self.raw_decode(s, idx=_w(s, 0).end())
  File "C:\Python36-32\lib\json\decoder.py", line 357, in raw_decode
    raise JSONDecodeError("Expecting value", s, err.value) from None
json.decoder.JSONDecodeError: Expecting value: line 1 column 1 (char 0)
2017-10-26 17:41:09,210 [Thread-1:18552] [django.request:135] [ERROR]- Internal Server Error: /v1/login/
Traceback (most recent call last):
  File "C:\Python36-32\lib\site-packages\django\core\handlers\exception.py", line 41, in inner
    response = get_response(request)
  File "C:\Python36-32\lib\site-packages\django\core\handlers\base.py", line 249, in _legacy_get_response
    response = self._get_response(request)
  File "C:\Python36-32\lib\site-packages\django\core\handlers\base.py", line 187, in _get_response
    response = self.process_exception_by_middleware(e, request)
  File "C:\Python36-32\lib\site-packages\django\core\handlers\base.py", line 185, in _get_response
    response = wrapped_callback(request, *callback_args, **callback_kwargs)
  File "D:\code\PycharmProjects\cms\manager\views.py", line 55, in wrapped
    request.body = QueryDict(s)
AttributeError: can't set attribute
2017-10-26 18:13:59,339 [Thread-4:16592] [django.request:135] [ERROR]- Internal Server Error: /v1/login/
Traceback (most recent call last):
  File "C:\Python36-32\lib\site-packages\django\core\handlers\exception.py", line 41, in inner
    response = get_response(request)
  File "C:\Python36-32\lib\site-packages\django\core\handlers\base.py", line 249, in _legacy_get_response
    response = self._get_response(request)
  File "C:\Python36-32\lib\site-packages\django\core\handlers\base.py", line 187, in _get_response
    response = self.process_exception_by_middleware(e, request)
  File "C:\Python36-32\lib\site-packages\django\core\handlers\base.py", line 185, in _get_response
    response = wrapped_callback(request, *callback_args, **callback_kwargs)
  File "D:\code\PycharmProjects\cms\manager\views.py", line 49, in wrapped
    d = dict(json.loads(request.body))
  File "C:\Python36-32\lib\json\__init__.py", line 354, in loads
    return _default_decoder.decode(s)
  File "C:\Python36-32\lib\json\decoder.py", line 339, in decode
    obj, end = self.raw_decode(s, idx=_w(s, 0).end())
  File "C:\Python36-32\lib\json\decoder.py", line 357, in raw_decode
    raise JSONDecodeError("Expecting value", s, err.value) from None
json.decoder.JSONDecodeError: Expecting value: line 1 column 1 (char 0)
2017-10-26 18:14:15,771 [Thread-6:17932] [django.request:135] [ERROR]- Internal Server Error: /v1/login/
Traceback (most recent call last):
  File "C:\Python36-32\lib\site-packages\django\core\handlers\exception.py", line 41, in inner
    response = get_response(request)
  File "C:\Python36-32\lib\site-packages\django\core\handlers\base.py", line 249, in _legacy_get_response
    response = self._get_response(request)
  File "C:\Python36-32\lib\site-packages\django\core\handlers\base.py", line 187, in _get_response
    response = self.process_exception_by_middleware(e, request)
  File "C:\Python36-32\lib\site-packages\django\core\handlers\base.py", line 185, in _get_response
    response = wrapped_callback(request, *callback_args, **callback_kwargs)
  File "D:\code\PycharmProjects\cms\manager\views.py", line 49, in wrapped
    d = dict(json.loads(request.body))
  File "C:\Python36-32\lib\json\__init__.py", line 354, in loads
    return _default_decoder.decode(s)
  File "C:\Python36-32\lib\json\decoder.py", line 339, in decode
    obj, end = self.raw_decode(s, idx=_w(s, 0).end())
  File "C:\Python36-32\lib\json\decoder.py", line 357, in raw_decode
    raise JSONDecodeError("Expecting value", s, err.value) from None
json.decoder.JSONDecodeError: Expecting value: line 1 column 1 (char 0)
2017-10-26 18:15:00,304 [Thread-3:9748] [django.request:135] [ERROR]- Internal Server Error: /v1/login/
Traceback (most recent call last):
  File "C:\Python36-32\lib\site-packages\django\core\handlers\exception.py", line 41, in inner
    response = get_response(request)
  File "C:\Python36-32\lib\site-packages\django\core\handlers\base.py", line 249, in _legacy_get_response
    response = self._get_response(request)
  File "C:\Python36-32\lib\site-packages\django\core\handlers\base.py", line 187, in _get_response
    response = self.process_exception_by_middleware(e, request)
  File "C:\Python36-32\lib\site-packages\django\core\handlers\base.py", line 185, in _get_response
    response = wrapped_callback(request, *callback_args, **callback_kwargs)
  File "D:\code\PycharmProjects\cms\manager\views.py", line 49, in wrapped
    d = dict(json.loads(request.body))
  File "C:\Python36-32\lib\json\__init__.py", line 354, in loads
    return _default_decoder.decode(s)
  File "C:\Python36-32\lib\json\decoder.py", line 339, in decode
    obj, end = self.raw_decode(s, idx=_w(s, 0).end())
  File "C:\Python36-32\lib\json\decoder.py", line 357, in raw_decode
    raise JSONDecodeError("Expecting value", s, err.value) from None
json.decoder.JSONDecodeError: Expecting value: line 1 column 1 (char 0)
2017-10-26 18:21:56,769 [Thread-4:15196] [django.request:135] [ERROR]- Internal Server Error: /v1/login/
Traceback (most recent call last):
  File "C:\Python36-32\lib\site-packages\django\core\handlers\exception.py", line 41, in inner
    response = get_response(request)
  File "C:\Python36-32\lib\site-packages\django\core\handlers\base.py", line 249, in _legacy_get_response
    response = self._get_response(request)
  File "C:\Python36-32\lib\site-packages\django\core\handlers\base.py", line 187, in _get_response
    response = self.process_exception_by_middleware(e, request)
  File "C:\Python36-32\lib\site-packages\django\core\handlers\base.py", line 185, in _get_response
    response = wrapped_callback(request, *callback_args, **callback_kwargs)
  File "D:\code\PycharmProjects\cms\manager\views.py", line 49, in wrapped
    d = dict(json.loads(request.body))
  File "C:\Python36-32\lib\json\__init__.py", line 354, in loads
    return _default_decoder.decode(s)
  File "C:\Python36-32\lib\json\decoder.py", line 339, in decode
    obj, end = self.raw_decode(s, idx=_w(s, 0).end())
  File "C:\Python36-32\lib\json\decoder.py", line 357, in raw_decode
    raise JSONDecodeError("Expecting value", s, err.value) from None
json.decoder.JSONDecodeError: Expecting value: line 1 column 1 (char 0)
2017-10-26 18:22:07,917 [Thread-6:15540] [django.request:135] [ERROR]- Internal Server Error: /v1/login/
Traceback (most recent call last):
  File "C:\Python36-32\lib\site-packages\django\core\handlers\exception.py", line 41, in inner
    response = get_response(request)
  File "C:\Python36-32\lib\site-packages\django\core\handlers\base.py", line 249, in _legacy_get_response
    response = self._get_response(request)
  File "C:\Python36-32\lib\site-packages\django\core\handlers\base.py", line 187, in _get_response
    response = self.process_exception_by_middleware(e, request)
  File "C:\Python36-32\lib\site-packages\django\core\handlers\base.py", line 185, in _get_response
    response = wrapped_callback(request, *callback_args, **callback_kwargs)
  File "D:\code\PycharmProjects\cms\manager\views.py", line 49, in wrapped
    d = dict(json.loads(request.body))
  File "C:\Python36-32\lib\json\__init__.py", line 354, in loads
    return _default_decoder.decode(s)
  File "C:\Python36-32\lib\json\decoder.py", line 339, in decode
    obj, end = self.raw_decode(s, idx=_w(s, 0).end())
  File "C:\Python36-32\lib\json\decoder.py", line 357, in raw_decode
    raise JSONDecodeError("Expecting value", s, err.value) from None
json.decoder.JSONDecodeError: Expecting value: line 1 column 1 (char 0)
2017-10-26 18:36:05,433 [Thread-10:15208] [django.request:135] [ERROR]- Internal Server Error: /v1/login/
Traceback (most recent call last):
  File "C:\Python36-32\lib\site-packages\django\core\handlers\exception.py", line 41, in inner
    response = get_response(request)
  File "C:\Python36-32\lib\site-packages\django\core\handlers\base.py", line 249, in _legacy_get_response
    response = self._get_response(request)
  File "C:\Python36-32\lib\site-packages\django\core\handlers\base.py", line 187, in _get_response
    response = self.process_exception_by_middleware(e, request)
  File "C:\Python36-32\lib\site-packages\django\core\handlers\base.py", line 185, in _get_response
    response = wrapped_callback(request, *callback_args, **callback_kwargs)
  File "D:\code\PycharmProjects\cms\manager\views.py", line 49, in wrapped
    d = dict(json.loads(request.body))
  File "C:\Python36-32\lib\json\__init__.py", line 354, in loads
    return _default_decoder.decode(s)
  File "C:\Python36-32\lib\json\decoder.py", line 339, in decode
    obj, end = self.raw_decode(s, idx=_w(s, 0).end())
  File "C:\Python36-32\lib\json\decoder.py", line 357, in raw_decode
    raise JSONDecodeError("Expecting value", s, err.value) from None
json.decoder.JSONDecodeError: Expecting value: line 1 column 1 (char 0)
2017-10-26 18:38:26,204 [Thread-14:19088] [django.request:135] [ERROR]- Internal Server Error: /v1/login/
Traceback (most recent call last):
  File "C:\Python36-32\lib\site-packages\django\core\handlers\exception.py", line 41, in inner
    response = get_response(request)
  File "C:\Python36-32\lib\site-packages\django\core\handlers\base.py", line 249, in _legacy_get_response
    response = self._get_response(request)
  File "C:\Python36-32\lib\site-packages\django\core\handlers\base.py", line 187, in _get_response
    response = self.process_exception_by_middleware(e, request)
  File "C:\Python36-32\lib\site-packages\django\core\handlers\base.py", line 185, in _get_response
    response = wrapped_callback(request, *callback_args, **callback_kwargs)
  File "D:\code\PycharmProjects\cms\manager\views.py", line 49, in wrapped
    d = dict(json.loads(request.body))
  File "C:\Python36-32\lib\json\__init__.py", line 354, in loads
    return _default_decoder.decode(s)
  File "C:\Python36-32\lib\json\decoder.py", line 339, in decode
    obj, end = self.raw_decode(s, idx=_w(s, 0).end())
  File "C:\Python36-32\lib\json\decoder.py", line 357, in raw_decode
    raise JSONDecodeError("Expecting value", s, err.value) from None
json.decoder.JSONDecodeError: Expecting value: line 1 column 1 (char 0)
2017-10-26 19:01:56,817 [Thread-1:15832] [django.request:135] [ERROR]- Internal Server Error: /v1/login/
Traceback (most recent call last):
  File "C:\Python36-32\lib\site-packages\django\core\handlers\exception.py", line 41, in inner
    response = get_response(request)
  File "C:\Python36-32\lib\site-packages\django\core\handlers\base.py", line 249, in _legacy_get_response
    response = self._get_response(request)
  File "C:\Python36-32\lib\site-packages\django\core\handlers\base.py", line 187, in _get_response
    response = self.process_exception_by_middleware(e, request)
  File "C:\Python36-32\lib\site-packages\django\core\handlers\base.py", line 185, in _get_response
    response = wrapped_callback(request, *callback_args, **callback_kwargs)
  File "D:\code\PycharmProjects\cms\manager\views.py", line 49, in wrapped
    d = dict(json.loads(request.body))
  File "C:\Python36-32\lib\json\__init__.py", line 354, in loads
    return _default_decoder.decode(s)
  File "C:\Python36-32\lib\json\decoder.py", line 339, in decode
    obj, end = self.raw_decode(s, idx=_w(s, 0).end())
  File "C:\Python36-32\lib\json\decoder.py", line 357, in raw_decode
    raise JSONDecodeError("Expecting value", s, err.value) from None
json.decoder.JSONDecodeError: Expecting value: line 1 column 1 (char 0)
2017-10-26 19:02:02,741 [Thread-3:17284] [django.request:135] [ERROR]- Internal Server Error: /v1/login/
Traceback (most recent call last):
  File "C:\Python36-32\lib\site-packages\django\core\handlers\exception.py", line 41, in inner
    response = get_response(request)
  File "C:\Python36-32\lib\site-packages\django\core\handlers\base.py", line 249, in _legacy_get_response
    response = self._get_response(request)
  File "C:\Python36-32\lib\site-packages\django\core\handlers\base.py", line 187, in _get_response
    response = self.process_exception_by_middleware(e, request)
  File "C:\Python36-32\lib\site-packages\django\core\handlers\base.py", line 185, in _get_response
    response = wrapped_callback(request, *callback_args, **callback_kwargs)
  File "D:\code\PycharmProjects\cms\manager\views.py", line 49, in wrapped
    d = dict(json.loads(request.body))
  File "C:\Python36-32\lib\json\__init__.py", line 354, in loads
    return _default_decoder.decode(s)
  File "C:\Python36-32\lib\json\decoder.py", line 339, in decode
    obj, end = self.raw_decode(s, idx=_w(s, 0).end())
  File "C:\Python36-32\lib\json\decoder.py", line 357, in raw_decode
    raise JSONDecodeError("Expecting value", s, err.value) from None
json.decoder.JSONDecodeError: Expecting value: line 1 column 1 (char 0)
2017-10-27 11:02:08,958 [Thread-8:17352] [django.request:152] [WARNING]- Not Found: /v1/login/
2017-10-27 11:05:09,134 [Thread-1:18268] [django.request:152] [WARNING]- Not Found: /v1/login/
2017-10-27 14:13:55,291 [Thread-1:17952] [django.request:135] [ERROR]- Internal Server Error: /contents
Traceback (most recent call last):
  File "C:\Python36-32\lib\site-packages\rest_framework\fields.py", line 444, in get_attribute
    return get_attribute(instance, self.source_attrs)
  File "C:\Python36-32\lib\site-packages\rest_framework\fields.py", line 103, in get_attribute
    instance = getattr(instance, attr)
AttributeError: 'AnonymousUser' object has no attribute 'avatar'

During handling of the above exception, another exception occurred:

Traceback (most recent call last):
  File "C:\Python36-32\lib\site-packages\django\core\handlers\exception.py", line 41, in inner
    response = get_response(request)
  File "C:\Python36-32\lib\site-packages\django\core\handlers\base.py", line 249, in _legacy_get_response
    response = self._get_response(request)
  File "C:\Python36-32\lib\site-packages\django\core\handlers\base.py", line 187, in _get_response
    response = self.process_exception_by_middleware(e, request)
  File "C:\Python36-32\lib\site-packages\django\core\handlers\base.py", line 185, in _get_response
    response = wrapped_callback(request, *callback_args, **callback_kwargs)
  File "C:\Python36-32\lib\site-packages\django\views\decorators\csrf.py", line 58, in wrapped_view
    return view_func(*args, **kwargs)
  File "C:\Python36-32\lib\site-packages\django\views\generic\base.py", line 68, in view
    return self.dispatch(request, *args, **kwargs)
  File "C:\Python36-32\lib\site-packages\rest_framework\views.py", line 489, in dispatch
    response = self.handle_exception(exc)
  File "C:\Python36-32\lib\site-packages\rest_framework\views.py", line 449, in handle_exception
    self.raise_uncaught_exception(exc)
  File "C:\Python36-32\lib\site-packages\rest_framework\views.py", line 486, in dispatch
    response = handler(request, *args, **kwargs)
  File "D:\code\PycharmProjects\cms\focus\views.py", line 202, in get
    logger.debug(user.data)
  File "C:\Python36-32\lib\site-packages\rest_framework\serializers.py", line 534, in data
    ret = super(Serializer, self).data
  File "C:\Python36-32\lib\site-packages\rest_framework\serializers.py", line 263, in data
    self._data = self.to_representation(self.instance)
  File "C:\Python36-32\lib\site-packages\rest_framework\serializers.py", line 488, in to_representation
    attribute = field.get_attribute(instance)
  File "C:\Python36-32\lib\site-packages\rest_framework\fields.py", line 463, in get_attribute
    raise type(exc)(msg)
AttributeError: Got AttributeError when attempting to get a value for field `avatar` on serializer `MyUserSerializer`.
The serializer field might be named incorrectly and not match any attribute or key on the `AnonymousUser` instance.
Original exception text was: 'AnonymousUser' object has no attribute 'avatar'.
2017-10-27 16:37:28,897 [Thread-12:18492] [django.request:152] [WARNING]- Not Found: /manager/signup/
2017-10-27 16:37:55,152 [Thread-14:17248] [django.request:152] [WARNING]- Not Found: /manager/signup/
2017-10-27 19:21:30,212 [Thread-52:21280] [django.request:135] [ERROR]- Internal Server Error: /manager/signup
Traceback (most recent call last):
  File "C:\Python36-32\lib\site-packages\django\core\handlers\exception.py", line 41, in inner
    response = get_response(request)
  File "C:\Python36-32\lib\site-packages\django\core\handlers\base.py", line 244, in _legacy_get_response
    response = middleware_method(request)
  File "C:\Python36-32\lib\site-packages\django\middleware\common.py", line 63, in process_request
    path = self.get_full_path_with_slash(request)
  File "C:\Python36-32\lib\site-packages\django\middleware\common.py", line 101, in get_full_path_with_slash
    'url': request.get_host() + new_path,
RuntimeError: You called this URL via POST, but the URL doesn't end in a slash and you have APPEND_SLASH set. Django can't redirect to the slash URL while maintaining POST data. Change your form to point to localhost:8008/manager/signup/ (note the trailing slash), or set APPEND_SLASH=False in your Django settings.
2017-10-27 19:22:21,318 [Thread-54:20744] [django.request:135] [ERROR]- Internal Server Error: /manager/signup
Traceback (most recent call last):
  File "C:\Python36-32\lib\site-packages\django\core\handlers\exception.py", line 41, in inner
    response = get_response(request)
  File "C:\Python36-32\lib\site-packages\django\core\handlers\base.py", line 244, in _legacy_get_response
    response = middleware_method(request)
  File "C:\Python36-32\lib\site-packages\django\middleware\common.py", line 63, in process_request
    path = self.get_full_path_with_slash(request)
  File "C:\Python36-32\lib\site-packages\django\middleware\common.py", line 101, in get_full_path_with_slash
    'url': request.get_host() + new_path,
RuntimeError: You called this URL via POST, but the URL doesn't end in a slash and you have APPEND_SLASH set. Django can't redirect to the slash URL while maintaining POST data. Change your form to point to localhost:8008/manager/signup/ (note the trailing slash), or set APPEND_SLASH=False in your Django settings.
2017-10-27 22:07:26,641 [Thread-5:7760] [django.request:152] [WARNING]- Not Found: /manager/login/
2017-10-27 22:08:32,831 [Thread-9:7724] [django.request:152] [WARNING]- Not Found: /manager/login/
2017-10-27 22:09:38,764 [Thread-11:6256] [django.request:152] [WARNING]- Not Found: /manager/login/
2017-10-27 22:10:48,612 [Thread-13:11288] [django.request:152] [WARNING]- Not Found: /manager/login/
2017-10-28 11:48:54,246 [Thread-17:10408] [django.request:135] [ERROR]- Internal Server Error: /user/focus/publish
Traceback (most recent call last):
  File "D:\ProgramData\Python36-32\lib\site-packages\django\template\base.py", line 882, in _resolve_lookup
    current = current[bit]
TypeError: 'ImageFieldFile' object is not subscriptable

During handling of the above exception, another exception occurred:

Traceback (most recent call last):
  File "D:\ProgramData\Python36-32\lib\site-packages\django\core\handlers\exception.py", line 41, in inner
    response = get_response(request)
  File "D:\ProgramData\Python36-32\lib\site-packages\django\core\handlers\base.py", line 249, in _legacy_get_response
    response = self._get_response(request)
  File "D:\ProgramData\Python36-32\lib\site-packages\django\core\handlers\base.py", line 187, in _get_response
    response = self.process_exception_by_middleware(e, request)
  File "D:\ProgramData\Python36-32\lib\site-packages\django\core\handlers\base.py", line 185, in _get_response
    response = wrapped_callback(request, *callback_args, **callback_kwargs)
  File "D:\Code\PycharmProjects\cms\focus\views.py", line 565, in user_publish
    return render(request, 'focus/u-publish.html', context)
  File "D:\ProgramData\Python36-32\lib\site-packages\django\shortcuts.py", line 30, in render
    content = loader.render_to_string(template_name, context, request, using=using)
  File "D:\ProgramData\Python36-32\lib\site-packages\django\template\loader.py", line 68, in render_to_string
    return template.render(context, request)
  File "D:\ProgramData\Python36-32\lib\site-packages\django\template\backends\django.py", line 66, in render
    return self.template.render(context)
  File "D:\ProgramData\Python36-32\lib\site-packages\django\template\base.py", line 207, in render
    return self._render(context)
  File "D:\ProgramData\Python36-32\lib\site-packages\django\template\base.py", line 199, in _render
    return self.nodelist.render(context)
  File "D:\ProgramData\Python36-32\lib\site-packages\django\template\base.py", line 990, in render
    bit = node.render_annotated(context)
  File "D:\ProgramData\Python36-32\lib\site-packages\django\template\base.py", line 957, in render_annotated
    return self.render(context)
  File "D:\ProgramData\Python36-32\lib\site-packages\django\template\base.py", line 1040, in render
    output = self.filter_expression.resolve(context)
  File "D:\ProgramData\Python36-32\lib\site-packages\django\template\base.py", line 708, in resolve
    obj = self.var.resolve(context)
  File "D:\ProgramData\Python36-32\lib\site-packages\django\template\base.py", line 849, in resolve
    value = self._resolve_lookup(context)
  File "D:\ProgramData\Python36-32\lib\site-packages\django\template\base.py", line 890, in _resolve_lookup
    current = getattr(current, bit)
  File "D:\ProgramData\Python36-32\lib\site-packages\django\db\models\fields\files.py", line 69, in url
    self._require_file()
  File "D:\ProgramData\Python36-32\lib\site-packages\django\db\models\fields\files.py", line 46, in _require_file
    raise ValueError("The '%s' attribute has no file associated with it." % self.field.name)
ValueError: The 'avatar' attribute has no file associated with it.
2017-10-28 11:48:54,905 [Thread-18:1288] [django.request:152] [WARNING]- Not Found: /favicon.ico
2017-10-28 19:36:15,522 [Thread-1:7708] [django.request:135] [ERROR]- Internal Server Error: /contents
Traceback (most recent call last):
  File "D:\ProgramData\Python36-32\lib\site-packages\django\core\handlers\exception.py", line 41, in inner
    response = get_response(request)
  File "D:\ProgramData\Python36-32\lib\site-packages\django\core\handlers\base.py", line 249, in _legacy_get_response
    response = self._get_response(request)
  File "D:\ProgramData\Python36-32\lib\site-packages\django\core\handlers\base.py", line 187, in _get_response
    response = self.process_exception_by_middleware(e, request)
  File "D:\ProgramData\Python36-32\lib\site-packages\django\core\handlers\base.py", line 185, in _get_response
    response = wrapped_callback(request, *callback_args, **callback_kwargs)
TypeError: contents() takes 0 positional arguments but 1 was given
2017-10-28 20:36:38,588 [Thread-18:12832] [django.request:152] [WARNING]- Not Found: /contents2
2017-10-28 20:40:06,911 [Thread-1:1212] [django.request:135] [ERROR]- Internal Server Error: /contents2
Traceback (most recent call last):
  File "D:\ProgramData\Python36-32\lib\site-packages\django\core\handlers\exception.py", line 41, in inner
    response = get_response(request)
  File "D:\ProgramData\Python36-32\lib\site-packages\django\core\handlers\base.py", line 249, in _legacy_get_response
    response = self._get_response(request)
  File "D:\ProgramData\Python36-32\lib\site-packages\django\core\handlers\base.py", line 187, in _get_response
    response = self.process_exception_by_middleware(e, request)
  File "D:\ProgramData\Python36-32\lib\site-packages\django\core\handlers\base.py", line 185, in _get_response
    response = wrapped_callback(request, *callback_args, **callback_kwargs)
  File "D:\ProgramData\Python36-32\lib\site-packages\django\views\decorators\csrf.py", line 58, in wrapped_view
    return view_func(*args, **kwargs)
  File "D:\ProgramData\Python36-32\lib\site-packages\django\views\generic\base.py", line 68, in view
    return self.dispatch(request, *args, **kwargs)
  File "D:\ProgramData\Python36-32\lib\site-packages\rest_framework\views.py", line 489, in dispatch
    response = self.handle_exception(exc)
  File "D:\ProgramData\Python36-32\lib\site-packages\rest_framework\views.py", line 449, in handle_exception
    self.raise_uncaught_exception(exc)
  File "D:\ProgramData\Python36-32\lib\site-packages\rest_framework\views.py", line 486, in dispatch
    response = handler(request, *args, **kwargs)
TypeError: post() takes 1 positional argument but 2 were given
2017-10-28 21:07:52,281 [Thread-1:10640] [django.request:135] [ERROR]- Internal Server Error: /contents2
Traceback (most recent call last):
  File "D:\ProgramData\Python36-32\lib\site-packages\django\core\handlers\exception.py", line 41, in inner
    response = get_response(request)
  File "D:\ProgramData\Python36-32\lib\site-packages\django\core\handlers\base.py", line 249, in _legacy_get_response
    response = self._get_response(request)
  File "D:\ProgramData\Python36-32\lib\site-packages\django\core\handlers\base.py", line 187, in _get_response
    response = self.process_exception_by_middleware(e, request)
  File "D:\ProgramData\Python36-32\lib\site-packages\django\core\handlers\base.py", line 185, in _get_response
    response = wrapped_callback(request, *callback_args, **callback_kwargs)
TypeError: __init__() takes 1 positional argument but 2 were given
2017-10-28 22:13:51,754 [Thread-4:9228] [django.request:135] [ERROR]- Internal Server Error: /manager/login
Traceback (most recent call last):
  File "D:\ProgramData\Python36-32\lib\site-packages\django\core\handlers\exception.py", line 41, in inner
    response = get_response(request)
  File "D:\ProgramData\Python36-32\lib\site-packages\django\core\handlers\base.py", line 249, in _legacy_get_response
    response = self._get_response(request)
  File "D:\ProgramData\Python36-32\lib\site-packages\django\core\handlers\base.py", line 187, in _get_response
    response = self.process_exception_by_middleware(e, request)
  File "D:\ProgramData\Python36-32\lib\site-packages\django\core\handlers\base.py", line 185, in _get_response
    response = wrapped_callback(request, *callback_args, **callback_kwargs)
  File "D:\ProgramData\Python36-32\lib\site-packages\django\views\decorators\csrf.py", line 58, in wrapped_view
    return view_func(*args, **kwargs)
  File "D:\ProgramData\Python36-32\lib\site-packages\django\views\generic\base.py", line 68, in view
    return self.dispatch(request, *args, **kwargs)
  File "D:\ProgramData\Python36-32\lib\site-packages\rest_framework\views.py", line 489, in dispatch
    response = self.handle_exception(exc)
  File "D:\ProgramData\Python36-32\lib\site-packages\rest_framework\views.py", line 449, in handle_exception
    self.raise_uncaught_exception(exc)
  File "D:\ProgramData\Python36-32\lib\site-packages\rest_framework\views.py", line 486, in dispatch
    response = handler(request, *args, **kwargs)
TypeError: wrapped() takes 1 positional argument but 2 were given
2017-10-28 22:13:55,899 [Thread-5:8300] [django.request:135] [ERROR]- Internal Server Error: /manager/login
Traceback (most recent call last):
  File "D:\ProgramData\Python36-32\lib\site-packages\django\core\handlers\exception.py", line 41, in inner
    response = get_response(request)
  File "D:\ProgramData\Python36-32\lib\site-packages\django\core\handlers\base.py", line 249, in _legacy_get_response
    response = self._get_response(request)
  File "D:\ProgramData\Python36-32\lib\site-packages\django\core\handlers\base.py", line 187, in _get_response
    response = self.process_exception_by_middleware(e, request)
  File "D:\ProgramData\Python36-32\lib\site-packages\django\core\handlers\base.py", line 185, in _get_response
    response = wrapped_callback(request, *callback_args, **callback_kwargs)
  File "D:\ProgramData\Python36-32\lib\site-packages\django\views\decorators\csrf.py", line 58, in wrapped_view
    return view_func(*args, **kwargs)
  File "D:\ProgramData\Python36-32\lib\site-packages\django\views\generic\base.py", line 68, in view
    return self.dispatch(request, *args, **kwargs)
  File "D:\ProgramData\Python36-32\lib\site-packages\rest_framework\views.py", line 489, in dispatch
    response = self.handle_exception(exc)
  File "D:\ProgramData\Python36-32\lib\site-packages\rest_framework\views.py", line 449, in handle_exception
    self.raise_uncaught_exception(exc)
  File "D:\ProgramData\Python36-32\lib\site-packages\rest_framework\views.py", line 486, in dispatch
    response = handler(request, *args, **kwargs)
TypeError: wrapped() takes 1 positional argument but 2 were given
2017-10-28 22:15:13,958 [Thread-1:9452] [django.request:135] [ERROR]- Internal Server Error: /manager/login
Traceback (most recent call last):
  File "D:\ProgramData\Python36-32\lib\site-packages\django\core\handlers\exception.py", line 41, in inner
    response = get_response(request)
  File "D:\ProgramData\Python36-32\lib\site-packages\django\core\handlers\base.py", line 249, in _legacy_get_response
    response = self._get_response(request)
  File "D:\ProgramData\Python36-32\lib\site-packages\django\core\handlers\base.py", line 187, in _get_response
    response = self.process_exception_by_middleware(e, request)
  File "D:\ProgramData\Python36-32\lib\site-packages\django\core\handlers\base.py", line 185, in _get_response
    response = wrapped_callback(request, *callback_args, **callback_kwargs)
  File "D:\ProgramData\Python36-32\lib\site-packages\django\views\decorators\csrf.py", line 58, in wrapped_view
    return view_func(*args, **kwargs)
  File "D:\ProgramData\Python36-32\lib\site-packages\django\views\generic\base.py", line 68, in view
    return self.dispatch(request, *args, **kwargs)
  File "D:\ProgramData\Python36-32\lib\site-packages\rest_framework\views.py", line 489, in dispatch
    response = self.handle_exception(exc)
  File "D:\ProgramData\Python36-32\lib\site-packages\rest_framework\views.py", line 449, in handle_exception
    self.raise_uncaught_exception(exc)
  File "D:\ProgramData\Python36-32\lib\site-packages\rest_framework\views.py", line 486, in dispatch
    response = handler(request, *args, **kwargs)
  File "D:\Code\PycharmProjects\cms\manager\views.py", line 58, in wrapped
    return fun(request)
TypeError: post() missing 1 required positional argument: 'request'
2017-10-28 22:15:31,711 [Thread-5:11024] [django.request:135] [ERROR]- Internal Server Error: /manager/login
Traceback (most recent call last):
  File "D:\ProgramData\Python36-32\lib\site-packages\django\core\handlers\exception.py", line 41, in inner
    response = get_response(request)
  File "D:\ProgramData\Python36-32\lib\site-packages\django\core\handlers\base.py", line 249, in _legacy_get_response
    response = self._get_response(request)
  File "D:\ProgramData\Python36-32\lib\site-packages\django\core\handlers\base.py", line 187, in _get_response
    response = self.process_exception_by_middleware(e, request)
  File "D:\ProgramData\Python36-32\lib\site-packages\django\core\handlers\base.py", line 185, in _get_response
    response = wrapped_callback(request, *callback_args, **callback_kwargs)
  File "D:\ProgramData\Python36-32\lib\site-packages\django\views\decorators\csrf.py", line 58, in wrapped_view
    return view_func(*args, **kwargs)
  File "D:\ProgramData\Python36-32\lib\site-packages\django\views\generic\base.py", line 68, in view
    return self.dispatch(request, *args, **kwargs)
  File "D:\ProgramData\Python36-32\lib\site-packages\rest_framework\views.py", line 489, in dispatch
    response = self.handle_exception(exc)
  File "D:\ProgramData\Python36-32\lib\site-packages\rest_framework\views.py", line 449, in handle_exception
    self.raise_uncaught_exception(exc)
  File "D:\ProgramData\Python36-32\lib\site-packages\rest_framework\views.py", line 486, in dispatch
    response = handler(request, *args, **kwargs)
  File "D:\Code\PycharmProjects\cms\manager\views.py", line 58, in wrapped
    return fun(request)
TypeError: post() missing 1 required positional argument: 'request'
2017-10-28 22:17:07,486 [Thread-4:7448] [django.request:135] [ERROR]- Internal Server Error: /manager/login
Traceback (most recent call last):
  File "D:\ProgramData\Python36-32\lib\site-packages\django\core\handlers\exception.py", line 41, in inner
    response = get_response(request)
  File "D:\ProgramData\Python36-32\lib\site-packages\django\core\handlers\base.py", line 249, in _legacy_get_response
    response = self._get_response(request)
  File "D:\ProgramData\Python36-32\lib\site-packages\django\core\handlers\base.py", line 187, in _get_response
    response = self.process_exception_by_middleware(e, request)
  File "D:\ProgramData\Python36-32\lib\site-packages\django\core\handlers\base.py", line 185, in _get_response
    response = wrapped_callback(request, *callback_args, **callback_kwargs)
  File "D:\ProgramData\Python36-32\lib\site-packages\django\views\decorators\csrf.py", line 58, in wrapped_view
    return view_func(*args, **kwargs)
  File "D:\ProgramData\Python36-32\lib\site-packages\django\views\generic\base.py", line 68, in view
    return self.dispatch(request, *args, **kwargs)
  File "D:\ProgramData\Python36-32\lib\site-packages\rest_framework\views.py", line 489, in dispatch
    response = self.handle_exception(exc)
  File "D:\ProgramData\Python36-32\lib\site-packages\rest_framework\views.py", line 449, in handle_exception
    self.raise_uncaught_exception(exc)
  File "D:\ProgramData\Python36-32\lib\site-packages\rest_framework\views.py", line 486, in dispatch
    response = handler(request, *args, **kwargs)
TypeError: wrapped() takes 1 positional argument but 2 were given
2017-10-28 22:17:08,631 [Thread-5:11612] [django.request:135] [ERROR]- Internal Server Error: /manager/login
Traceback (most recent call last):
  File "D:\ProgramData\Python36-32\lib\site-packages\django\core\handlers\exception.py", line 41, in inner
    response = get_response(request)
  File "D:\ProgramData\Python36-32\lib\site-packages\django\core\handlers\base.py", line 249, in _legacy_get_response
    response = self._get_response(request)
  File "D:\ProgramData\Python36-32\lib\site-packages\django\core\handlers\base.py", line 187, in _get_response
    response = self.process_exception_by_middleware(e, request)
  File "D:\ProgramData\Python36-32\lib\site-packages\django\core\handlers\base.py", line 185, in _get_response
    response = wrapped_callback(request, *callback_args, **callback_kwargs)
  File "D:\ProgramData\Python36-32\lib\site-packages\django\views\decorators\csrf.py", line 58, in wrapped_view
    return view_func(*args, **kwargs)
  File "D:\ProgramData\Python36-32\lib\site-packages\django\views\generic\base.py", line 68, in view
    return self.dispatch(request, *args, **kwargs)
  File "D:\ProgramData\Python36-32\lib\site-packages\rest_framework\views.py", line 489, in dispatch
    response = self.handle_exception(exc)
  File "D:\ProgramData\Python36-32\lib\site-packages\rest_framework\views.py", line 449, in handle_exception
    self.raise_uncaught_exception(exc)
  File "D:\ProgramData\Python36-32\lib\site-packages\rest_framework\views.py", line 486, in dispatch
    response = handler(request, *args, **kwargs)
TypeError: wrapped() takes 1 positional argument but 2 were given
2017-10-28 22:22:43,989 [Thread-4:8808] [django.request:135] [ERROR]- Internal Server Error: /manager/login
Traceback (most recent call last):
  File "D:\ProgramData\Python36-32\lib\site-packages\django\core\handlers\exception.py", line 41, in inner
    response = get_response(request)
  File "D:\ProgramData\Python36-32\lib\site-packages\django\core\handlers\base.py", line 249, in _legacy_get_response
    response = self._get_response(request)
  File "D:\ProgramData\Python36-32\lib\site-packages\django\core\handlers\base.py", line 187, in _get_response
    response = self.process_exception_by_middleware(e, request)
  File "D:\ProgramData\Python36-32\lib\site-packages\django\core\handlers\base.py", line 185, in _get_response
    response = wrapped_callback(request, *callback_args, **callback_kwargs)
  File "D:\ProgramData\Python36-32\lib\site-packages\django\views\decorators\csrf.py", line 58, in wrapped_view
    return view_func(*args, **kwargs)
  File "D:\ProgramData\Python36-32\lib\site-packages\django\views\generic\base.py", line 68, in view
    return self.dispatch(request, *args, **kwargs)
  File "D:\ProgramData\Python36-32\lib\site-packages\rest_framework\views.py", line 489, in dispatch
    response = self.handle_exception(exc)
  File "D:\ProgramData\Python36-32\lib\site-packages\rest_framework\views.py", line 449, in handle_exception
    self.raise_uncaught_exception(exc)
  File "D:\ProgramData\Python36-32\lib\site-packages\rest_framework\views.py", line 486, in dispatch
    response = handler(request, *args, **kwargs)
  File "D:\Code\PycharmProjects\cms\manager\views.py", line 58, in wrapped
    return fun(request)
TypeError: post() missing 1 required positional argument: 'request'
2017-10-28 22:38:51,124 [Thread-1:12460] [django.request:152] [WARNING]- Not Found: /docs/
2017-10-28 22:45:52,772 [Thread-1:14260] [django.request:152] [WARNING]- Not Found: /api
2017-10-29 14:16:15,746 [Thread-1:4520] [django.request:152] [WARNING]- Not Found: /manager/logout/
2017-10-29 14:16:25,175 [Thread-4:7096] [django.request:152] [WARNING]- Not Found: /manager/logout/
2017-10-29 14:16:35,027 [Thread-9:11492] [django.request:135] [ERROR]- Internal Server Error: /user/focus/publish
Traceback (most recent call last):
  File "D:\ProgramData\Python36-32\lib\site-packages\django\template\base.py", line 882, in _resolve_lookup
    current = current[bit]
TypeError: 'ImageFieldFile' object is not subscriptable

During handling of the above exception, another exception occurred:

Traceback (most recent call last):
  File "D:\ProgramData\Python36-32\lib\site-packages\django\core\handlers\exception.py", line 41, in inner
    response = get_response(request)
  File "D:\ProgramData\Python36-32\lib\site-packages\django\core\handlers\base.py", line 249, in _legacy_get_response
    response = self._get_response(request)
  File "D:\ProgramData\Python36-32\lib\site-packages\django\core\handlers\base.py", line 187, in _get_response
    response = self.process_exception_by_middleware(e, request)
  File "D:\ProgramData\Python36-32\lib\site-packages\django\core\handlers\base.py", line 185, in _get_response
    response = wrapped_callback(request, *callback_args, **callback_kwargs)
  File "D:\Code\PycharmProjects\cms\focus\views.py", line 582, in user_publish
    return render(request, 'focus/u-publish.html', context)
  File "D:\ProgramData\Python36-32\lib\site-packages\django\shortcuts.py", line 30, in render
    content = loader.render_to_string(template_name, context, request, using=using)
  File "D:\ProgramData\Python36-32\lib\site-packages\django\template\loader.py", line 68, in render_to_string
    return template.render(context, request)
  File "D:\ProgramData\Python36-32\lib\site-packages\django\template\backends\django.py", line 66, in render
    return self.template.render(context)
  File "D:\ProgramData\Python36-32\lib\site-packages\django\template\base.py", line 207, in render
    return self._render(context)
  File "D:\ProgramData\Python36-32\lib\site-packages\django\template\base.py", line 199, in _render
    return self.nodelist.render(context)
  File "D:\ProgramData\Python36-32\lib\site-packages\django\template\base.py", line 990, in render
    bit = node.render_annotated(context)
  File "D:\ProgramData\Python36-32\lib\site-packages\django\template\base.py", line 957, in render_annotated
    return self.render(context)
  File "D:\ProgramData\Python36-32\lib\site-packages\django\template\base.py", line 1040, in render
    output = self.filter_expression.resolve(context)
  File "D:\ProgramData\Python36-32\lib\site-packages\django\template\base.py", line 708, in resolve
    obj = self.var.resolve(context)
  File "D:\ProgramData\Python36-32\lib\site-packages\django\template\base.py", line 849, in resolve
    value = self._resolve_lookup(context)
  File "D:\ProgramData\Python36-32\lib\site-packages\django\template\base.py", line 890, in _resolve_lookup
    current = getattr(current, bit)
  File "D:\ProgramData\Python36-32\lib\site-packages\django\db\models\fields\files.py", line 69, in url
    self._require_file()
  File "D:\ProgramData\Python36-32\lib\site-packages\django\db\models\fields\files.py", line 46, in _require_file
    raise ValueError("The '%s' attribute has no file associated with it." % self.field.name)
ValueError: The 'avatar' attribute has no file associated with it.
2017-10-29 14:17:22,735 [Thread-21:9648] [django.request:135] [ERROR]- Internal Server Error: /user/focus/publish
Traceback (most recent call last):
  File "D:\ProgramData\Python36-32\lib\site-packages\django\template\base.py", line 882, in _resolve_lookup
    current = current[bit]
TypeError: 'ImageFieldFile' object is not subscriptable

During handling of the above exception, another exception occurred:

Traceback (most recent call last):
  File "D:\ProgramData\Python36-32\lib\site-packages\django\core\handlers\exception.py", line 41, in inner
    response = get_response(request)
  File "D:\ProgramData\Python36-32\lib\site-packages\django\core\handlers\base.py", line 249, in _legacy_get_response
    response = self._get_response(request)
  File "D:\ProgramData\Python36-32\lib\site-packages\django\core\handlers\base.py", line 187, in _get_response
    response = self.process_exception_by_middleware(e, request)
  File "D:\ProgramData\Python36-32\lib\site-packages\django\core\handlers\base.py", line 185, in _get_response
    response = wrapped_callback(request, *callback_args, **callback_kwargs)
  File "D:\Code\PycharmProjects\cms\focus\views.py", line 582, in user_publish
    return render(request, 'focus/u-publish.html', context)
  File "D:\ProgramData\Python36-32\lib\site-packages\django\shortcuts.py", line 30, in render
    content = loader.render_to_string(template_name, context, request, using=using)
  File "D:\ProgramData\Python36-32\lib\site-packages\django\template\loader.py", line 68, in render_to_string
    return template.render(context, request)
  File "D:\ProgramData\Python36-32\lib\site-packages\django\template\backends\django.py", line 66, in render
    return self.template.render(context)
  File "D:\ProgramData\Python36-32\lib\site-packages\django\template\base.py", line 207, in render
    return self._render(context)
  File "D:\ProgramData\Python36-32\lib\site-packages\django\template\base.py", line 199, in _render
    return self.nodelist.render(context)
  File "D:\ProgramData\Python36-32\lib\site-packages\django\template\base.py", line 990, in render
    bit = node.render_annotated(context)
  File "D:\ProgramData\Python36-32\lib\site-packages\django\template\base.py", line 957, in render_annotated
    return self.render(context)
  File "D:\ProgramData\Python36-32\lib\site-packages\django\template\base.py", line 1040, in render
    output = self.filter_expression.resolve(context)
  File "D:\ProgramData\Python36-32\lib\site-packages\django\template\base.py", line 708, in resolve
    obj = self.var.resolve(context)
  File "D:\ProgramData\Python36-32\lib\site-packages\django\template\base.py", line 849, in resolve
    value = self._resolve_lookup(context)
  File "D:\ProgramData\Python36-32\lib\site-packages\django\template\base.py", line 890, in _resolve_lookup
    current = getattr(current, bit)
  File "D:\ProgramData\Python36-32\lib\site-packages\django\db\models\fields\files.py", line 69, in url
    self._require_file()
  File "D:\ProgramData\Python36-32\lib\site-packages\django\db\models\fields\files.py", line 46, in _require_file
    raise ValueError("The '%s' attribute has no file associated with it." % self.field.name)
ValueError: The 'avatar' attribute has no file associated with it.
2017-10-29 14:17:43,827 [Thread-23:9092] [django.request:152] [WARNING]- Not Found: /manager/logout/
2017-10-29 14:20:21,700 [Thread-1:13364] [django.request:135] [ERROR]- Internal Server Error: /
Traceback (most recent call last):
  File "D:\ProgramData\Python36-32\lib\site-packages\django\template\base.py", line 882, in _resolve_lookup
    current = current[bit]
TypeError: 'ImageFieldFile' object is not subscriptable

During handling of the above exception, another exception occurred:

Traceback (most recent call last):
  File "D:\ProgramData\Python36-32\lib\site-packages\django\core\handlers\exception.py", line 41, in inner
    response = get_response(request)
  File "D:\ProgramData\Python36-32\lib\site-packages\django\core\handlers\base.py", line 249, in _legacy_get_response
    response = self._get_response(request)
  File "D:\ProgramData\Python36-32\lib\site-packages\django\core\handlers\base.py", line 187, in _get_response
    response = self.process_exception_by_middleware(e, request)
  File "D:\ProgramData\Python36-32\lib\site-packages\django\core\handlers\base.py", line 185, in _get_response
    response = wrapped_callback(request, *callback_args, **callback_kwargs)
  File "D:\Code\PycharmProjects\cms\focus\views.py", line 154, in index
    return render(request, 'focus/index.html', context)
  File "D:\ProgramData\Python36-32\lib\site-packages\django\shortcuts.py", line 30, in render
    content = loader.render_to_string(template_name, context, request, using=using)
  File "D:\ProgramData\Python36-32\lib\site-packages\django\template\loader.py", line 68, in render_to_string
    return template.render(context, request)
  File "D:\ProgramData\Python36-32\lib\site-packages\django\template\backends\django.py", line 66, in render
    return self.template.render(context)
  File "D:\ProgramData\Python36-32\lib\site-packages\django\template\base.py", line 207, in render
    return self._render(context)
  File "D:\ProgramData\Python36-32\lib\site-packages\django\template\base.py", line 199, in _render
    return self.nodelist.render(context)
  File "D:\ProgramData\Python36-32\lib\site-packages\django\template\base.py", line 990, in render
    bit = node.render_annotated(context)
  File "D:\ProgramData\Python36-32\lib\site-packages\django\template\base.py", line 957, in render_annotated
    return self.render(context)
  File "D:\ProgramData\Python36-32\lib\site-packages\django\template\loader_tags.py", line 177, in render
    return compiled_parent._render(context)
  File "D:\ProgramData\Python36-32\lib\site-packages\django\template\base.py", line 199, in _render
    return self.nodelist.render(context)
  File "D:\ProgramData\Python36-32\lib\site-packages\django\template\base.py", line 990, in render
    bit = node.render_annotated(context)
  File "D:\ProgramData\Python36-32\lib\site-packages\django\template\base.py", line 957, in render_annotated
    return self.render(context)
  File "D:\ProgramData\Python36-32\lib\site-packages\django\template\defaulttags.py", line 216, in render
    nodelist.append(node.render_annotated(context))
  File "D:\ProgramData\Python36-32\lib\site-packages\django\template\base.py", line 957, in render_annotated
    return self.render(context)
  File "D:\ProgramData\Python36-32\lib\site-packages\django\template\base.py", line 1040, in render
    output = self.filter_expression.resolve(context)
  File "D:\ProgramData\Python36-32\lib\site-packages\django\template\base.py", line 708, in resolve
    obj = self.var.resolve(context)
  File "D:\ProgramData\Python36-32\lib\site-packages\django\template\base.py", line 849, in resolve
    value = self._resolve_lookup(context)
  File "D:\ProgramData\Python36-32\lib\site-packages\django\template\base.py", line 890, in _resolve_lookup
    current = getattr(current, bit)
  File "D:\ProgramData\Python36-32\lib\site-packages\django\db\models\fields\files.py", line 69, in url
    self._require_file()
  File "D:\ProgramData\Python36-32\lib\site-packages\django\db\models\fields\files.py", line 46, in _require_file
    raise ValueError("The '%s' attribute has no file associated with it." % self.field.name)
ValueError: The 'avatar' attribute has no file associated with it.
2017-10-29 14:22:39,711 [Thread-35:8428] [django.request:152] [WARNING]- Not Found: /manager/logout/
2017-10-29 14:24:47,938 [Thread-44:708] [django.request:152] [WARNING]- Not Found: /manager/logout/
2017-10-29 15:02:36,955 [Thread-1:11596] [django.request:152] [WARNING]- Not Found: /manager/login/
2017-10-29 15:27:07,706 [Thread-7:12292] [django.request:135] [ERROR]- Internal Server Error: /manager/logout/
Traceback (most recent call last):
  File "D:\ProgramData\Python36-32\lib\site-packages\django\core\handlers\exception.py", line 41, in inner
    response = get_response(request)
  File "D:\ProgramData\Python36-32\lib\site-packages\django\core\handlers\base.py", line 249, in _legacy_get_response
    response = self._get_response(request)
  File "D:\ProgramData\Python36-32\lib\site-packages\django\core\handlers\base.py", line 187, in _get_response
    response = self.process_exception_by_middleware(e, request)
  File "D:\ProgramData\Python36-32\lib\site-packages\django\core\handlers\base.py", line 185, in _get_response
    response = wrapped_callback(request, *callback_args, **callback_kwargs)
  File "D:\ProgramData\Python36-32\lib\site-packages\django\views\decorators\csrf.py", line 58, in wrapped_view
    return view_func(*args, **kwargs)
  File "D:\ProgramData\Python36-32\lib\site-packages\django\views\generic\base.py", line 68, in view
    return self.dispatch(request, *args, **kwargs)
  File "D:\ProgramData\Python36-32\lib\site-packages\rest_framework\views.py", line 489, in dispatch
    response = self.handle_exception(exc)
  File "D:\ProgramData\Python36-32\lib\site-packages\rest_framework\views.py", line 449, in handle_exception
    self.raise_uncaught_exception(exc)
  File "D:\ProgramData\Python36-32\lib\site-packages\rest_framework\views.py", line 486, in dispatch
    response = handler(request, *args, **kwargs)
  File "D:\ProgramData\Python36-32\lib\site-packages\django\contrib\auth\decorators.py", line 22, in _wrapped_view
    if test_func(request.user):
AttributeError: 'log_out' object has no attribute 'user'
2017-10-29 15:47:31,190 [Thread-1:4332] [django.request:135] [ERROR]- Internal Server Error: /contents
Traceback (most recent call last):
  File "D:\ProgramData\Python36-32\lib\site-packages\django\core\handlers\exception.py", line 41, in inner
    response = get_response(request)
  File "D:\ProgramData\Python36-32\lib\site-packages\django\core\handlers\base.py", line 249, in _legacy_get_response
    response = self._get_response(request)
  File "D:\ProgramData\Python36-32\lib\site-packages\django\core\handlers\base.py", line 187, in _get_response
    response = self.process_exception_by_middleware(e, request)
  File "D:\ProgramData\Python36-32\lib\site-packages\django\core\handlers\base.py", line 185, in _get_response
    response = wrapped_callback(request, *callback_args, **callback_kwargs)
  File "D:\ProgramData\Python36-32\lib\site-packages\django\views\decorators\csrf.py", line 58, in wrapped_view
    return view_func(*args, **kwargs)
  File "D:\ProgramData\Python36-32\lib\site-packages\django\views\generic\base.py", line 68, in view
    return self.dispatch(request, *args, **kwargs)
  File "D:\ProgramData\Python36-32\lib\site-packages\rest_framework\views.py", line 489, in dispatch
    response = self.handle_exception(exc)
  File "D:\ProgramData\Python36-32\lib\site-packages\rest_framework\views.py", line 449, in handle_exception
    self.raise_uncaught_exception(exc)
  File "D:\ProgramData\Python36-32\lib\site-packages\rest_framework\views.py", line 486, in dispatch
    response = handler(request, *args, **kwargs)
  File "D:\Code\PycharmProjects\cms\focus\views.py", line 185, in get
    post_data = json.loads(request.body)
  File "D:\ProgramData\Python36-32\lib\json\__init__.py", line 354, in loads
    return _default_decoder.decode(s)
  File "D:\ProgramData\Python36-32\lib\json\decoder.py", line 339, in decode
    obj, end = self.raw_decode(s, idx=_w(s, 0).end())
  File "D:\ProgramData\Python36-32\lib\json\decoder.py", line 357, in raw_decode
    raise JSONDecodeError("Expecting value", s, err.value) from None
json.decoder.JSONDecodeError: Expecting value: line 1 column 1 (char 0)
2017-10-29 15:47:42,135 [Thread-3:6768] [django.request:135] [ERROR]- Internal Server Error: /contents
Traceback (most recent call last):
  File "D:\ProgramData\Python36-32\lib\site-packages\django\core\handlers\exception.py", line 41, in inner
    response = get_response(request)
  File "D:\ProgramData\Python36-32\lib\site-packages\django\core\handlers\base.py", line 249, in _legacy_get_response
    response = self._get_response(request)
  File "D:\ProgramData\Python36-32\lib\site-packages\django\core\handlers\base.py", line 187, in _get_response
    response = self.process_exception_by_middleware(e, request)
  File "D:\ProgramData\Python36-32\lib\site-packages\django\core\handlers\base.py", line 185, in _get_response
    response = wrapped_callback(request, *callback_args, **callback_kwargs)
  File "D:\ProgramData\Python36-32\lib\site-packages\django\views\decorators\csrf.py", line 58, in wrapped_view
    return view_func(*args, **kwargs)
  File "D:\ProgramData\Python36-32\lib\site-packages\django\views\generic\base.py", line 68, in view
    return self.dispatch(request, *args, **kwargs)
  File "D:\ProgramData\Python36-32\lib\site-packages\rest_framework\views.py", line 489, in dispatch
    response = self.handle_exception(exc)
  File "D:\ProgramData\Python36-32\lib\site-packages\rest_framework\views.py", line 449, in handle_exception
    self.raise_uncaught_exception(exc)
  File "D:\ProgramData\Python36-32\lib\site-packages\rest_framework\views.py", line 486, in dispatch
    response = handler(request, *args, **kwargs)
  File "D:\Code\PycharmProjects\cms\focus\views.py", line 185, in get
    post_data = json.loads(request.body)
  File "D:\ProgramData\Python36-32\lib\json\__init__.py", line 354, in loads
    return _default_decoder.decode(s)
  File "D:\ProgramData\Python36-32\lib\json\decoder.py", line 339, in decode
    obj, end = self.raw_decode(s, idx=_w(s, 0).end())
  File "D:\ProgramData\Python36-32\lib\json\decoder.py", line 357, in raw_decode
    raise JSONDecodeError("Expecting value", s, err.value) from None
json.decoder.JSONDecodeError: Expecting value: line 1 column 1 (char 0)
2017-10-29 15:54:04,648 [Thread-8:12376] [django.request:135] [ERROR]- Internal Server Error: /contents
Traceback (most recent call last):
  File "D:\ProgramData\Python36-32\lib\site-packages\django\core\handlers\exception.py", line 41, in inner
    response = get_response(request)
  File "D:\ProgramData\Python36-32\lib\site-packages\django\core\handlers\base.py", line 249, in _legacy_get_response
    response = self._get_response(request)
  File "D:\ProgramData\Python36-32\lib\site-packages\django\core\handlers\base.py", line 187, in _get_response
    response = self.process_exception_by_middleware(e, request)
  File "D:\ProgramData\Python36-32\lib\site-packages\django\core\handlers\base.py", line 185, in _get_response
    response = wrapped_callback(request, *callback_args, **callback_kwargs)
  File "D:\ProgramData\Python36-32\lib\site-packages\django\views\decorators\csrf.py", line 58, in wrapped_view
    return view_func(*args, **kwargs)
  File "D:\ProgramData\Python36-32\lib\site-packages\django\views\generic\base.py", line 68, in view
    return self.dispatch(request, *args, **kwargs)
  File "D:\ProgramData\Python36-32\lib\site-packages\rest_framework\views.py", line 489, in dispatch
    response = self.handle_exception(exc)
  File "D:\ProgramData\Python36-32\lib\site-packages\rest_framework\views.py", line 449, in handle_exception
    self.raise_uncaught_exception(exc)
  File "D:\ProgramData\Python36-32\lib\site-packages\rest_framework\views.py", line 486, in dispatch
    response = handler(request, *args, **kwargs)
  File "D:\Code\PycharmProjects\cms\focus\views.py", line 185, in get
    post_data = json.loads(request.body)
  File "D:\ProgramData\Python36-32\lib\json\__init__.py", line 354, in loads
    return _default_decoder.decode(s)
  File "D:\ProgramData\Python36-32\lib\json\decoder.py", line 339, in decode
    obj, end = self.raw_decode(s, idx=_w(s, 0).end())
  File "D:\ProgramData\Python36-32\lib\json\decoder.py", line 357, in raw_decode
    raise JSONDecodeError("Expecting value", s, err.value) from None
json.decoder.JSONDecodeError: Expecting value: line 1 column 1 (char 0)
2017-10-29 15:54:09,364 [Thread-9:8096] [django.request:135] [ERROR]- Internal Server Error: /contents
Traceback (most recent call last):
  File "D:\ProgramData\Python36-32\lib\site-packages\django\core\handlers\exception.py", line 41, in inner
    response = get_response(request)
  File "D:\ProgramData\Python36-32\lib\site-packages\django\core\handlers\base.py", line 249, in _legacy_get_response
    response = self._get_response(request)
  File "D:\ProgramData\Python36-32\lib\site-packages\django\core\handlers\base.py", line 187, in _get_response
    response = self.process_exception_by_middleware(e, request)
  File "D:\ProgramData\Python36-32\lib\site-packages\django\core\handlers\base.py", line 185, in _get_response
    response = wrapped_callback(request, *callback_args, **callback_kwargs)
  File "D:\ProgramData\Python36-32\lib\site-packages\django\views\decorators\csrf.py", line 58, in wrapped_view
    return view_func(*args, **kwargs)
  File "D:\ProgramData\Python36-32\lib\site-packages\django\views\generic\base.py", line 68, in view
    return self.dispatch(request, *args, **kwargs)
  File "D:\ProgramData\Python36-32\lib\site-packages\rest_framework\views.py", line 489, in dispatch
    response = self.handle_exception(exc)
  File "D:\ProgramData\Python36-32\lib\site-packages\rest_framework\views.py", line 449, in handle_exception
    self.raise_uncaught_exception(exc)
  File "D:\ProgramData\Python36-32\lib\site-packages\rest_framework\views.py", line 486, in dispatch
    response = handler(request, *args, **kwargs)
  File "D:\Code\PycharmProjects\cms\focus\views.py", line 185, in get
    post_data = json.loads(request.body)
  File "D:\ProgramData\Python36-32\lib\json\__init__.py", line 354, in loads
    return _default_decoder.decode(s)
  File "D:\ProgramData\Python36-32\lib\json\decoder.py", line 339, in decode
    obj, end = self.raw_decode(s, idx=_w(s, 0).end())
  File "D:\ProgramData\Python36-32\lib\json\decoder.py", line 357, in raw_decode
    raise JSONDecodeError("Expecting value", s, err.value) from None
json.decoder.JSONDecodeError: Expecting value: line 1 column 1 (char 0)
2017-10-29 15:54:36,072 [Thread-1:11280] [django.request:135] [ERROR]- Internal Server Error: /contents
Traceback (most recent call last):
  File "D:\ProgramData\Python36-32\lib\site-packages\django\core\handlers\exception.py", line 41, in inner
    response = get_response(request)
  File "D:\ProgramData\Python36-32\lib\site-packages\django\core\handlers\base.py", line 249, in _legacy_get_response
    response = self._get_response(request)
  File "D:\ProgramData\Python36-32\lib\site-packages\django\core\handlers\base.py", line 187, in _get_response
    response = self.process_exception_by_middleware(e, request)
  File "D:\ProgramData\Python36-32\lib\site-packages\django\core\handlers\base.py", line 185, in _get_response
    response = wrapped_callback(request, *callback_args, **callback_kwargs)
  File "D:\ProgramData\Python36-32\lib\site-packages\django\views\decorators\csrf.py", line 58, in wrapped_view
    return view_func(*args, **kwargs)
  File "D:\ProgramData\Python36-32\lib\site-packages\django\views\generic\base.py", line 68, in view
    return self.dispatch(request, *args, **kwargs)
  File "D:\ProgramData\Python36-32\lib\site-packages\rest_framework\views.py", line 489, in dispatch
    response = self.handle_exception(exc)
  File "D:\ProgramData\Python36-32\lib\site-packages\rest_framework\views.py", line 449, in handle_exception
    self.raise_uncaught_exception(exc)
  File "D:\ProgramData\Python36-32\lib\site-packages\rest_framework\views.py", line 486, in dispatch
    response = handler(request, *args, **kwargs)
  File "D:\Code\PycharmProjects\cms\focus\views.py", line 185, in get
    post_data = json.loads(request.body)
  File "D:\ProgramData\Python36-32\lib\json\__init__.py", line 354, in loads
    return _default_decoder.decode(s)
  File "D:\ProgramData\Python36-32\lib\json\decoder.py", line 339, in decode
    obj, end = self.raw_decode(s, idx=_w(s, 0).end())
  File "D:\ProgramData\Python36-32\lib\json\decoder.py", line 357, in raw_decode
    raise JSONDecodeError("Expecting value", s, err.value) from None
json.decoder.JSONDecodeError: Expecting value: line 1 column 1 (char 0)
2017-10-29 16:37:20,826 [Thread-1:4752] [django.request:135] [ERROR]- Internal Server Error: /contents
Traceback (most recent call last):
  File "D:\ProgramData\Python36-32\lib\site-packages\django\core\handlers\exception.py", line 41, in inner
    response = get_response(request)
  File "D:\ProgramData\Python36-32\lib\site-packages\django\core\handlers\base.py", line 249, in _legacy_get_response
    response = self._get_response(request)
  File "D:\ProgramData\Python36-32\lib\site-packages\django\core\handlers\base.py", line 187, in _get_response
    response = self.process_exception_by_middleware(e, request)
  File "D:\ProgramData\Python36-32\lib\site-packages\django\core\handlers\base.py", line 185, in _get_response
    response = wrapped_callback(request, *callback_args, **callback_kwargs)
  File "D:\ProgramData\Python36-32\lib\site-packages\django\views\decorators\csrf.py", line 58, in wrapped_view
    return view_func(*args, **kwargs)
  File "D:\ProgramData\Python36-32\lib\site-packages\django\views\generic\base.py", line 68, in view
    return self.dispatch(request, *args, **kwargs)
  File "D:\ProgramData\Python36-32\lib\site-packages\rest_framework\views.py", line 489, in dispatch
    response = self.handle_exception(exc)
  File "D:\ProgramData\Python36-32\lib\site-packages\rest_framework\views.py", line 449, in handle_exception
    self.raise_uncaught_exception(exc)
  File "D:\ProgramData\Python36-32\lib\site-packages\rest_framework\views.py", line 477, in dispatch
    self.initial(request, *args, **kwargs)
  File "D:\ProgramData\Python36-32\lib\site-packages\rest_framework\views.py", line 394, in initial
    self.perform_authentication(request)
  File "D:\ProgramData\Python36-32\lib\site-packages\rest_framework\views.py", line 320, in perform_authentication
    request.user
  File "D:\ProgramData\Python36-32\lib\site-packages\rest_framework\request.py", line 381, in __getattribute__
    return super(Request, self).__getattribute__(attr)
  File "D:\ProgramData\Python36-32\lib\site-packages\rest_framework\request.py", line 196, in user
    self._authenticate()
  File "D:\ProgramData\Python36-32\lib\site-packages\rest_framework\request.py", line 345, in _authenticate
    user_auth_tuple = authenticator.authenticate(self)
  File "D:\ProgramData\Python36-32\lib\site-packages\rest_framework\authentication.py", line 130, in authenticate
    if GLOBAL_CSRF_CHECK:
NameError: name 'GLOBAL_CSRF_CHECK' is not defined
2017-10-29 16:38:35,479 [Thread-1:13628] [django.request:135] [ERROR]- Internal Server Error: /contents
Traceback (most recent call last):
  File "D:\ProgramData\Python36-32\lib\site-packages\django\core\handlers\exception.py", line 41, in inner
    response = get_response(request)
  File "D:\ProgramData\Python36-32\lib\site-packages\django\core\handlers\base.py", line 249, in _legacy_get_response
    response = self._get_response(request)
  File "D:\ProgramData\Python36-32\lib\site-packages\django\core\handlers\base.py", line 187, in _get_response
    response = self.process_exception_by_middleware(e, request)
  File "D:\ProgramData\Python36-32\lib\site-packages\django\core\handlers\base.py", line 185, in _get_response
    response = wrapped_callback(request, *callback_args, **callback_kwargs)
  File "D:\ProgramData\Python36-32\lib\site-packages\django\views\decorators\csrf.py", line 58, in wrapped_view
    return view_func(*args, **kwargs)
  File "D:\ProgramData\Python36-32\lib\site-packages\django\views\generic\base.py", line 68, in view
    return self.dispatch(request, *args, **kwargs)
  File "D:\ProgramData\Python36-32\lib\site-packages\rest_framework\views.py", line 489, in dispatch
    response = self.handle_exception(exc)
  File "D:\ProgramData\Python36-32\lib\site-packages\rest_framework\views.py", line 449, in handle_exception
    self.raise_uncaught_exception(exc)
  File "D:\ProgramData\Python36-32\lib\site-packages\rest_framework\views.py", line 477, in dispatch
    self.initial(request, *args, **kwargs)
  File "D:\ProgramData\Python36-32\lib\site-packages\rest_framework\views.py", line 394, in initial
    self.perform_authentication(request)
  File "D:\ProgramData\Python36-32\lib\site-packages\rest_framework\views.py", line 320, in perform_authentication
    request.user
  File "D:\ProgramData\Python36-32\lib\site-packages\rest_framework\request.py", line 381, in __getattribute__
    return super(Request, self).__getattribute__(attr)
  File "D:\ProgramData\Python36-32\lib\site-packages\rest_framework\request.py", line 196, in user
    self._authenticate()
  File "D:\ProgramData\Python36-32\lib\site-packages\rest_framework\request.py", line 345, in _authenticate
    user_auth_tuple = authenticator.authenticate(self)
  File "D:\ProgramData\Python36-32\lib\site-packages\rest_framework\authentication.py", line 130, in authenticate
    if GLOBAL_CSRF_CHECK:
NameError: name 'GLOBAL_CSRF_CHECK' is not defined
2017-10-29 16:50:38,801 [Thread-3:11860] [django.request:135] [ERROR]- Internal Server Error: /manager/logout/
Traceback (most recent call last):
  File "D:\ProgramData\Python36-32\lib\site-packages\django\core\handlers\exception.py", line 41, in inner
    response = get_response(request)
  File "D:\ProgramData\Python36-32\lib\site-packages\django\core\handlers\base.py", line 249, in _legacy_get_response
    response = self._get_response(request)
  File "D:\ProgramData\Python36-32\lib\site-packages\django\core\handlers\base.py", line 187, in _get_response
    response = self.process_exception_by_middleware(e, request)
  File "D:\ProgramData\Python36-32\lib\site-packages\django\core\handlers\base.py", line 185, in _get_response
    response = wrapped_callback(request, *callback_args, **callback_kwargs)
  File "D:\ProgramData\Python36-32\lib\site-packages\django\views\decorators\csrf.py", line 58, in wrapped_view
    return view_func(*args, **kwargs)
  File "D:\ProgramData\Python36-32\lib\site-packages\django\views\generic\base.py", line 68, in view
    return self.dispatch(request, *args, **kwargs)
  File "D:\ProgramData\Python36-32\lib\site-packages\rest_framework\views.py", line 489, in dispatch
    response = self.handle_exception(exc)
  File "D:\ProgramData\Python36-32\lib\site-packages\rest_framework\views.py", line 449, in handle_exception
    self.raise_uncaught_exception(exc)
  File "D:\ProgramData\Python36-32\lib\site-packages\rest_framework\views.py", line 486, in dispatch
    response = handler(request, *args, **kwargs)
  File "D:\ProgramData\Python36-32\lib\site-packages\django\contrib\auth\decorators.py", line 22, in _wrapped_view
    if test_func(request.user):
AttributeError: 'log_out' object has no attribute 'user'
2017-10-29 18:18:36,980 [Thread-5:11964] [django.request:152] [WARNING]- Not Found: /manager/logout/
2017-10-29 20:40:55,489 [Thread-11:7548] [django.request:135] [ERROR]- Internal Server Error: /ucenter
Traceback (most recent call last):
  File "D:\ProgramData\Python36-32\lib\site-packages\django\core\handlers\exception.py", line 41, in inner
    response = get_response(request)
  File "D:\ProgramData\Python36-32\lib\site-packages\django\core\handlers\base.py", line 249, in _legacy_get_response
    response = self._get_response(request)
  File "D:\ProgramData\Python36-32\lib\site-packages\django\core\handlers\base.py", line 217, in _get_response
    response = self.process_exception_by_middleware(e, request)
  File "D:\ProgramData\Python36-32\lib\site-packages\django\core\handlers\base.py", line 215, in _get_response
    response = response.render()
  File "D:\ProgramData\Python36-32\lib\site-packages\django\template\response.py", line 107, in render
    self.content = self.rendered_content
  File "D:\ProgramData\Python36-32\lib\site-packages\rest_framework\response.py", line 72, in rendered_content
    ret = renderer.render(self.data, accepted_media_type, context)
  File "D:\ProgramData\Python36-32\lib\site-packages\rest_framework\renderers.py", line 105, in render
    separators=separators
  File "D:\ProgramData\Python36-32\lib\json\__init__.py", line 238, in dumps
    **kw).encode(obj)
  File "D:\ProgramData\Python36-32\lib\json\encoder.py", line 199, in encode
    chunks = self.iterencode(o, _one_shot=True)
  File "D:\ProgramData\Python36-32\lib\json\encoder.py", line 257, in iterencode
    return _iterencode(o, 0)
  File "D:\ProgramData\Python36-32\lib\site-packages\rest_framework\utils\encoders.py", line 70, in default
    return super(JSONEncoder, self).default(obj)
  File "D:\ProgramData\Python36-32\lib\json\encoder.py", line 180, in default
    o.__class__.__name__)
TypeError: Object of type 'Note' is not JSON serializable
2017-10-29 20:46:04,736 [Thread-1:12120] [django.request:135] [ERROR]- Internal Server Error: /ucenter
Traceback (most recent call last):
  File "D:\ProgramData\Python36-32\lib\site-packages\django\core\handlers\exception.py", line 41, in inner
    response = get_response(request)
  File "D:\ProgramData\Python36-32\lib\site-packages\django\core\handlers\base.py", line 249, in _legacy_get_response
    response = self._get_response(request)
  File "D:\ProgramData\Python36-32\lib\site-packages\django\core\handlers\base.py", line 217, in _get_response
    response = self.process_exception_by_middleware(e, request)
  File "D:\ProgramData\Python36-32\lib\site-packages\django\core\handlers\base.py", line 215, in _get_response
    response = response.render()
  File "D:\ProgramData\Python36-32\lib\site-packages\django\template\response.py", line 107, in render
    self.content = self.rendered_content
  File "D:\ProgramData\Python36-32\lib\site-packages\rest_framework\response.py", line 72, in rendered_content
    ret = renderer.render(self.data, accepted_media_type, context)
  File "D:\ProgramData\Python36-32\lib\site-packages\rest_framework\renderers.py", line 105, in render
    separators=separators
  File "D:\ProgramData\Python36-32\lib\json\__init__.py", line 238, in dumps
    **kw).encode(obj)
  File "D:\ProgramData\Python36-32\lib\json\encoder.py", line 199, in encode
    chunks = self.iterencode(o, _one_shot=True)
  File "D:\ProgramData\Python36-32\lib\json\encoder.py", line 257, in iterencode
    return _iterencode(o, 0)
  File "D:\ProgramData\Python36-32\lib\site-packages\rest_framework\utils\encoders.py", line 70, in default
    return super(JSONEncoder, self).default(obj)
  File "D:\ProgramData\Python36-32\lib\json\encoder.py", line 180, in default
    o.__class__.__name__)
TypeError: Object of type 'ListSerializer' is not JSON serializable
2017-10-29 20:47:17,358 [Thread-3:9936] [django.request:135] [ERROR]- Internal Server Error: /ucenter
Traceback (most recent call last):
  File "D:\ProgramData\Python36-32\lib\site-packages\django\core\handlers\exception.py", line 41, in inner
    response = get_response(request)
  File "D:\ProgramData\Python36-32\lib\site-packages\django\core\handlers\base.py", line 249, in _legacy_get_response
    response = self._get_response(request)
  File "D:\ProgramData\Python36-32\lib\site-packages\django\core\handlers\base.py", line 217, in _get_response
    response = self.process_exception_by_middleware(e, request)
  File "D:\ProgramData\Python36-32\lib\site-packages\django\core\handlers\base.py", line 215, in _get_response
    response = response.render()
  File "D:\ProgramData\Python36-32\lib\site-packages\django\template\response.py", line 107, in render
    self.content = self.rendered_content
  File "D:\ProgramData\Python36-32\lib\site-packages\rest_framework\response.py", line 72, in rendered_content
    ret = renderer.render(self.data, accepted_media_type, context)
  File "D:\ProgramData\Python36-32\lib\site-packages\rest_framework\renderers.py", line 105, in render
    separators=separators
  File "D:\ProgramData\Python36-32\lib\json\__init__.py", line 238, in dumps
    **kw).encode(obj)
  File "D:\ProgramData\Python36-32\lib\json\encoder.py", line 199, in encode
    chunks = self.iterencode(o, _one_shot=True)
  File "D:\ProgramData\Python36-32\lib\json\encoder.py", line 257, in iterencode
    return _iterencode(o, 0)
  File "D:\ProgramData\Python36-32\lib\site-packages\rest_framework\utils\encoders.py", line 70, in default
    return super(JSONEncoder, self).default(obj)
  File "D:\ProgramData\Python36-32\lib\json\encoder.py", line 180, in default
    o.__class__.__name__)
TypeError: Object of type 'ListSerializer' is not JSON serializable
2017-10-29 20:47:27,072 [Thread-4:12152] [django.request:135] [ERROR]- Internal Server Error: /ucenter
Traceback (most recent call last):
  File "D:\ProgramData\Python36-32\lib\site-packages\django\core\handlers\exception.py", line 41, in inner
    response = get_response(request)
  File "D:\ProgramData\Python36-32\lib\site-packages\django\core\handlers\base.py", line 249, in _legacy_get_response
    response = self._get_response(request)
  File "D:\ProgramData\Python36-32\lib\site-packages\django\core\handlers\base.py", line 217, in _get_response
    response = self.process_exception_by_middleware(e, request)
  File "D:\ProgramData\Python36-32\lib\site-packages\django\core\handlers\base.py", line 215, in _get_response
    response = response.render()
  File "D:\ProgramData\Python36-32\lib\site-packages\django\template\response.py", line 107, in render
    self.content = self.rendered_content
  File "D:\ProgramData\Python36-32\lib\site-packages\rest_framework\response.py", line 72, in rendered_content
    ret = renderer.render(self.data, accepted_media_type, context)
  File "D:\ProgramData\Python36-32\lib\site-packages\rest_framework\renderers.py", line 105, in render
    separators=separators
  File "D:\ProgramData\Python36-32\lib\json\__init__.py", line 238, in dumps
    **kw).encode(obj)
  File "D:\ProgramData\Python36-32\lib\json\encoder.py", line 199, in encode
    chunks = self.iterencode(o, _one_shot=True)
  File "D:\ProgramData\Python36-32\lib\json\encoder.py", line 257, in iterencode
    return _iterencode(o, 0)
  File "D:\ProgramData\Python36-32\lib\site-packages\rest_framework\utils\encoders.py", line 70, in default
    return super(JSONEncoder, self).default(obj)
  File "D:\ProgramData\Python36-32\lib\json\encoder.py", line 180, in default
    o.__class__.__name__)
TypeError: Object of type 'ListSerializer' is not JSON serializable
2017-10-29 20:50:51,235 [Thread-1:13804] [django.request:135] [ERROR]- Internal Server Error: /ucenter
Traceback (most recent call last):
  File "D:\ProgramData\Python36-32\lib\site-packages\django\core\handlers\exception.py", line 41, in inner
    response = get_response(request)
  File "D:\ProgramData\Python36-32\lib\site-packages\django\core\handlers\base.py", line 249, in _legacy_get_response
    response = self._get_response(request)
  File "D:\ProgramData\Python36-32\lib\site-packages\django\core\handlers\base.py", line 217, in _get_response
    response = self.process_exception_by_middleware(e, request)
  File "D:\ProgramData\Python36-32\lib\site-packages\django\core\handlers\base.py", line 215, in _get_response
    response = response.render()
  File "D:\ProgramData\Python36-32\lib\site-packages\django\template\response.py", line 107, in render
    self.content = self.rendered_content
  File "D:\ProgramData\Python36-32\lib\site-packages\rest_framework\response.py", line 72, in rendered_content
    ret = renderer.render(self.data, accepted_media_type, context)
  File "D:\ProgramData\Python36-32\lib\site-packages\rest_framework\renderers.py", line 105, in render
    separators=separators
  File "D:\ProgramData\Python36-32\lib\json\__init__.py", line 238, in dumps
    **kw).encode(obj)
  File "D:\ProgramData\Python36-32\lib\json\encoder.py", line 199, in encode
    chunks = self.iterencode(o, _one_shot=True)
  File "D:\ProgramData\Python36-32\lib\json\encoder.py", line 257, in iterencode
    return _iterencode(o, 0)
  File "D:\ProgramData\Python36-32\lib\site-packages\rest_framework\utils\encoders.py", line 70, in default
    return super(JSONEncoder, self).default(obj)
  File "D:\ProgramData\Python36-32\lib\json\encoder.py", line 180, in default
    o.__class__.__name__)
TypeError: Object of type 'ListSerializer' is not JSON serializable
2017-10-29 20:51:16,558 [Thread-1:13708] [django.request:135] [ERROR]- Internal Server Error: /ucenter
Traceback (most recent call last):
  File "D:\ProgramData\Python36-32\lib\site-packages\django\core\handlers\exception.py", line 41, in inner
    response = get_response(request)
  File "D:\ProgramData\Python36-32\lib\site-packages\django\core\handlers\base.py", line 249, in _legacy_get_response
    response = self._get_response(request)
  File "D:\ProgramData\Python36-32\lib\site-packages\django\core\handlers\base.py", line 217, in _get_response
    response = self.process_exception_by_middleware(e, request)
  File "D:\ProgramData\Python36-32\lib\site-packages\django\core\handlers\base.py", line 215, in _get_response
    response = response.render()
  File "D:\ProgramData\Python36-32\lib\site-packages\django\template\response.py", line 107, in render
    self.content = self.rendered_content
  File "D:\ProgramData\Python36-32\lib\site-packages\rest_framework\response.py", line 72, in rendered_content
    ret = renderer.render(self.data, accepted_media_type, context)
  File "D:\ProgramData\Python36-32\lib\site-packages\rest_framework\renderers.py", line 105, in render
    separators=separators
  File "D:\ProgramData\Python36-32\lib\json\__init__.py", line 238, in dumps
    **kw).encode(obj)
  File "D:\ProgramData\Python36-32\lib\json\encoder.py", line 199, in encode
    chunks = self.iterencode(o, _one_shot=True)
  File "D:\ProgramData\Python36-32\lib\json\encoder.py", line 257, in iterencode
    return _iterencode(o, 0)
  File "D:\ProgramData\Python36-32\lib\site-packages\rest_framework\utils\encoders.py", line 70, in default
    return super(JSONEncoder, self).default(obj)
  File "D:\ProgramData\Python36-32\lib\json\encoder.py", line 180, in default
    o.__class__.__name__)
TypeError: Object of type 'ListSerializer' is not JSON serializable
2017-10-29 20:51:45,399 [Thread-1:8412] [django.request:135] [ERROR]- Internal Server Error: /ucenter
Traceback (most recent call last):
  File "D:\ProgramData\Python36-32\lib\site-packages\django\core\handlers\exception.py", line 41, in inner
    response = get_response(request)
  File "D:\ProgramData\Python36-32\lib\site-packages\django\core\handlers\base.py", line 249, in _legacy_get_response
    response = self._get_response(request)
  File "D:\ProgramData\Python36-32\lib\site-packages\django\core\handlers\base.py", line 217, in _get_response
    response = self.process_exception_by_middleware(e, request)
  File "D:\ProgramData\Python36-32\lib\site-packages\django\core\handlers\base.py", line 215, in _get_response
    response = response.render()
  File "D:\ProgramData\Python36-32\lib\site-packages\django\template\response.py", line 107, in render
    self.content = self.rendered_content
  File "D:\ProgramData\Python36-32\lib\site-packages\rest_framework\response.py", line 72, in rendered_content
    ret = renderer.render(self.data, accepted_media_type, context)
  File "D:\ProgramData\Python36-32\lib\site-packages\rest_framework\renderers.py", line 105, in render
    separators=separators
  File "D:\ProgramData\Python36-32\lib\json\__init__.py", line 238, in dumps
    **kw).encode(obj)
  File "D:\ProgramData\Python36-32\lib\json\encoder.py", line 199, in encode
    chunks = self.iterencode(o, _one_shot=True)
  File "D:\ProgramData\Python36-32\lib\json\encoder.py", line 257, in iterencode
    return _iterencode(o, 0)
  File "D:\ProgramData\Python36-32\lib\site-packages\rest_framework\utils\encoders.py", line 70, in default
    return super(JSONEncoder, self).default(obj)
  File "D:\ProgramData\Python36-32\lib\json\encoder.py", line 180, in default
    o.__class__.__name__)
TypeError: Object of type 'ListSerializer' is not JSON serializable
2017-10-29 20:52:24,414 [Thread-1:11752] [django.request:135] [ERROR]- Internal Server Error: /ucenter
Traceback (most recent call last):
  File "D:\ProgramData\Python36-32\lib\site-packages\django\core\handlers\exception.py", line 41, in inner
    response = get_response(request)
  File "D:\ProgramData\Python36-32\lib\site-packages\django\core\handlers\base.py", line 249, in _legacy_get_response
    response = self._get_response(request)
  File "D:\ProgramData\Python36-32\lib\site-packages\django\core\handlers\base.py", line 217, in _get_response
    response = self.process_exception_by_middleware(e, request)
  File "D:\ProgramData\Python36-32\lib\site-packages\django\core\handlers\base.py", line 215, in _get_response
    response = response.render()
  File "D:\ProgramData\Python36-32\lib\site-packages\django\template\response.py", line 107, in render
    self.content = self.rendered_content
  File "D:\ProgramData\Python36-32\lib\site-packages\rest_framework\response.py", line 72, in rendered_content
    ret = renderer.render(self.data, accepted_media_type, context)
  File "D:\ProgramData\Python36-32\lib\site-packages\rest_framework\renderers.py", line 105, in render
    separators=separators
  File "D:\ProgramData\Python36-32\lib\json\__init__.py", line 238, in dumps
    **kw).encode(obj)
  File "D:\ProgramData\Python36-32\lib\json\encoder.py", line 199, in encode
    chunks = self.iterencode(o, _one_shot=True)
  File "D:\ProgramData\Python36-32\lib\json\encoder.py", line 257, in iterencode
    return _iterencode(o, 0)
  File "D:\ProgramData\Python36-32\lib\site-packages\rest_framework\utils\encoders.py", line 70, in default
    return super(JSONEncoder, self).default(obj)
  File "D:\ProgramData\Python36-32\lib\json\encoder.py", line 180, in default
    o.__class__.__name__)
TypeError: Object of type 'ListSerializer' is not JSON serializable
2017-10-30 16:40:01,258 [Thread-1:12404] [django.request:135] [ERROR]- Internal Server Error: /contents
Traceback (most recent call last):
  File "C:\Python36-32\lib\site-packages\django\core\handlers\exception.py", line 41, in inner
    response = get_response(request)
  File "C:\Python36-32\lib\site-packages\django\core\handlers\base.py", line 249, in _legacy_get_response
    response = self._get_response(request)
  File "C:\Python36-32\lib\site-packages\django\core\handlers\base.py", line 187, in _get_response
    response = self.process_exception_by_middleware(e, request)
  File "C:\Python36-32\lib\site-packages\django\core\handlers\base.py", line 185, in _get_response
    response = wrapped_callback(request, *callback_args, **callback_kwargs)
  File "C:\Python36-32\lib\site-packages\django\views\decorators\csrf.py", line 58, in wrapped_view
    return view_func(*args, **kwargs)
  File "C:\Python36-32\lib\site-packages\django\views\generic\base.py", line 68, in view
    return self.dispatch(request, *args, **kwargs)
  File "C:\Python36-32\lib\site-packages\rest_framework\views.py", line 489, in dispatch
    response = self.handle_exception(exc)
  File "C:\Python36-32\lib\site-packages\rest_framework\views.py", line 449, in handle_exception
    self.raise_uncaught_exception(exc)
  File "C:\Python36-32\lib\site-packages\rest_framework\views.py", line 486, in dispatch
    response = handler(request, *args, **kwargs)
  File "D:\code\PycharmProjects\cms\focus\views.py", line 235, in post
    'user': user.data,
  File "C:\Python36-32\lib\site-packages\rest_framework\serializers.py", line 739, in data
    ret = super(ListSerializer, self).data
  File "C:\Python36-32\lib\site-packages\rest_framework\serializers.py", line 263, in data
    self._data = self.to_representation(self.instance)
  File "C:\Python36-32\lib\site-packages\rest_framework\serializers.py", line 657, in to_representation
    self.child.to_representation(item) for item in iterable
  File "C:\Python36-32\lib\site-packages\django\utils\functional.py", line 239, in inner
    return func(self._wrapped, *args)
TypeError: 'MyUser' object is not iterable
2017-10-31 16:31:45,514 [Thread-1:11172] [django.request:152] [WARNING]- Not Found: /details
2017-10-31 16:31:45,954 [Thread-3:14952] [django.request:152] [WARNING]- Not Found: /details
2017-10-31 16:32:54,785 [Thread-1:19320] [django.request:135] [ERROR]- Internal Server Error: /details
Traceback (most recent call last):
  File "C:\Python36-32\lib\site-packages\django\core\handlers\exception.py", line 41, in inner
    response = get_response(request)
  File "C:\Python36-32\lib\site-packages\django\core\handlers\base.py", line 249, in _legacy_get_response
    response = self._get_response(request)
  File "C:\Python36-32\lib\site-packages\django\core\handlers\base.py", line 187, in _get_response
    response = self.process_exception_by_middleware(e, request)
  File "C:\Python36-32\lib\site-packages\django\core\handlers\base.py", line 185, in _get_response
    response = wrapped_callback(request, *callback_args, **callback_kwargs)
TypeError: details() missing 1 required positional argument: 'id'
2017-10-31 16:34:21,340 [Thread-1:18660] [django.request:135] [ERROR]- Internal Server Error: /details
Traceback (most recent call last):
  File "C:\Python36-32\lib\site-packages\django\core\handlers\exception.py", line 41, in inner
    response = get_response(request)
  File "C:\Python36-32\lib\site-packages\django\core\handlers\base.py", line 249, in _legacy_get_response
    response = self._get_response(request)
  File "C:\Python36-32\lib\site-packages\django\core\handlers\base.py", line 187, in _get_response
    response = self.process_exception_by_middleware(e, request)
  File "C:\Python36-32\lib\site-packages\django\core\handlers\base.py", line 185, in _get_response
    response = wrapped_callback(request, *callback_args, **callback_kwargs)
  File "D:\code\PycharmProjects\cms\focus\views.py", line 754, in details
    return render(request, 'focus/comment.html', context)
  File "C:\Python36-32\lib\site-packages\django\shortcuts.py", line 30, in render
    content = loader.render_to_string(template_name, context, request, using=using)
  File "C:\Python36-32\lib\site-packages\django\template\loader.py", line 68, in render_to_string
    return template.render(context, request)
  File "C:\Python36-32\lib\site-packages\django\template\backends\django.py", line 66, in render
    return self.template.render(context)
  File "C:\Python36-32\lib\site-packages\django\template\base.py", line 207, in render
    return self._render(context)
  File "C:\Python36-32\lib\site-packages\django\template\base.py", line 199, in _render
    return self.nodelist.render(context)
  File "C:\Python36-32\lib\site-packages\django\template\base.py", line 990, in render
    bit = node.render_annotated(context)
  File "C:\Python36-32\lib\site-packages\django\template\base.py", line 957, in render_annotated
    return self.render(context)
  File "C:\Python36-32\lib\site-packages\django\template\defaulttags.py", line 172, in render
    values = list(values)
TypeError: 'ListSerializer' object is not iterable
2017-10-31 16:35:27,585 [Thread-1:14448] [django.request:135] [ERROR]- Internal Server Error: /details
Traceback (most recent call last):
  File "C:\Python36-32\lib\site-packages\django\core\handlers\exception.py", line 41, in inner
    response = get_response(request)
  File "C:\Python36-32\lib\site-packages\django\core\handlers\base.py", line 249, in _legacy_get_response
    response = self._get_response(request)
  File "C:\Python36-32\lib\site-packages\django\core\handlers\base.py", line 187, in _get_response
    response = self.process_exception_by_middleware(e, request)
  File "C:\Python36-32\lib\site-packages\django\core\handlers\base.py", line 185, in _get_response
    response = wrapped_callback(request, *callback_args, **callback_kwargs)
  File "D:\code\PycharmProjects\cms\focus\views.py", line 754, in details
    return JsonResponse(context)
  File "C:\Python36-32\lib\site-packages\django\http\response.py", line 530, in __init__
    data = json.dumps(data, cls=encoder, **json_dumps_params)
  File "C:\Python36-32\lib\json\__init__.py", line 238, in dumps
    **kw).encode(obj)
  File "C:\Python36-32\lib\json\encoder.py", line 199, in encode
    chunks = self.iterencode(o, _one_shot=True)
  File "C:\Python36-32\lib\json\encoder.py", line 257, in iterencode
    return _iterencode(o, 0)
  File "C:\Python36-32\lib\site-packages\django\core\serializers\json.py", line 124, in default
    return super(DjangoJSONEncoder, self).default(o)
  File "C:\Python36-32\lib\json\encoder.py", line 180, in default
    o.__class__.__name__)
TypeError: Object of type 'MyUserSerializer' is not JSON serializable
2017-10-31 16:37:59,236 [Thread-1:8300] [django.request:135] [ERROR]- Internal Server Error: /details
Traceback (most recent call last):
  File "C:\Python36-32\lib\site-packages\django\core\handlers\exception.py", line 41, in inner
    response = get_response(request)
  File "C:\Python36-32\lib\site-packages\django\core\handlers\base.py", line 249, in _legacy_get_response
    response = self._get_response(request)
  File "C:\Python36-32\lib\site-packages\django\core\handlers\base.py", line 187, in _get_response
    response = self.process_exception_by_middleware(e, request)
  File "C:\Python36-32\lib\site-packages\django\core\handlers\base.py", line 185, in _get_response
    response = wrapped_callback(request, *callback_args, **callback_kwargs)
  File "D:\code\PycharmProjects\cms\focus\views.py", line 754, in details
    return JsonResponse(context)
  File "C:\Python36-32\lib\site-packages\django\http\response.py", line 530, in __init__
    data = json.dumps(data, cls=encoder, **json_dumps_params)
  File "C:\Python36-32\lib\json\__init__.py", line 238, in dumps
    **kw).encode(obj)
  File "C:\Python36-32\lib\json\encoder.py", line 199, in encode
    chunks = self.iterencode(o, _one_shot=True)
  File "C:\Python36-32\lib\json\encoder.py", line 257, in iterencode
    return _iterencode(o, 0)
  File "C:\Python36-32\lib\site-packages\django\core\serializers\json.py", line 124, in default
    return super(DjangoJSONEncoder, self).default(o)
  File "C:\Python36-32\lib\json\encoder.py", line 180, in default
    o.__class__.__name__)
TypeError: Object of type 'Note' is not JSON serializable
2017-10-31 16:49:41,383 [Thread-1:11964] [django.request:135] [ERROR]- Internal Server Error: /details
Traceback (most recent call last):
  File "C:\Python36-32\lib\site-packages\django\core\handlers\exception.py", line 41, in inner
    response = get_response(request)
  File "C:\Python36-32\lib\site-packages\django\core\handlers\base.py", line 249, in _legacy_get_response
    response = self._get_response(request)
  File "C:\Python36-32\lib\site-packages\django\core\handlers\base.py", line 187, in _get_response
    response = self.process_exception_by_middleware(e, request)
  File "C:\Python36-32\lib\site-packages\django\core\handlers\base.py", line 185, in _get_response
    response = wrapped_callback(request, *callback_args, **callback_kwargs)
  File "D:\code\PycharmProjects\cms\focus\views.py", line 753, in details
    'note': json.dumps(json.loads(notes)[0]),
  File "C:\Python36-32\lib\json\__init__.py", line 348, in loads
    'not {!r}'.format(s.__class__.__name__))
TypeError: the JSON object must be str, bytes or bytearray, not 'ListSerializer'
2017-10-31 16:50:51,596 [Thread-1:13908] [django.request:135] [ERROR]- Internal Server Error: /details
Traceback (most recent call last):
  File "C:\Python36-32\lib\site-packages\django\core\handlers\exception.py", line 41, in inner
    response = get_response(request)
  File "C:\Python36-32\lib\site-packages\django\core\handlers\base.py", line 249, in _legacy_get_response
    response = self._get_response(request)
  File "C:\Python36-32\lib\site-packages\django\core\handlers\base.py", line 187, in _get_response
    response = self.process_exception_by_middleware(e, request)
  File "C:\Python36-32\lib\site-packages\django\core\handlers\base.py", line 185, in _get_response
    response = wrapped_callback(request, *callback_args, **callback_kwargs)
  File "D:\code\PycharmProjects\cms\focus\views.py", line 756, in details
    return JsonResponse(context)
  File "C:\Python36-32\lib\site-packages\django\http\response.py", line 530, in __init__
    data = json.dumps(data, cls=encoder, **json_dumps_params)
  File "C:\Python36-32\lib\json\__init__.py", line 238, in dumps
    **kw).encode(obj)
  File "C:\Python36-32\lib\json\encoder.py", line 199, in encode
    chunks = self.iterencode(o, _one_shot=True)
  File "C:\Python36-32\lib\json\encoder.py", line 257, in iterencode
    return _iterencode(o, 0)
  File "C:\Python36-32\lib\site-packages\django\core\serializers\json.py", line 124, in default
    return super(DjangoJSONEncoder, self).default(o)
  File "C:\Python36-32\lib\json\encoder.py", line 180, in default
    o.__class__.__name__)
TypeError: Object of type 'ListSerializer' is not JSON serializable
2017-11-01 18:00:54,311 [Thread-1:21372] [django.request:135] [ERROR]- Internal Server Error: /publish
Traceback (most recent call last):
  File "C:\Python36-32\lib\site-packages\PIL\Image.py", line 2481, in open
    fp.seek(0)
AttributeError: 'NoneType' object has no attribute 'seek'

During handling of the above exception, another exception occurred:

Traceback (most recent call last):
  File "C:\Python36-32\lib\site-packages\django\core\handlers\exception.py", line 41, in inner
    response = get_response(request)
  File "C:\Python36-32\lib\site-packages\django\core\handlers\base.py", line 249, in _legacy_get_response
    response = self._get_response(request)
  File "C:\Python36-32\lib\site-packages\django\core\handlers\base.py", line 187, in _get_response
    response = self.process_exception_by_middleware(e, request)
  File "C:\Python36-32\lib\site-packages\django\core\handlers\base.py", line 185, in _get_response
    response = wrapped_callback(request, *callback_args, **callback_kwargs)
  File "D:\code\PycharmProjects\cms\focus\views.py", line 708, in publish
    img = Image.open(photo)
  File "C:\Python36-32\lib\site-packages\PIL\Image.py", line 2483, in open
    fp = io.BytesIO(fp.read())
AttributeError: 'NoneType' object has no attribute 'read'
2017-11-01 18:02:50,276 [Thread-1:13980] [django.request:135] [ERROR]- Internal Server Error: /publish
Traceback (most recent call last):
  File "C:\Python36-32\lib\site-packages\django\db\backends\utils.py", line 65, in execute
    return self.cursor.execute(sql, params)
  File "C:\Python36-32\lib\site-packages\django\db\backends\mysql\base.py", line 101, in execute
    return self.cursor.execute(query, args)
  File "C:\Python36-32\lib\site-packages\pymysql\cursors.py", line 166, in execute
    result = self._query(query)
  File "C:\Python36-32\lib\site-packages\pymysql\cursors.py", line 322, in _query
    conn.query(q)
  File "C:\Python36-32\lib\site-packages\pymysql\connections.py", line 856, in query
    self._affected_rows = self._read_query_result(unbuffered=unbuffered)
  File "C:\Python36-32\lib\site-packages\pymysql\connections.py", line 1057, in _read_query_result
    result.read()
  File "C:\Python36-32\lib\site-packages\pymysql\connections.py", line 1340, in read
    first_packet = self.connection._read_packet()
  File "C:\Python36-32\lib\site-packages\pymysql\connections.py", line 1014, in _read_packet
    packet.check_error()
  File "C:\Python36-32\lib\site-packages\pymysql\connections.py", line 393, in check_error
    err.raise_mysql_exception(self._data)
  File "C:\Python36-32\lib\site-packages\pymysql\err.py", line 107, in raise_mysql_exception
    raise errorclass(errno, errval)
pymysql.err.IntegrityError: (1048, "Column 'text' cannot be null")

The above exception was the direct cause of the following exception:

Traceback (most recent call last):
  File "C:\Python36-32\lib\site-packages\django\core\handlers\exception.py", line 41, in inner
    response = get_response(request)
  File "C:\Python36-32\lib\site-packages\django\core\handlers\base.py", line 249, in _legacy_get_response
    response = self._get_response(request)
  File "C:\Python36-32\lib\site-packages\django\core\handlers\base.py", line 187, in _get_response
    response = self.process_exception_by_middleware(e, request)
  File "C:\Python36-32\lib\site-packages\django\core\handlers\base.py", line 185, in _get_response
    response = wrapped_callback(request, *callback_args, **callback_kwargs)
  File "D:\code\PycharmProjects\cms\focus\views.py", line 719, in publish
    note.save()
  File "D:\code\PycharmProjects\cms\focus\models.py", line 138, in save
    super(Note, self).save(*args, **kwargs)
  File "C:\Python36-32\lib\site-packages\django\db\models\base.py", line 807, in save
    force_update=force_update, update_fields=update_fields)
  File "C:\Python36-32\lib\site-packages\django\db\models\base.py", line 837, in save_base
    updated = self._save_table(raw, cls, force_insert, force_update, using, update_fields)
  File "C:\Python36-32\lib\site-packages\django\db\models\base.py", line 923, in _save_table
    result = self._do_insert(cls._base_manager, using, fields, update_pk, raw)
  File "C:\Python36-32\lib\site-packages\django\db\models\base.py", line 962, in _do_insert
    using=using, raw=raw)
  File "C:\Python36-32\lib\site-packages\django\db\models\manager.py", line 85, in manager_method
    return getattr(self.get_queryset(), name)(*args, **kwargs)
  File "C:\Python36-32\lib\site-packages\django\db\models\query.py", line 1076, in _insert
    return query.get_compiler(using=using).execute_sql(return_id)
  File "C:\Python36-32\lib\site-packages\django\db\models\sql\compiler.py", line 1107, in execute_sql
    cursor.execute(sql, params)
  File "C:\Python36-32\lib\site-packages\django\db\backends\utils.py", line 80, in execute
    return super(CursorDebugWrapper, self).execute(sql, params)
  File "C:\Python36-32\lib\site-packages\django\db\backends\utils.py", line 65, in execute
    return self.cursor.execute(sql, params)
  File "C:\Python36-32\lib\site-packages\django\db\utils.py", line 94, in __exit__
    six.reraise(dj_exc_type, dj_exc_value, traceback)
  File "C:\Python36-32\lib\site-packages\django\utils\six.py", line 685, in reraise
    raise value.with_traceback(tb)
  File "C:\Python36-32\lib\site-packages\django\db\backends\utils.py", line 65, in execute
    return self.cursor.execute(sql, params)
  File "C:\Python36-32\lib\site-packages\django\db\backends\mysql\base.py", line 101, in execute
    return self.cursor.execute(query, args)
  File "C:\Python36-32\lib\site-packages\pymysql\cursors.py", line 166, in execute
    result = self._query(query)
  File "C:\Python36-32\lib\site-packages\pymysql\cursors.py", line 322, in _query
    conn.query(q)
  File "C:\Python36-32\lib\site-packages\pymysql\connections.py", line 856, in query
    self._affected_rows = self._read_query_result(unbuffered=unbuffered)
  File "C:\Python36-32\lib\site-packages\pymysql\connections.py", line 1057, in _read_query_result
    result.read()
  File "C:\Python36-32\lib\site-packages\pymysql\connections.py", line 1340, in read
    first_packet = self.connection._read_packet()
  File "C:\Python36-32\lib\site-packages\pymysql\connections.py", line 1014, in _read_packet
    packet.check_error()
  File "C:\Python36-32\lib\site-packages\pymysql\connections.py", line 393, in check_error
    err.raise_mysql_exception(self._data)
  File "C:\Python36-32\lib\site-packages\pymysql\err.py", line 107, in raise_mysql_exception
    raise errorclass(errno, errval)
django.db.utils.IntegrityError: (1048, "Column 'text' cannot be null")
2017-11-01 18:04:01,945 [Thread-1:13856] [django.request:135] [ERROR]- Internal Server Error: /publish
Traceback (most recent call last):
  File "C:\Python36-32\lib\site-packages\django\db\backends\utils.py", line 65, in execute
    return self.cursor.execute(sql, params)
  File "C:\Python36-32\lib\site-packages\django\db\backends\mysql\base.py", line 101, in execute
    return self.cursor.execute(query, args)
  File "C:\Python36-32\lib\site-packages\pymysql\cursors.py", line 166, in execute
    result = self._query(query)
  File "C:\Python36-32\lib\site-packages\pymysql\cursors.py", line 322, in _query
    conn.query(q)
  File "C:\Python36-32\lib\site-packages\pymysql\connections.py", line 856, in query
    self._affected_rows = self._read_query_result(unbuffered=unbuffered)
  File "C:\Python36-32\lib\site-packages\pymysql\connections.py", line 1057, in _read_query_result
    result.read()
  File "C:\Python36-32\lib\site-packages\pymysql\connections.py", line 1340, in read
    first_packet = self.connection._read_packet()
  File "C:\Python36-32\lib\site-packages\pymysql\connections.py", line 1014, in _read_packet
    packet.check_error()
  File "C:\Python36-32\lib\site-packages\pymysql\connections.py", line 393, in check_error
    err.raise_mysql_exception(self._data)
  File "C:\Python36-32\lib\site-packages\pymysql\err.py", line 107, in raise_mysql_exception
    raise errorclass(errno, errval)
pymysql.err.IntegrityError: (1048, "Column 'text' cannot be null")

The above exception was the direct cause of the following exception:

Traceback (most recent call last):
  File "C:\Python36-32\lib\site-packages\django\core\handlers\exception.py", line 41, in inner
    response = get_response(request)
  File "C:\Python36-32\lib\site-packages\django\core\handlers\base.py", line 249, in _legacy_get_response
    response = self._get_response(request)
  File "C:\Python36-32\lib\site-packages\django\core\handlers\base.py", line 187, in _get_response
    response = self.process_exception_by_middleware(e, request)
  File "C:\Python36-32\lib\site-packages\django\core\handlers\base.py", line 185, in _get_response
    response = wrapped_callback(request, *callback_args, **callback_kwargs)
  File "D:\code\PycharmProjects\cms\focus\views.py", line 719, in publish
    note.save()
  File "D:\code\PycharmProjects\cms\focus\models.py", line 138, in save
    super(Note, self).save(*args, **kwargs)
  File "C:\Python36-32\lib\site-packages\django\db\models\base.py", line 807, in save
    force_update=force_update, update_fields=update_fields)
  File "C:\Python36-32\lib\site-packages\django\db\models\base.py", line 837, in save_base
    updated = self._save_table(raw, cls, force_insert, force_update, using, update_fields)
  File "C:\Python36-32\lib\site-packages\django\db\models\base.py", line 923, in _save_table
    result = self._do_insert(cls._base_manager, using, fields, update_pk, raw)
  File "C:\Python36-32\lib\site-packages\django\db\models\base.py", line 962, in _do_insert
    using=using, raw=raw)
  File "C:\Python36-32\lib\site-packages\django\db\models\manager.py", line 85, in manager_method
    return getattr(self.get_queryset(), name)(*args, **kwargs)
  File "C:\Python36-32\lib\site-packages\django\db\models\query.py", line 1076, in _insert
    return query.get_compiler(using=using).execute_sql(return_id)
  File "C:\Python36-32\lib\site-packages\django\db\models\sql\compiler.py", line 1107, in execute_sql
    cursor.execute(sql, params)
  File "C:\Python36-32\lib\site-packages\django\db\backends\utils.py", line 80, in execute
    return super(CursorDebugWrapper, self).execute(sql, params)
  File "C:\Python36-32\lib\site-packages\django\db\backends\utils.py", line 65, in execute
    return self.cursor.execute(sql, params)
  File "C:\Python36-32\lib\site-packages\django\db\utils.py", line 94, in __exit__
    six.reraise(dj_exc_type, dj_exc_value, traceback)
  File "C:\Python36-32\lib\site-packages\django\utils\six.py", line 685, in reraise
    raise value.with_traceback(tb)
  File "C:\Python36-32\lib\site-packages\django\db\backends\utils.py", line 65, in execute
    return self.cursor.execute(sql, params)
  File "C:\Python36-32\lib\site-packages\django\db\backends\mysql\base.py", line 101, in execute
    return self.cursor.execute(query, args)
  File "C:\Python36-32\lib\site-packages\pymysql\cursors.py", line 166, in execute
    result = self._query(query)
  File "C:\Python36-32\lib\site-packages\pymysql\cursors.py", line 322, in _query
    conn.query(q)
  File "C:\Python36-32\lib\site-packages\pymysql\connections.py", line 856, in query
    self._affected_rows = self._read_query_result(unbuffered=unbuffered)
  File "C:\Python36-32\lib\site-packages\pymysql\connections.py", line 1057, in _read_query_result
    result.read()
  File "C:\Python36-32\lib\site-packages\pymysql\connections.py", line 1340, in read
    first_packet = self.connection._read_packet()
  File "C:\Python36-32\lib\site-packages\pymysql\connections.py", line 1014, in _read_packet
    packet.check_error()
  File "C:\Python36-32\lib\site-packages\pymysql\connections.py", line 393, in check_error
    err.raise_mysql_exception(self._data)
  File "C:\Python36-32\lib\site-packages\pymysql\err.py", line 107, in raise_mysql_exception
    raise errorclass(errno, errval)
django.db.utils.IntegrityError: (1048, "Column 'text' cannot be null")
2017-11-02 11:44:34,105 [Thread-3:11420] [django.request:135] [ERROR]- Internal Server Error: /contents
Traceback (most recent call last):
  File "C:\Python36-32\lib\site-packages\rest_framework\fields.py", line 444, in get_attribute
    return get_attribute(instance, self.source_attrs)
  File "C:\Python36-32\lib\site-packages\rest_framework\fields.py", line 103, in get_attribute
    instance = getattr(instance, attr)
AttributeError: 'AnonymousUser' object has no attribute 'avatar'

During handling of the above exception, another exception occurred:

Traceback (most recent call last):
  File "C:\Python36-32\lib\site-packages\django\core\handlers\exception.py", line 41, in inner
    response = get_response(request)
  File "C:\Python36-32\lib\site-packages\django\core\handlers\base.py", line 249, in _legacy_get_response
    response = self._get_response(request)
  File "C:\Python36-32\lib\site-packages\django\core\handlers\base.py", line 187, in _get_response
    response = self.process_exception_by_middleware(e, request)
  File "C:\Python36-32\lib\site-packages\django\core\handlers\base.py", line 185, in _get_response
    response = wrapped_callback(request, *callback_args, **callback_kwargs)
  File "C:\Python36-32\lib\site-packages\django\views\decorators\csrf.py", line 58, in wrapped_view
    return view_func(*args, **kwargs)
  File "C:\Python36-32\lib\site-packages\django\views\generic\base.py", line 68, in view
    return self.dispatch(request, *args, **kwargs)
  File "C:\Python36-32\lib\site-packages\rest_framework\views.py", line 489, in dispatch
    response = self.handle_exception(exc)
  File "C:\Python36-32\lib\site-packages\rest_framework\views.py", line 449, in handle_exception
    self.raise_uncaught_exception(exc)
  File "C:\Python36-32\lib\site-packages\rest_framework\views.py", line 486, in dispatch
    response = handler(request, *args, **kwargs)
  File "D:\code\PycharmProjects\cms\focus\views.py", line 241, in post
    'user': user.data,
  File "C:\Python36-32\lib\site-packages\rest_framework\serializers.py", line 534, in data
    ret = super(Serializer, self).data
  File "C:\Python36-32\lib\site-packages\rest_framework\serializers.py", line 263, in data
    self._data = self.to_representation(self.instance)
  File "C:\Python36-32\lib\site-packages\rest_framework\serializers.py", line 488, in to_representation
    attribute = field.get_attribute(instance)
  File "C:\Python36-32\lib\site-packages\rest_framework\fields.py", line 463, in get_attribute
    raise type(exc)(msg)
AttributeError: Got AttributeError when attempting to get a value for field `avatar` on serializer `MyUserSerializer`.
The serializer field might be named incorrectly and not match any attribute or key on the `AnonymousUser` instance.
Original exception text was: 'AnonymousUser' object has no attribute 'avatar'.
2017-11-02 11:44:35,038 [Thread-4:20820] [django.request:135] [ERROR]- Internal Server Error: /contents
Traceback (most recent call last):
  File "C:\Python36-32\lib\site-packages\rest_framework\fields.py", line 444, in get_attribute
    return get_attribute(instance, self.source_attrs)
  File "C:\Python36-32\lib\site-packages\rest_framework\fields.py", line 103, in get_attribute
    instance = getattr(instance, attr)
AttributeError: 'AnonymousUser' object has no attribute 'avatar'

During handling of the above exception, another exception occurred:

Traceback (most recent call last):
  File "C:\Python36-32\lib\site-packages\django\core\handlers\exception.py", line 41, in inner
    response = get_response(request)
  File "C:\Python36-32\lib\site-packages\django\core\handlers\base.py", line 249, in _legacy_get_response
    response = self._get_response(request)
  File "C:\Python36-32\lib\site-packages\django\core\handlers\base.py", line 187, in _get_response
    response = self.process_exception_by_middleware(e, request)
  File "C:\Python36-32\lib\site-packages\django\core\handlers\base.py", line 185, in _get_response
    response = wrapped_callback(request, *callback_args, **callback_kwargs)
  File "C:\Python36-32\lib\site-packages\django\views\decorators\csrf.py", line 58, in wrapped_view
    return view_func(*args, **kwargs)
  File "C:\Python36-32\lib\site-packages\django\views\generic\base.py", line 68, in view
    return self.dispatch(request, *args, **kwargs)
  File "C:\Python36-32\lib\site-packages\rest_framework\views.py", line 489, in dispatch
    response = self.handle_exception(exc)
  File "C:\Python36-32\lib\site-packages\rest_framework\views.py", line 449, in handle_exception
    self.raise_uncaught_exception(exc)
  File "C:\Python36-32\lib\site-packages\rest_framework\views.py", line 486, in dispatch
    response = handler(request, *args, **kwargs)
  File "D:\code\PycharmProjects\cms\focus\views.py", line 241, in post
    'user': user.data,
  File "C:\Python36-32\lib\site-packages\rest_framework\serializers.py", line 534, in data
    ret = super(Serializer, self).data
  File "C:\Python36-32\lib\site-packages\rest_framework\serializers.py", line 263, in data
    self._data = self.to_representation(self.instance)
  File "C:\Python36-32\lib\site-packages\rest_framework\serializers.py", line 488, in to_representation
    attribute = field.get_attribute(instance)
  File "C:\Python36-32\lib\site-packages\rest_framework\fields.py", line 463, in get_attribute
    raise type(exc)(msg)
AttributeError: Got AttributeError when attempting to get a value for field `avatar` on serializer `MyUserSerializer`.
The serializer field might be named incorrectly and not match any attribute or key on the `AnonymousUser` instance.
Original exception text was: 'AnonymousUser' object has no attribute 'avatar'.
2017-11-02 11:44:41,342 [Thread-6:19424] [django.request:135] [ERROR]- Internal Server Error: /contents
Traceback (most recent call last):
  File "C:\Python36-32\lib\site-packages\rest_framework\fields.py", line 444, in get_attribute
    return get_attribute(instance, self.source_attrs)
  File "C:\Python36-32\lib\site-packages\rest_framework\fields.py", line 103, in get_attribute
    instance = getattr(instance, attr)
AttributeError: 'AnonymousUser' object has no attribute 'avatar'

During handling of the above exception, another exception occurred:

Traceback (most recent call last):
  File "C:\Python36-32\lib\site-packages\django\core\handlers\exception.py", line 41, in inner
    response = get_response(request)
  File "C:\Python36-32\lib\site-packages\django\core\handlers\base.py", line 249, in _legacy_get_response
    response = self._get_response(request)
  File "C:\Python36-32\lib\site-packages\django\core\handlers\base.py", line 187, in _get_response
    response = self.process_exception_by_middleware(e, request)
  File "C:\Python36-32\lib\site-packages\django\core\handlers\base.py", line 185, in _get_response
    response = wrapped_callback(request, *callback_args, **callback_kwargs)
  File "C:\Python36-32\lib\site-packages\django\views\decorators\csrf.py", line 58, in wrapped_view
    return view_func(*args, **kwargs)
  File "C:\Python36-32\lib\site-packages\django\views\generic\base.py", line 68, in view
    return self.dispatch(request, *args, **kwargs)
  File "C:\Python36-32\lib\site-packages\rest_framework\views.py", line 489, in dispatch
    response = self.handle_exception(exc)
  File "C:\Python36-32\lib\site-packages\rest_framework\views.py", line 449, in handle_exception
    self.raise_uncaught_exception(exc)
  File "C:\Python36-32\lib\site-packages\rest_framework\views.py", line 486, in dispatch
    response = handler(request, *args, **kwargs)
  File "D:\code\PycharmProjects\cms\focus\views.py", line 241, in post
    'user': user.data,
  File "C:\Python36-32\lib\site-packages\rest_framework\serializers.py", line 534, in data
    ret = super(Serializer, self).data
  File "C:\Python36-32\lib\site-packages\rest_framework\serializers.py", line 263, in data
    self._data = self.to_representation(self.instance)
  File "C:\Python36-32\lib\site-packages\rest_framework\serializers.py", line 488, in to_representation
    attribute = field.get_attribute(instance)
  File "C:\Python36-32\lib\site-packages\rest_framework\fields.py", line 463, in get_attribute
    raise type(exc)(msg)
AttributeError: Got AttributeError when attempting to get a value for field `avatar` on serializer `MyUserSerializer`.
The serializer field might be named incorrectly and not match any attribute or key on the `AnonymousUser` instance.
Original exception text was: 'AnonymousUser' object has no attribute 'avatar'.
2017-11-02 11:45:17,980 [Thread-7:9720] [django.request:135] [ERROR]- Internal Server Error: /contents
Traceback (most recent call last):
  File "C:\Python36-32\lib\site-packages\rest_framework\fields.py", line 444, in get_attribute
    return get_attribute(instance, self.source_attrs)
  File "C:\Python36-32\lib\site-packages\rest_framework\fields.py", line 103, in get_attribute
    instance = getattr(instance, attr)
AttributeError: 'AnonymousUser' object has no attribute 'avatar'

During handling of the above exception, another exception occurred:

Traceback (most recent call last):
  File "C:\Python36-32\lib\site-packages\django\core\handlers\exception.py", line 41, in inner
    response = get_response(request)
  File "C:\Python36-32\lib\site-packages\django\core\handlers\base.py", line 249, in _legacy_get_response
    response = self._get_response(request)
  File "C:\Python36-32\lib\site-packages\django\core\handlers\base.py", line 187, in _get_response
    response = self.process_exception_by_middleware(e, request)
  File "C:\Python36-32\lib\site-packages\django\core\handlers\base.py", line 185, in _get_response
    response = wrapped_callback(request, *callback_args, **callback_kwargs)
  File "C:\Python36-32\lib\site-packages\django\views\decorators\csrf.py", line 58, in wrapped_view
    return view_func(*args, **kwargs)
  File "C:\Python36-32\lib\site-packages\django\views\generic\base.py", line 68, in view
    return self.dispatch(request, *args, **kwargs)
  File "C:\Python36-32\lib\site-packages\rest_framework\views.py", line 489, in dispatch
    response = self.handle_exception(exc)
  File "C:\Python36-32\lib\site-packages\rest_framework\views.py", line 449, in handle_exception
    self.raise_uncaught_exception(exc)
  File "C:\Python36-32\lib\site-packages\rest_framework\views.py", line 486, in dispatch
    response = handler(request, *args, **kwargs)
  File "D:\code\PycharmProjects\cms\focus\views.py", line 241, in post
    'user': user.data,
  File "C:\Python36-32\lib\site-packages\rest_framework\serializers.py", line 534, in data
    ret = super(Serializer, self).data
  File "C:\Python36-32\lib\site-packages\rest_framework\serializers.py", line 263, in data
    self._data = self.to_representation(self.instance)
  File "C:\Python36-32\lib\site-packages\rest_framework\serializers.py", line 488, in to_representation
    attribute = field.get_attribute(instance)
  File "C:\Python36-32\lib\site-packages\rest_framework\fields.py", line 463, in get_attribute
    raise type(exc)(msg)
AttributeError: Got AttributeError when attempting to get a value for field `avatar` on serializer `MyUserSerializer`.
The serializer field might be named incorrectly and not match any attribute or key on the `AnonymousUser` instance.
Original exception text was: 'AnonymousUser' object has no attribute 'avatar'.
2017-11-02 11:45:21,762 [Thread-8:22016] [django.request:135] [ERROR]- Internal Server Error: /contents
Traceback (most recent call last):
  File "C:\Python36-32\lib\site-packages\rest_framework\fields.py", line 444, in get_attribute
    return get_attribute(instance, self.source_attrs)
  File "C:\Python36-32\lib\site-packages\rest_framework\fields.py", line 103, in get_attribute
    instance = getattr(instance, attr)
AttributeError: 'AnonymousUser' object has no attribute 'avatar'

During handling of the above exception, another exception occurred:

Traceback (most recent call last):
  File "C:\Python36-32\lib\site-packages\django\core\handlers\exception.py", line 41, in inner
    response = get_response(request)
  File "C:\Python36-32\lib\site-packages\django\core\handlers\base.py", line 249, in _legacy_get_response
    response = self._get_response(request)
  File "C:\Python36-32\lib\site-packages\django\core\handlers\base.py", line 187, in _get_response
    response = self.process_exception_by_middleware(e, request)
  File "C:\Python36-32\lib\site-packages\django\core\handlers\base.py", line 185, in _get_response
    response = wrapped_callback(request, *callback_args, **callback_kwargs)
  File "C:\Python36-32\lib\site-packages\django\views\decorators\csrf.py", line 58, in wrapped_view
    return view_func(*args, **kwargs)
  File "C:\Python36-32\lib\site-packages\django\views\generic\base.py", line 68, in view
    return self.dispatch(request, *args, **kwargs)
  File "C:\Python36-32\lib\site-packages\rest_framework\views.py", line 489, in dispatch
    response = self.handle_exception(exc)
  File "C:\Python36-32\lib\site-packages\rest_framework\views.py", line 449, in handle_exception
    self.raise_uncaught_exception(exc)
  File "C:\Python36-32\lib\site-packages\rest_framework\views.py", line 486, in dispatch
    response = handler(request, *args, **kwargs)
  File "D:\code\PycharmProjects\cms\focus\views.py", line 241, in post
    'user': user.data,
  File "C:\Python36-32\lib\site-packages\rest_framework\serializers.py", line 534, in data
    ret = super(Serializer, self).data
  File "C:\Python36-32\lib\site-packages\rest_framework\serializers.py", line 263, in data
    self._data = self.to_representation(self.instance)
  File "C:\Python36-32\lib\site-packages\rest_framework\serializers.py", line 488, in to_representation
    attribute = field.get_attribute(instance)
  File "C:\Python36-32\lib\site-packages\rest_framework\fields.py", line 463, in get_attribute
    raise type(exc)(msg)
AttributeError: Got AttributeError when attempting to get a value for field `avatar` on serializer `MyUserSerializer`.
The serializer field might be named incorrectly and not match any attribute or key on the `AnonymousUser` instance.
Original exception text was: 'AnonymousUser' object has no attribute 'avatar'.
2017-11-02 11:45:26,425 [Thread-9:14500] [django.request:135] [ERROR]- Internal Server Error: /contents
Traceback (most recent call last):
  File "C:\Python36-32\lib\site-packages\rest_framework\fields.py", line 444, in get_attribute
    return get_attribute(instance, self.source_attrs)
  File "C:\Python36-32\lib\site-packages\rest_framework\fields.py", line 103, in get_attribute
    instance = getattr(instance, attr)
AttributeError: 'AnonymousUser' object has no attribute 'avatar'

During handling of the above exception, another exception occurred:

Traceback (most recent call last):
  File "C:\Python36-32\lib\site-packages\django\core\handlers\exception.py", line 41, in inner
    response = get_response(request)
  File "C:\Python36-32\lib\site-packages\django\core\handlers\base.py", line 249, in _legacy_get_response
    response = self._get_response(request)
  File "C:\Python36-32\lib\site-packages\django\core\handlers\base.py", line 187, in _get_response
    response = self.process_exception_by_middleware(e, request)
  File "C:\Python36-32\lib\site-packages\django\core\handlers\base.py", line 185, in _get_response
    response = wrapped_callback(request, *callback_args, **callback_kwargs)
  File "C:\Python36-32\lib\site-packages\django\views\decorators\csrf.py", line 58, in wrapped_view
    return view_func(*args, **kwargs)
  File "C:\Python36-32\lib\site-packages\django\views\generic\base.py", line 68, in view
    return self.dispatch(request, *args, **kwargs)
  File "C:\Python36-32\lib\site-packages\rest_framework\views.py", line 489, in dispatch
    response = self.handle_exception(exc)
  File "C:\Python36-32\lib\site-packages\rest_framework\views.py", line 449, in handle_exception
    self.raise_uncaught_exception(exc)
  File "C:\Python36-32\lib\site-packages\rest_framework\views.py", line 486, in dispatch
    response = handler(request, *args, **kwargs)
  File "D:\code\PycharmProjects\cms\focus\views.py", line 241, in post
    'user': user.data,
  File "C:\Python36-32\lib\site-packages\rest_framework\serializers.py", line 534, in data
    ret = super(Serializer, self).data
  File "C:\Python36-32\lib\site-packages\rest_framework\serializers.py", line 263, in data
    self._data = self.to_representation(self.instance)
  File "C:\Python36-32\lib\site-packages\rest_framework\serializers.py", line 488, in to_representation
    attribute = field.get_attribute(instance)
  File "C:\Python36-32\lib\site-packages\rest_framework\fields.py", line 463, in get_attribute
    raise type(exc)(msg)
AttributeError: Got AttributeError when attempting to get a value for field `avatar` on serializer `MyUserSerializer`.
The serializer field might be named incorrectly and not match any attribute or key on the `AnonymousUser` instance.
Original exception text was: 'AnonymousUser' object has no attribute 'avatar'.
2017-11-02 11:46:15,696 [Thread-10:15100] [django.request:135] [ERROR]- Internal Server Error: /contents
Traceback (most recent call last):
  File "C:\Python36-32\lib\site-packages\rest_framework\fields.py", line 444, in get_attribute
    return get_attribute(instance, self.source_attrs)
  File "C:\Python36-32\lib\site-packages\rest_framework\fields.py", line 103, in get_attribute
    instance = getattr(instance, attr)
AttributeError: 'AnonymousUser' object has no attribute 'avatar'

During handling of the above exception, another exception occurred:

Traceback (most recent call last):
  File "C:\Python36-32\lib\site-packages\django\core\handlers\exception.py", line 41, in inner
    response = get_response(request)
  File "C:\Python36-32\lib\site-packages\django\core\handlers\base.py", line 249, in _legacy_get_response
    response = self._get_response(request)
  File "C:\Python36-32\lib\site-packages\django\core\handlers\base.py", line 187, in _get_response
    response = self.process_exception_by_middleware(e, request)
  File "C:\Python36-32\lib\site-packages\django\core\handlers\base.py", line 185, in _get_response
    response = wrapped_callback(request, *callback_args, **callback_kwargs)
  File "C:\Python36-32\lib\site-packages\django\views\decorators\csrf.py", line 58, in wrapped_view
    return view_func(*args, **kwargs)
  File "C:\Python36-32\lib\site-packages\django\views\generic\base.py", line 68, in view
    return self.dispatch(request, *args, **kwargs)
  File "C:\Python36-32\lib\site-packages\rest_framework\views.py", line 489, in dispatch
    response = self.handle_exception(exc)
  File "C:\Python36-32\lib\site-packages\rest_framework\views.py", line 449, in handle_exception
    self.raise_uncaught_exception(exc)
  File "C:\Python36-32\lib\site-packages\rest_framework\views.py", line 486, in dispatch
    response = handler(request, *args, **kwargs)
  File "D:\code\PycharmProjects\cms\focus\views.py", line 241, in post
    'user': user.data,
  File "C:\Python36-32\lib\site-packages\rest_framework\serializers.py", line 534, in data
    ret = super(Serializer, self).data
  File "C:\Python36-32\lib\site-packages\rest_framework\serializers.py", line 263, in data
    self._data = self.to_representation(self.instance)
  File "C:\Python36-32\lib\site-packages\rest_framework\serializers.py", line 488, in to_representation
    attribute = field.get_attribute(instance)
  File "C:\Python36-32\lib\site-packages\rest_framework\fields.py", line 463, in get_attribute
    raise type(exc)(msg)
AttributeError: Got AttributeError when attempting to get a value for field `avatar` on serializer `MyUserSerializer`.
The serializer field might be named incorrectly and not match any attribute or key on the `AnonymousUser` instance.
Original exception text was: 'AnonymousUser' object has no attribute 'avatar'.
2017-11-02 14:03:21,515 [Thread-55:4384] [django.request:135] [ERROR]- Internal Server Error: /contents
Traceback (most recent call last):
  File "C:\Python36-32\lib\site-packages\django\core\handlers\exception.py", line 41, in inner
    response = get_response(request)
  File "C:\Python36-32\lib\site-packages\django\core\handlers\base.py", line 249, in _legacy_get_response
    response = self._get_response(request)
  File "C:\Python36-32\lib\site-packages\django\core\handlers\base.py", line 187, in _get_response
    response = self.process_exception_by_middleware(e, request)
  File "C:\Python36-32\lib\site-packages\django\core\handlers\base.py", line 185, in _get_response
    response = wrapped_callback(request, *callback_args, **callback_kwargs)
  File "C:\Python36-32\lib\site-packages\django\views\decorators\csrf.py", line 58, in wrapped_view
    return view_func(*args, **kwargs)
  File "C:\Python36-32\lib\site-packages\django\views\generic\base.py", line 68, in view
    return self.dispatch(request, *args, **kwargs)
  File "C:\Python36-32\lib\site-packages\rest_framework\views.py", line 489, in dispatch
    response = self.handle_exception(exc)
  File "C:\Python36-32\lib\site-packages\rest_framework\views.py", line 449, in handle_exception
    self.raise_uncaught_exception(exc)
  File "C:\Python36-32\lib\site-packages\rest_framework\views.py", line 486, in dispatch
    response = handler(request, *args, **kwargs)
  File "D:\code\PycharmProjects\cms\focus\views.py", line 236, in post
    query_set = query_set[start:end]
  File "C:\Python36-32\lib\site-packages\django\db\models\query.py", line 269, in __getitem__
    "Negative indexing is not supported."
AssertionError: Negative indexing is not supported.
2017-11-02 15:01:35,382 [Thread-3:14784] [django.request:135] [ERROR]- Internal Server Error: /manager/user_state/
Traceback (most recent call last):
  File "C:\Python36-32\lib\site-packages\django\core\handlers\exception.py", line 41, in inner
    response = get_response(request)
  File "C:\Python36-32\lib\site-packages\django\core\handlers\base.py", line 249, in _legacy_get_response
    response = self._get_response(request)
  File "C:\Python36-32\lib\site-packages\django\core\handlers\base.py", line 187, in _get_response
    response = self.process_exception_by_middleware(e, request)
  File "C:\Python36-32\lib\site-packages\django\core\handlers\base.py", line 185, in _get_response
    response = wrapped_callback(request, *callback_args, **callback_kwargs)
  File "C:\Python36-32\lib\site-packages\django\views\decorators\csrf.py", line 58, in wrapped_view
    return view_func(*args, **kwargs)
  File "C:\Python36-32\lib\site-packages\django\views\generic\base.py", line 68, in view
    return self.dispatch(request, *args, **kwargs)
  File "C:\Python36-32\lib\site-packages\rest_framework\views.py", line 489, in dispatch
    response = self.handle_exception(exc)
  File "C:\Python36-32\lib\site-packages\rest_framework\views.py", line 449, in handle_exception
    self.raise_uncaught_exception(exc)
  File "C:\Python36-32\lib\site-packages\rest_framework\views.py", line 486, in dispatch
    response = handler(request, *args, **kwargs)
  File "C:\Python36-32\lib\site-packages\rest_framework\decorators.py", line 52, in handler
    return func(*args, **kwargs)
  File "D:\code\PycharmProjects\cms\manager\views.py", line 171, in user_state
    return JsonResponse(context)
  File "C:\Python36-32\lib\site-packages\django\http\response.py", line 530, in __init__
    data = json.dumps(data, cls=encoder, **json_dumps_params)
  File "C:\Python36-32\lib\json\__init__.py", line 238, in dumps
    **kw).encode(obj)
  File "C:\Python36-32\lib\json\encoder.py", line 199, in encode
    chunks = self.iterencode(o, _one_shot=True)
  File "C:\Python36-32\lib\json\encoder.py", line 257, in iterencode
    return _iterencode(o, 0)
  File "C:\Python36-32\lib\site-packages\django\core\serializers\json.py", line 124, in default
    return super(DjangoJSONEncoder, self).default(o)
  File "C:\Python36-32\lib\json\encoder.py", line 180, in default
    o.__class__.__name__)
TypeError: Object of type 'MyUserSerializer' is not JSON serializable
2017-11-02 15:01:47,265 [Thread-5:736] [django.request:135] [ERROR]- Internal Server Error: /manager/user_state/
Traceback (most recent call last):
  File "C:\Python36-32\lib\site-packages\django\core\handlers\exception.py", line 41, in inner
    response = get_response(request)
  File "C:\Python36-32\lib\site-packages\django\core\handlers\base.py", line 249, in _legacy_get_response
    response = self._get_response(request)
  File "C:\Python36-32\lib\site-packages\django\core\handlers\base.py", line 187, in _get_response
    response = self.process_exception_by_middleware(e, request)
  File "C:\Python36-32\lib\site-packages\django\core\handlers\base.py", line 185, in _get_response
    response = wrapped_callback(request, *callback_args, **callback_kwargs)
  File "C:\Python36-32\lib\site-packages\django\views\decorators\csrf.py", line 58, in wrapped_view
    return view_func(*args, **kwargs)
  File "C:\Python36-32\lib\site-packages\django\views\generic\base.py", line 68, in view
    return self.dispatch(request, *args, **kwargs)
  File "C:\Python36-32\lib\site-packages\rest_framework\views.py", line 489, in dispatch
    response = self.handle_exception(exc)
  File "C:\Python36-32\lib\site-packages\rest_framework\views.py", line 449, in handle_exception
    self.raise_uncaught_exception(exc)
  File "C:\Python36-32\lib\site-packages\rest_framework\views.py", line 486, in dispatch
    response = handler(request, *args, **kwargs)
  File "C:\Python36-32\lib\site-packages\rest_framework\decorators.py", line 52, in handler
    return func(*args, **kwargs)
  File "D:\code\PycharmProjects\cms\manager\views.py", line 171, in user_state
    return JsonResponse(context)
  File "C:\Python36-32\lib\site-packages\django\http\response.py", line 530, in __init__
    data = json.dumps(data, cls=encoder, **json_dumps_params)
  File "C:\Python36-32\lib\json\__init__.py", line 238, in dumps
    **kw).encode(obj)
  File "C:\Python36-32\lib\json\encoder.py", line 199, in encode
    chunks = self.iterencode(o, _one_shot=True)
  File "C:\Python36-32\lib\json\encoder.py", line 257, in iterencode
    return _iterencode(o, 0)
  File "C:\Python36-32\lib\site-packages\django\core\serializers\json.py", line 124, in default
    return super(DjangoJSONEncoder, self).default(o)
  File "C:\Python36-32\lib\json\encoder.py", line 180, in default
    o.__class__.__name__)
TypeError: Object of type 'MyUserSerializer' is not JSON serializable
2017-11-02 15:01:57,029 [Thread-7:20564] [django.request:135] [ERROR]- Internal Server Error: /manager/user_state/
Traceback (most recent call last):
  File "C:\Python36-32\lib\site-packages\django\core\handlers\exception.py", line 41, in inner
    response = get_response(request)
  File "C:\Python36-32\lib\site-packages\django\core\handlers\base.py", line 249, in _legacy_get_response
    response = self._get_response(request)
  File "C:\Python36-32\lib\site-packages\django\core\handlers\base.py", line 187, in _get_response
    response = self.process_exception_by_middleware(e, request)
  File "C:\Python36-32\lib\site-packages\django\core\handlers\base.py", line 185, in _get_response
    response = wrapped_callback(request, *callback_args, **callback_kwargs)
  File "C:\Python36-32\lib\site-packages\django\views\decorators\csrf.py", line 58, in wrapped_view
    return view_func(*args, **kwargs)
  File "C:\Python36-32\lib\site-packages\django\views\generic\base.py", line 68, in view
    return self.dispatch(request, *args, **kwargs)
  File "C:\Python36-32\lib\site-packages\rest_framework\views.py", line 489, in dispatch
    response = self.handle_exception(exc)
  File "C:\Python36-32\lib\site-packages\rest_framework\views.py", line 449, in handle_exception
    self.raise_uncaught_exception(exc)
  File "C:\Python36-32\lib\site-packages\rest_framework\views.py", line 486, in dispatch
    response = handler(request, *args, **kwargs)
  File "C:\Python36-32\lib\site-packages\rest_framework\decorators.py", line 52, in handler
    return func(*args, **kwargs)
  File "D:\code\PycharmProjects\cms\manager\views.py", line 171, in user_state
    return JsonResponse(context)
  File "C:\Python36-32\lib\site-packages\django\http\response.py", line 530, in __init__
    data = json.dumps(data, cls=encoder, **json_dumps_params)
  File "C:\Python36-32\lib\json\__init__.py", line 238, in dumps
    **kw).encode(obj)
  File "C:\Python36-32\lib\json\encoder.py", line 199, in encode
    chunks = self.iterencode(o, _one_shot=True)
  File "C:\Python36-32\lib\json\encoder.py", line 257, in iterencode
    return _iterencode(o, 0)
  File "C:\Python36-32\lib\site-packages\django\core\serializers\json.py", line 124, in default
    return super(DjangoJSONEncoder, self).default(o)
  File "C:\Python36-32\lib\json\encoder.py", line 180, in default
    o.__class__.__name__)
TypeError: Object of type 'MyUserSerializer' is not JSON serializable
2017-11-02 15:02:56,393 [Thread-9:17772] [django.request:135] [ERROR]- Internal Server Error: /manager/user_state/
Traceback (most recent call last):
  File "C:\Python36-32\lib\site-packages\django\core\handlers\exception.py", line 41, in inner
    response = get_response(request)
  File "C:\Python36-32\lib\site-packages\django\core\handlers\base.py", line 249, in _legacy_get_response
    response = self._get_response(request)
  File "C:\Python36-32\lib\site-packages\django\core\handlers\base.py", line 187, in _get_response
    response = self.process_exception_by_middleware(e, request)
  File "C:\Python36-32\lib\site-packages\django\core\handlers\base.py", line 185, in _get_response
    response = wrapped_callback(request, *callback_args, **callback_kwargs)
  File "C:\Python36-32\lib\site-packages\django\views\decorators\csrf.py", line 58, in wrapped_view
    return view_func(*args, **kwargs)
  File "C:\Python36-32\lib\site-packages\django\views\generic\base.py", line 68, in view
    return self.dispatch(request, *args, **kwargs)
  File "C:\Python36-32\lib\site-packages\rest_framework\views.py", line 489, in dispatch
    response = self.handle_exception(exc)
  File "C:\Python36-32\lib\site-packages\rest_framework\views.py", line 449, in handle_exception
    self.raise_uncaught_exception(exc)
  File "C:\Python36-32\lib\site-packages\rest_framework\views.py", line 486, in dispatch
    response = handler(request, *args, **kwargs)
  File "C:\Python36-32\lib\site-packages\rest_framework\decorators.py", line 52, in handler
    return func(*args, **kwargs)
  File "D:\code\PycharmProjects\cms\manager\views.py", line 171, in user_state
    return JsonResponse(context)
  File "C:\Python36-32\lib\site-packages\django\http\response.py", line 530, in __init__
    data = json.dumps(data, cls=encoder, **json_dumps_params)
  File "C:\Python36-32\lib\json\__init__.py", line 238, in dumps
    **kw).encode(obj)
  File "C:\Python36-32\lib\json\encoder.py", line 199, in encode
    chunks = self.iterencode(o, _one_shot=True)
  File "C:\Python36-32\lib\json\encoder.py", line 257, in iterencode
    return _iterencode(o, 0)
  File "C:\Python36-32\lib\site-packages\django\core\serializers\json.py", line 124, in default
    return super(DjangoJSONEncoder, self).default(o)
  File "C:\Python36-32\lib\json\encoder.py", line 180, in default
    o.__class__.__name__)
TypeError: Object of type 'MyUserSerializer' is not JSON serializable
2017-11-02 15:03:44,821 [Thread-11:22228] [django.request:135] [ERROR]- Internal Server Error: /manager/user_state/
Traceback (most recent call last):
  File "C:\Python36-32\lib\site-packages\django\core\handlers\exception.py", line 41, in inner
    response = get_response(request)
  File "C:\Python36-32\lib\site-packages\django\core\handlers\base.py", line 249, in _legacy_get_response
    response = self._get_response(request)
  File "C:\Python36-32\lib\site-packages\django\core\handlers\base.py", line 187, in _get_response
    response = self.process_exception_by_middleware(e, request)
  File "C:\Python36-32\lib\site-packages\django\core\handlers\base.py", line 185, in _get_response
    response = wrapped_callback(request, *callback_args, **callback_kwargs)
  File "C:\Python36-32\lib\site-packages\django\views\decorators\csrf.py", line 58, in wrapped_view
    return view_func(*args, **kwargs)
  File "C:\Python36-32\lib\site-packages\django\views\generic\base.py", line 68, in view
    return self.dispatch(request, *args, **kwargs)
  File "C:\Python36-32\lib\site-packages\rest_framework\views.py", line 489, in dispatch
    response = self.handle_exception(exc)
  File "C:\Python36-32\lib\site-packages\rest_framework\views.py", line 449, in handle_exception
    self.raise_uncaught_exception(exc)
  File "C:\Python36-32\lib\site-packages\rest_framework\views.py", line 486, in dispatch
    response = handler(request, *args, **kwargs)
  File "C:\Python36-32\lib\site-packages\rest_framework\decorators.py", line 52, in handler
    return func(*args, **kwargs)
  File "D:\code\PycharmProjects\cms\manager\views.py", line 171, in user_state
    return JsonResponse(context)
  File "C:\Python36-32\lib\site-packages\django\http\response.py", line 530, in __init__
    data = json.dumps(data, cls=encoder, **json_dumps_params)
  File "C:\Python36-32\lib\json\__init__.py", line 238, in dumps
    **kw).encode(obj)
  File "C:\Python36-32\lib\json\encoder.py", line 199, in encode
    chunks = self.iterencode(o, _one_shot=True)
  File "C:\Python36-32\lib\json\encoder.py", line 257, in iterencode
    return _iterencode(o, 0)
  File "C:\Python36-32\lib\site-packages\django\core\serializers\json.py", line 124, in default
    return super(DjangoJSONEncoder, self).default(o)
  File "C:\Python36-32\lib\json\encoder.py", line 180, in default
    o.__class__.__name__)
TypeError: Object of type 'MyUserSerializer' is not JSON serializable
2017-11-02 15:03:56,092 [Thread-14:21580] [django.request:135] [ERROR]- Internal Server Error: /manager/user_state/
Traceback (most recent call last):
  File "C:\Python36-32\lib\site-packages\django\core\handlers\exception.py", line 41, in inner
    response = get_response(request)
  File "C:\Python36-32\lib\site-packages\django\core\handlers\base.py", line 249, in _legacy_get_response
    response = self._get_response(request)
  File "C:\Python36-32\lib\site-packages\django\core\handlers\base.py", line 187, in _get_response
    response = self.process_exception_by_middleware(e, request)
  File "C:\Python36-32\lib\site-packages\django\core\handlers\base.py", line 185, in _get_response
    response = wrapped_callback(request, *callback_args, **callback_kwargs)
  File "C:\Python36-32\lib\site-packages\django\views\decorators\csrf.py", line 58, in wrapped_view
    return view_func(*args, **kwargs)
  File "C:\Python36-32\lib\site-packages\django\views\generic\base.py", line 68, in view
    return self.dispatch(request, *args, **kwargs)
  File "C:\Python36-32\lib\site-packages\rest_framework\views.py", line 489, in dispatch
    response = self.handle_exception(exc)
  File "C:\Python36-32\lib\site-packages\rest_framework\views.py", line 449, in handle_exception
    self.raise_uncaught_exception(exc)
  File "C:\Python36-32\lib\site-packages\rest_framework\views.py", line 486, in dispatch
    response = handler(request, *args, **kwargs)
  File "C:\Python36-32\lib\site-packages\rest_framework\decorators.py", line 52, in handler
    return func(*args, **kwargs)
  File "D:\code\PycharmProjects\cms\manager\views.py", line 171, in user_state
    return JsonResponse(context)
  File "C:\Python36-32\lib\site-packages\django\http\response.py", line 530, in __init__
    data = json.dumps(data, cls=encoder, **json_dumps_params)
  File "C:\Python36-32\lib\json\__init__.py", line 238, in dumps
    **kw).encode(obj)
  File "C:\Python36-32\lib\json\encoder.py", line 199, in encode
    chunks = self.iterencode(o, _one_shot=True)
  File "C:\Python36-32\lib\json\encoder.py", line 257, in iterencode
    return _iterencode(o, 0)
  File "C:\Python36-32\lib\site-packages\django\core\serializers\json.py", line 124, in default
    return super(DjangoJSONEncoder, self).default(o)
  File "C:\Python36-32\lib\json\encoder.py", line 180, in default
    o.__class__.__name__)
TypeError: Object of type 'MyUserSerializer' is not JSON serializable
2017-11-02 15:04:12,019 [Thread-23:19256] [django.request:135] [ERROR]- Internal Server Error: /manager/user_state/
Traceback (most recent call last):
  File "C:\Python36-32\lib\site-packages\django\core\handlers\exception.py", line 41, in inner
    response = get_response(request)
  File "C:\Python36-32\lib\site-packages\django\core\handlers\base.py", line 249, in _legacy_get_response
    response = self._get_response(request)
  File "C:\Python36-32\lib\site-packages\django\core\handlers\base.py", line 187, in _get_response
    response = self.process_exception_by_middleware(e, request)
  File "C:\Python36-32\lib\site-packages\django\core\handlers\base.py", line 185, in _get_response
    response = wrapped_callback(request, *callback_args, **callback_kwargs)
  File "C:\Python36-32\lib\site-packages\django\views\decorators\csrf.py", line 58, in wrapped_view
    return view_func(*args, **kwargs)
  File "C:\Python36-32\lib\site-packages\django\views\generic\base.py", line 68, in view
    return self.dispatch(request, *args, **kwargs)
  File "C:\Python36-32\lib\site-packages\rest_framework\views.py", line 489, in dispatch
    response = self.handle_exception(exc)
  File "C:\Python36-32\lib\site-packages\rest_framework\views.py", line 449, in handle_exception
    self.raise_uncaught_exception(exc)
  File "C:\Python36-32\lib\site-packages\rest_framework\views.py", line 486, in dispatch
    response = handler(request, *args, **kwargs)
  File "C:\Python36-32\lib\site-packages\rest_framework\decorators.py", line 52, in handler
    return func(*args, **kwargs)
  File "D:\code\PycharmProjects\cms\manager\views.py", line 171, in user_state
    return JsonResponse(context)
  File "C:\Python36-32\lib\site-packages\django\http\response.py", line 530, in __init__
    data = json.dumps(data, cls=encoder, **json_dumps_params)
  File "C:\Python36-32\lib\json\__init__.py", line 238, in dumps
    **kw).encode(obj)
  File "C:\Python36-32\lib\json\encoder.py", line 199, in encode
    chunks = self.iterencode(o, _one_shot=True)
  File "C:\Python36-32\lib\json\encoder.py", line 257, in iterencode
    return _iterencode(o, 0)
  File "C:\Python36-32\lib\site-packages\django\core\serializers\json.py", line 124, in default
    return super(DjangoJSONEncoder, self).default(o)
  File "C:\Python36-32\lib\json\encoder.py", line 180, in default
    o.__class__.__name__)
TypeError: Object of type 'MyUserSerializer' is not JSON serializable
2017-11-02 16:10:33,864 [Thread-41:19960] [django.request:135] [ERROR]- Internal Server Error: /manager/login
Traceback (most recent call last):
  File "C:\Python36-32\lib\site-packages\django\core\handlers\exception.py", line 41, in inner
    response = get_response(request)
  File "C:\Python36-32\lib\site-packages\django\core\handlers\base.py", line 249, in _legacy_get_response
    response = self._get_response(request)
  File "C:\Python36-32\lib\site-packages\django\core\handlers\base.py", line 187, in _get_response
    response = self.process_exception_by_middleware(e, request)
  File "C:\Python36-32\lib\site-packages\django\core\handlers\base.py", line 185, in _get_response
    response = wrapped_callback(request, *callback_args, **callback_kwargs)
  File "C:\Python36-32\lib\site-packages\django\views\decorators\csrf.py", line 58, in wrapped_view
    return view_func(*args, **kwargs)
  File "C:\Python36-32\lib\site-packages\django\views\generic\base.py", line 68, in view
    return self.dispatch(request, *args, **kwargs)
  File "C:\Python36-32\lib\site-packages\rest_framework\views.py", line 489, in dispatch
    response = self.handle_exception(exc)
  File "C:\Python36-32\lib\site-packages\rest_framework\views.py", line 449, in handle_exception
    self.raise_uncaught_exception(exc)
  File "C:\Python36-32\lib\site-packages\rest_framework\views.py", line 486, in dispatch
    response = handler(request, *args, **kwargs)
  File "D:\code\PycharmProjects\cms\manager\views.py", line 62, in wrapped
    return fun(self, request)
  File "D:\code\PycharmProjects\cms\manager\views.py", line 88, in post
    return JsonResponse(context)
  File "C:\Python36-32\lib\site-packages\django\http\response.py", line 530, in __init__
    data = json.dumps(data, cls=encoder, **json_dumps_params)
  File "C:\Python36-32\lib\json\__init__.py", line 238, in dumps
    **kw).encode(obj)
  File "C:\Python36-32\lib\json\encoder.py", line 199, in encode
    chunks = self.iterencode(o, _one_shot=True)
  File "C:\Python36-32\lib\json\encoder.py", line 257, in iterencode
    return _iterencode(o, 0)
  File "C:\Python36-32\lib\site-packages\django\core\serializers\json.py", line 124, in default
    return super(DjangoJSONEncoder, self).default(o)
  File "C:\Python36-32\lib\json\encoder.py", line 180, in default
    o.__class__.__name__)
TypeError: Object of type 'MyUserSerializer' is not JSON serializable
2017-11-02 16:10:36,163 [Thread-42:20096] [django.request:135] [ERROR]- Internal Server Error: /manager/login
Traceback (most recent call last):
  File "C:\Python36-32\lib\site-packages\django\core\handlers\exception.py", line 41, in inner
    response = get_response(request)
  File "C:\Python36-32\lib\site-packages\django\core\handlers\base.py", line 249, in _legacy_get_response
    response = self._get_response(request)
  File "C:\Python36-32\lib\site-packages\django\core\handlers\base.py", line 187, in _get_response
    response = self.process_exception_by_middleware(e, request)
  File "C:\Python36-32\lib\site-packages\django\core\handlers\base.py", line 185, in _get_response
    response = wrapped_callback(request, *callback_args, **callback_kwargs)
  File "C:\Python36-32\lib\site-packages\django\views\decorators\csrf.py", line 58, in wrapped_view
    return view_func(*args, **kwargs)
  File "C:\Python36-32\lib\site-packages\django\views\generic\base.py", line 68, in view
    return self.dispatch(request, *args, **kwargs)
  File "C:\Python36-32\lib\site-packages\rest_framework\views.py", line 489, in dispatch
    response = self.handle_exception(exc)
  File "C:\Python36-32\lib\site-packages\rest_framework\views.py", line 449, in handle_exception
    self.raise_uncaught_exception(exc)
  File "C:\Python36-32\lib\site-packages\rest_framework\views.py", line 486, in dispatch
    response = handler(request, *args, **kwargs)
  File "D:\code\PycharmProjects\cms\manager\views.py", line 62, in wrapped
    return fun(self, request)
  File "D:\code\PycharmProjects\cms\manager\views.py", line 88, in post
    return JsonResponse(context)
  File "C:\Python36-32\lib\site-packages\django\http\response.py", line 530, in __init__
    data = json.dumps(data, cls=encoder, **json_dumps_params)
  File "C:\Python36-32\lib\json\__init__.py", line 238, in dumps
    **kw).encode(obj)
  File "C:\Python36-32\lib\json\encoder.py", line 199, in encode
    chunks = self.iterencode(o, _one_shot=True)
  File "C:\Python36-32\lib\json\encoder.py", line 257, in iterencode
    return _iterencode(o, 0)
  File "C:\Python36-32\lib\site-packages\django\core\serializers\json.py", line 124, in default
    return super(DjangoJSONEncoder, self).default(o)
  File "C:\Python36-32\lib\json\encoder.py", line 180, in default
    o.__class__.__name__)
TypeError: Object of type 'MyUserSerializer' is not JSON serializable
2017-11-02 16:10:37,623 [Thread-43:22372] [django.request:135] [ERROR]- Internal Server Error: /manager/login
Traceback (most recent call last):
  File "C:\Python36-32\lib\site-packages\django\core\handlers\exception.py", line 41, in inner
    response = get_response(request)
  File "C:\Python36-32\lib\site-packages\django\core\handlers\base.py", line 249, in _legacy_get_response
    response = self._get_response(request)
  File "C:\Python36-32\lib\site-packages\django\core\handlers\base.py", line 187, in _get_response
    response = self.process_exception_by_middleware(e, request)
  File "C:\Python36-32\lib\site-packages\django\core\handlers\base.py", line 185, in _get_response
    response = wrapped_callback(request, *callback_args, **callback_kwargs)
  File "C:\Python36-32\lib\site-packages\django\views\decorators\csrf.py", line 58, in wrapped_view
    return view_func(*args, **kwargs)
  File "C:\Python36-32\lib\site-packages\django\views\generic\base.py", line 68, in view
    return self.dispatch(request, *args, **kwargs)
  File "C:\Python36-32\lib\site-packages\rest_framework\views.py", line 489, in dispatch
    response = self.handle_exception(exc)
  File "C:\Python36-32\lib\site-packages\rest_framework\views.py", line 449, in handle_exception
    self.raise_uncaught_exception(exc)
  File "C:\Python36-32\lib\site-packages\rest_framework\views.py", line 486, in dispatch
    response = handler(request, *args, **kwargs)
  File "D:\code\PycharmProjects\cms\manager\views.py", line 62, in wrapped
    return fun(self, request)
  File "D:\code\PycharmProjects\cms\manager\views.py", line 88, in post
    return JsonResponse(context)
  File "C:\Python36-32\lib\site-packages\django\http\response.py", line 530, in __init__
    data = json.dumps(data, cls=encoder, **json_dumps_params)
  File "C:\Python36-32\lib\json\__init__.py", line 238, in dumps
    **kw).encode(obj)
  File "C:\Python36-32\lib\json\encoder.py", line 199, in encode
    chunks = self.iterencode(o, _one_shot=True)
  File "C:\Python36-32\lib\json\encoder.py", line 257, in iterencode
    return _iterencode(o, 0)
  File "C:\Python36-32\lib\site-packages\django\core\serializers\json.py", line 124, in default
    return super(DjangoJSONEncoder, self).default(o)
  File "C:\Python36-32\lib\json\encoder.py", line 180, in default
    o.__class__.__name__)
TypeError: Object of type 'MyUserSerializer' is not JSON serializable
2017-11-02 17:33:01,982 [Thread-340:11244] [django.request:65] [WARNING]- Bad request (Unable to parse request body): /publish
2017-11-02 17:42:42,511 [Thread-362:19476] [django.request:135] [ERROR]- Internal Server Error: /contents
Traceback (most recent call last):
  File "C:\Python36-32\lib\site-packages\django\core\handlers\exception.py", line 41, in inner
    response = get_response(request)
  File "C:\Python36-32\lib\site-packages\django\core\handlers\base.py", line 249, in _legacy_get_response
    response = self._get_response(request)
  File "C:\Python36-32\lib\site-packages\django\core\handlers\base.py", line 187, in _get_response
    response = self.process_exception_by_middleware(e, request)
  File "C:\Python36-32\lib\site-packages\django\core\handlers\base.py", line 185, in _get_response
    response = wrapped_callback(request, *callback_args, **callback_kwargs)
  File "C:\Python36-32\lib\site-packages\django\views\decorators\csrf.py", line 58, in wrapped_view
    return view_func(*args, **kwargs)
  File "C:\Python36-32\lib\site-packages\django\views\generic\base.py", line 68, in view
    return self.dispatch(request, *args, **kwargs)
  File "C:\Python36-32\lib\site-packages\rest_framework\views.py", line 489, in dispatch
    response = self.handle_exception(exc)
  File "C:\Python36-32\lib\site-packages\rest_framework\views.py", line 449, in handle_exception
    self.raise_uncaught_exception(exc)
  File "C:\Python36-32\lib\site-packages\rest_framework\views.py", line 486, in dispatch
    response = handler(request, *args, **kwargs)
  File "D:\code\PycharmProjects\cms\focus\views.py", line 236, in post
    query_set = query_set[start:end]
  File "C:\Python36-32\lib\site-packages\django\db\models\query.py", line 269, in __getitem__
    "Negative indexing is not supported."
AssertionError: Negative indexing is not supported.
2017-11-02 17:42:44,940 [Thread-363:21716] [django.request:135] [ERROR]- Internal Server Error: /contents
Traceback (most recent call last):
  File "C:\Python36-32\lib\site-packages\django\core\handlers\exception.py", line 41, in inner
    response = get_response(request)
  File "C:\Python36-32\lib\site-packages\django\core\handlers\base.py", line 249, in _legacy_get_response
    response = self._get_response(request)
  File "C:\Python36-32\lib\site-packages\django\core\handlers\base.py", line 187, in _get_response
    response = self.process_exception_by_middleware(e, request)
  File "C:\Python36-32\lib\site-packages\django\core\handlers\base.py", line 185, in _get_response
    response = wrapped_callback(request, *callback_args, **callback_kwargs)
  File "C:\Python36-32\lib\site-packages\django\views\decorators\csrf.py", line 58, in wrapped_view
    return view_func(*args, **kwargs)
  File "C:\Python36-32\lib\site-packages\django\views\generic\base.py", line 68, in view
    return self.dispatch(request, *args, **kwargs)
  File "C:\Python36-32\lib\site-packages\rest_framework\views.py", line 489, in dispatch
    response = self.handle_exception(exc)
  File "C:\Python36-32\lib\site-packages\rest_framework\views.py", line 449, in handle_exception
    self.raise_uncaught_exception(exc)
  File "C:\Python36-32\lib\site-packages\rest_framework\views.py", line 486, in dispatch
    response = handler(request, *args, **kwargs)
  File "D:\code\PycharmProjects\cms\focus\views.py", line 236, in post
    query_set = query_set[start:end]
  File "C:\Python36-32\lib\site-packages\django\db\models\query.py", line 269, in __getitem__
    "Negative indexing is not supported."
AssertionError: Negative indexing is not supported.
2017-11-02 17:42:45,698 [Thread-364:17204] [django.request:135] [ERROR]- Internal Server Error: /contents
Traceback (most recent call last):
  File "C:\Python36-32\lib\site-packages\django\core\handlers\exception.py", line 41, in inner
    response = get_response(request)
  File "C:\Python36-32\lib\site-packages\django\core\handlers\base.py", line 249, in _legacy_get_response
    response = self._get_response(request)
  File "C:\Python36-32\lib\site-packages\django\core\handlers\base.py", line 187, in _get_response
    response = self.process_exception_by_middleware(e, request)
  File "C:\Python36-32\lib\site-packages\django\core\handlers\base.py", line 185, in _get_response
    response = wrapped_callback(request, *callback_args, **callback_kwargs)
  File "C:\Python36-32\lib\site-packages\django\views\decorators\csrf.py", line 58, in wrapped_view
    return view_func(*args, **kwargs)
  File "C:\Python36-32\lib\site-packages\django\views\generic\base.py", line 68, in view
    return self.dispatch(request, *args, **kwargs)
  File "C:\Python36-32\lib\site-packages\rest_framework\views.py", line 489, in dispatch
    response = self.handle_exception(exc)
  File "C:\Python36-32\lib\site-packages\rest_framework\views.py", line 449, in handle_exception
    self.raise_uncaught_exception(exc)
  File "C:\Python36-32\lib\site-packages\rest_framework\views.py", line 486, in dispatch
    response = handler(request, *args, **kwargs)
  File "D:\code\PycharmProjects\cms\focus\views.py", line 236, in post
    query_set = query_set[start:end]
  File "C:\Python36-32\lib\site-packages\django\db\models\query.py", line 269, in __getitem__
    "Negative indexing is not supported."
AssertionError: Negative indexing is not supported.
2017-11-02 17:44:14,747 [Thread-1:8540] [django.request:135] [ERROR]- Internal Server Error: /contents
Traceback (most recent call last):
  File "C:\Python36-32\lib\site-packages\django\core\handlers\exception.py", line 41, in inner
    response = get_response(request)
  File "C:\Python36-32\lib\site-packages\django\core\handlers\base.py", line 249, in _legacy_get_response
    response = self._get_response(request)
  File "C:\Python36-32\lib\site-packages\django\core\handlers\base.py", line 187, in _get_response
    response = self.process_exception_by_middleware(e, request)
  File "C:\Python36-32\lib\site-packages\django\core\handlers\base.py", line 185, in _get_response
    response = wrapped_callback(request, *callback_args, **callback_kwargs)
  File "C:\Python36-32\lib\site-packages\django\views\decorators\csrf.py", line 58, in wrapped_view
    return view_func(*args, **kwargs)
  File "C:\Python36-32\lib\site-packages\django\views\generic\base.py", line 68, in view
    return self.dispatch(request, *args, **kwargs)
  File "C:\Python36-32\lib\site-packages\rest_framework\views.py", line 489, in dispatch
    response = self.handle_exception(exc)
  File "C:\Python36-32\lib\site-packages\rest_framework\views.py", line 449, in handle_exception
    self.raise_uncaught_exception(exc)
  File "C:\Python36-32\lib\site-packages\rest_framework\views.py", line 486, in dispatch
    response = handler(request, *args, **kwargs)
  File "D:\code\PycharmProjects\cms\focus\views.py", line 238, in post
    query_set = query_set[start:end]
  File "C:\Python36-32\lib\site-packages\django\db\models\query.py", line 269, in __getitem__
    "Negative indexing is not supported."
AssertionError: Negative indexing is not supported.
